Workbook
Name nNIA: DATOS!$A$2:INDEX(DATOS!$A:$A,CONFIG_METADATA!$B$8)
Name nCURSO: DATOS!$D$2:INDEX(DATOS!$D:$D,CONFIG_METADATA!$B$8)
Name nEVAL: DATOS!$G$2:INDEX(DATOS!$G:$G,CONFIG_METADATA!$B$8)
Name nASIG: DATOS!$I$2:INDEX(DATOS!$I:$I,CONFIG_METADATA!$B$8)
Name nNOTA: DATOS!$K$2:INDEX(DATOS!$K:$K,CONFIG_METADATA!$B$8)
Name nAPTO: DATOS!$L$2:INDEX(DATOS!$L:$L,CONFIG_METADATA!$B$8)
Name nCLASE_E: CONFIG_METADATA!$E$2:INDEX(CONFIG_METADATA!$E:$E,CONFIG_METADATA!$B$8)

Sheet PORTADA_EEM
B2: Analizador de calificaciones
B3: Enseñanzas Elementales de Música · Conservatorios
B5: EMPEZAR
B6: 1 · Pega las calificaciones en la hoja DATOS
B7: Una fila por alumno, asignatura y evaluación. Las columnas ya están puestas: respeta su orden y sus nombres.
B9: 2 · Elige la evaluación
B10: CONFIG_METADATA!B4
B11: Códigos: 1EV · 2EV · 3EV · FI
B13: 3 · Mira los avisos antes de fiarte de las cifras
B14: Están en CONFIG_METADATA, debajo de la configuración. Cada uno dice qué significa que no sea cero.
B16: 4 · Exporta
B17: Copia la hoja EXPORTADOR entera y guárdala como CSV. Ese CSV es lo que lee la aplicación de visualización.
... B58: Versión 2.0 · agosto 2026

Sheet CONFIG_ASIGNATURAS
A1: ID | B1: Asignatura | C1: Cursos | D1: Grupo1 | E1: Grupo2 | F1: EsEspecialidad | G1: Activa | H1: UnaSolaVez | I1: Tipo | J1: Clase (calculada) | K1: CÓMO AÑADIR UNA ASIGNATURA
A2: 1 | B2: Lenguaje Musical | C2: 1EEM;2EEM;3EEM;4EEM | D2: Referencia | F2: No | G2: Sí | H2: Sí | I2: Obligatoria | J2: =IF($G2<>"Sí","",IF($D2="Especialidad","E",IF($E2="TeoricaTroncal","NT","N"))) | K2: 1. Escríbela en la primera fila libre (marcada abajo con una flecha). No hace falta
A3: 2 | B3: Coro | C3: 1EEM;2EEM;3EEM;4EEM | D3: NoEspecialidad | F3: No | G3: Sí | H3: Sí | I3: Obligatoria | J3: =IF($G3<>"Sí","",IF($D3="Especialidad","E",IF($E3="TeoricaTroncal","NT","N"))) | K3: insertar filas ni ordenar nada: las fórmulas no miran POSICIONES, miran columnas.
A4: 3 | B4: Conjunto | C4: 3EEM;4EEM | D4: NoEspecialidad | F4: No | G4: Sí | H4: No | I4: Obligatoria | J4: =IF($G4<>"Sí","",IF($D4="Especialidad","E",IF($E4="TeoricaTroncal","NT","N"))) | K4: 2. B Asignatura — EXACTAMENTE igual que en el fichero de calificaciones que
A5: 4 | B5: Acordeón | C5: 1EEM;2EEM;3EEM;4EEM | D5: Especialidad | E5: Tecla | F5: Sí | G5: Sí | H5: No | I5: Obligatoria | J5: =IF($G5<>"Sí","",IF($D5="Especialidad","E",IF($E5="TeoricaTroncal","NT","N"))) | K5: pegas en DATOS. Si no coincide letra por letra, esa asignatura no aparece
A6: 5 | B6: Arpa | C6: 1EEM;2EEM;3EEM;4EEM | D6: Especialidad | E6: Cuerda | F6: Sí | G6: Sí | H6: No | I6: Obligatoria | J6: =IF($G6<>"Sí","",IF($D6="Especialidad","E",IF($E6="TeoricaTroncal","NT","N"))) | K6: ni con un cero, y sus registros los cuenta el aviso «FueraDeLasCifras».
A7: 6 | B7: Clarinete | C7: 1EEM;2EEM;3EEM;4EEM | D7: Especialidad | E7: Madera | F7: Sí | G7: Sí | H7: No | I7: Obligatoria | J7: =IF($G7<>"Sí","",IF($D7="Especialidad","E",IF($E7="TeoricaTroncal","NT","N"))) | K7: 3. C Cursos — separados por punto y coma. Solo sale en los cursos que pongas.
A8: 7 | B8: Clave | C8: 1EEM;2EEM;3EEM;4EEM | D8: Especialidad | E8: Tecla | F8: Sí | G8: Sí | H8: No | I8: Obligatoria | J8: =IF($G8<>"Sí","",IF($D8="Especialidad","E",IF($E8="TeoricaTroncal","NT","N"))) | K8: 4. D Grupo1 — «Especialidad» si es un instrumento: decide en qué total cuenta.
A9: 8 | B9: Contrabajo | C9: 1EEM;2EEM;3EEM;4EEM | D9: Especialidad | E9: Cuerda | F9: Sí | G9: Sí | H9: No | I9: Obligatoria | J9: =IF($G9<>"Sí","",IF($D9="Especialidad","E",IF($E9="TeoricaTroncal","NT","N"))) | K9: 5. G Activa — «Sí». Sin eso no sale por ningún sitio.
A10: 9 | B10: Dulzaina | C10: 1EEM;2EEM;3EEM;4EEM | D10: Especialidad | E10: Madera | F10: Sí | G10: Sí | H10: No | I10: Obligatoria | J10: =IF($G10<>"Sí","",IF($D10="Especialidad","E",IF($E10="TeoricaTroncal","NT","N"))) | K10: 6. H UnaSolaVez — «Sí» solo si NO se vuelve a cursar con un segundo instrumento.
A11: 10 | B11: Fagot | C11: 1EEM;2EEM;3EEM;4EEM | D11: Especialidad | E11: Madera | F11: Sí | G11: Sí | H11: No | I11: Obligatoria | J11: =IF($G11<>"Sí","",IF($D11="Especialidad","E",IF($E11="TeoricaTroncal","NT","N"))) | K11: 7. I Tipo — Obligatoria / Optativa / De centro.
A12: 11 | B12: Flauta Travesera | C12: 1EEM;2EEM;3EEM;4EEM | D12: Especialidad | E12: Madera | F12: Sí | G12: Sí | H12: No | I12: Obligatoria | J12: =IF($G12<>"Sí","",IF($D12="Especialidad","E",IF($E12="TeoricaTroncal","NT","N"))) | K12: J Clase se calcula sola. Si sale vacía, esa fila no está activa.
A13: 12 | B13: Flauta de Pico | C13: 1EEM;2EEM;3EEM;4EEM | D13: Especialidad | E13: Madera | F13: Sí | G13: Sí | H13: No | I13: Obligatoria | J13: =IF($G13<>"Sí","",IF($D13="Especialidad","E",IF($E13="TeoricaTroncal","NT","N")))
A14: 13 | B14: Guitarra | C14: 1EEM;2EEM;3EEM;4EEM | D14: Especialidad | E14: Cuerda | F14: Sí | G14: Sí | H14: No | I14: Obligatoria | J14: =IF($G14<>"Sí","",IF($D14="Especialidad","E",IF($E14="TeoricaTroncal","NT","N")))
A15: 14 | B15: Instrumentos de Púa | C15: 1EEM;2EEM;3EEM;4EEM | D15: Especialidad | E15: Cuerda | F15: Sí | G15: Sí | H15: No | I15: Obligatoria | J15: =IF($G15<>"Sí","",IF($D15="Especialidad","E",IF($E15="TeoricaTroncal","NT","N")))
A16: 15 | B16: Oboe | C16: 1EEM;2EEM;3EEM;4EEM | D16: Especialidad | E16: Madera | F16: Sí | G16: Sí | H16: No | I16: Obligatoria | J16: =IF($G16<>"Sí","",IF($D16="Especialidad","E",IF($E16="TeoricaTroncal","NT","N")))
A17: 16 | B17: Percusión | C17: 1EEM;2EEM;3EEM;4EEM | D17: Especialidad | E17: Metal | F17: Sí | G17: Sí | H17: No | I17: Obligatoria | J17: =IF($G17<>"Sí","",IF($D17="Especialidad","E",IF($E17="TeoricaTroncal","NT","N")))
A18: 17 | B18: Piano | C18: 1EEM;2EEM;3EEM;4EEM | D18: Especialidad | E18: Tecla | F18: Sí | G18: Sí | H18: No | I18: Obligatoria | J18: =IF($G18<>"Sí","",IF($D18="Especialidad","E",IF($E18="TeoricaTroncal","NT","N")))
A19: 18 | B19: Saxofón | C19: 1EEM;2EEM;3EEM;4EEM | D19: Especialidad | E19: Madera | F19: Sí | G19: Sí | H19: No | I19: Obligatoria | J19: =IF($G19<>"Sí","",IF($D19="Especialidad","E",IF($E19="TeoricaTroncal","NT","N")))
A20: 19 | B20: Trombón | C20: 1EEM;2EEM;3EEM;4EEM | D20: Especialidad | E20: Metal | F20: Sí | G20: Sí | H20: No | I20: Obligatoria | J20: =IF($G20<>"Sí","",IF($D20="Especialidad","E",IF($E20="TeoricaTroncal","NT","N")))
A21: 20 | B21: Trompa | C21: 1EEM;2EEM;3EEM;4EEM | D21: Especialidad | E21: Metal | F21: Sí | G21: Sí | H21: No | I21: Obligatoria | J21: =IF($G21<>"Sí","",IF($D21="Especialidad","E",IF($E21="TeoricaTroncal","NT","N")))
A22: 21 | B22: Trompeta | C22: 1EEM;2EEM;3EEM;4EEM | D22: Especialidad | E22: Metal | F22: Sí | G22: Sí | H22: No | I22: Obligatoria | J22: =IF($G22<>"Sí","",IF($D22="Especialidad","E",IF($E22="TeoricaTroncal","NT","N")))
A23: 22 | B23: Tuba | C23: 1EEM;2EEM;3EEM;4EEM | D23: Especialidad | E23: Metal | F23: Sí | G23: Sí | H23: No | I23: Obligatoria | J23: =IF($G23<>"Sí","",IF($D23="Especialidad","E",IF($E23="TeoricaTroncal","NT","N")))
A24: 23 | B24: Viola | C24: 1EEM;2EEM;3EEM;4EEM | D24: Especialidad | E24: Cuerda | F24: Sí | G24: Sí | H24: No | I24: Obligatoria | J24: =IF($G24<>"Sí","",IF($D24="Especialidad","E",IF($E24="TeoricaTroncal","NT","N")))
... A27: 26 | B27: Violoncello | C27: 1EEM;2EEM;3EEM;4EEM | D27: Especialidad | E27: Cuerda | F27: Sí | G27: Sí | H27: No | I27: Obligatoria | J27: =IF($G27<>"Sí","",IF($D27="Especialidad","E",IF($E27="TeoricaTroncal","NT","N")))
J28: =IF($G28<>"Sí","",IF($D28="Especialidad","E",IF($E28="TeoricaTroncal","NT","N"))) | M28: ↓ primera fila libre
J29: =IF($G29<>"Sí","",IF($D29="Especialidad","E",IF($E29="TeoricaTroncal","NT","N")))
J30: =IF($G30<>"Sí","",IF($D30="Especialidad","E",IF($E30="TeoricaTroncal","NT","N")))
J31: =IF($G31<>"Sí","",IF($D31="Especialidad","E",IF($E31="TeoricaTroncal","NT","N")))
J32: =IF($G32<>"Sí","",IF($D32="Especialidad","E",IF($E32="TeoricaTroncal","NT","N")))
J33: =IF($G33<>"Sí","",IF($D33="Especialidad","E",IF($E33="TeoricaTroncal","NT","N")))
J34: =IF($G34<>"Sí","",IF($D34="Especialidad","E",IF($E34="TeoricaTroncal","NT","N")))
J35: =IF($G35<>"Sí","",IF($D35="Especialidad","E",IF($E35="TeoricaTroncal","NT","N")))
J36: =IF($G36<>"Sí","",IF($D36="Especialidad","E",IF($E36="TeoricaTroncal","NT","N")))
J37: =IF($G37<>"Sí","",IF($D37="Especialidad","E",IF($E37="TeoricaTroncal","NT","N")))
J38: =IF($G38<>"Sí","",IF($D38="Especialidad","E",IF($E38="TeoricaTroncal","NT","N")))
J39: =IF($G39<>"Sí","",IF($D39="Especialidad","E",IF($E39="TeoricaTroncal","NT","N")))
J40: =IF($G40<>"Sí","",IF($D40="Especialidad","E",IF($E40="TeoricaTroncal","NT","N")))
... J60: =IF($G60<>"Sí","",IF($D60="Especialidad","E",IF($E60="TeoricaTroncal","NT","N")))
J61: =IF($G61<>"Sí","",IF($D61="Especialidad","E",IF($E61="TeoricaTroncal","NT","N"))) | M61: ↑ última fila que miran las fórmulas

Sheet CONFIG_METADATA
A1: Campo | B1: Valor | D1: Evaluaciones
A2: Centro | B2: CPM Mestre Tárrega | D2: 1EV | E2: =IF(DATOS!$I2="","",IFERROR(VLOOKUP(DATOS!$I2,CONFIG_ASIGNATURAS!$B$2:$J$61,9,FALSE()),""))
A3: CursoAcademico | B3: 25/26 | D3: 2EV | E3: =IF(DATOS!$I3="","",IFERROR(VLOOKUP(DATOS!$I3,CONFIG_ASIGNATURAS!$B$2:$J$61,9,FALSE()),""))
A4: Evaluacion | B4: 1EV | D4: 3EV | E4: =IF(DATOS!$I4="","",IFERROR(VLOOKUP(DATOS!$I4,CONFIG_ASIGNATURAS!$B$2:$J$61,9,FALSE()),""))
D5: FI | E5: =IF(DATOS!$I5="","",IFERROR(VLOOKUP(DATOS!$I5,CONFIG_ASIGNATURAS!$B$2:$J$61,9,FALSE()),""))
A6: DobleEspecialidad | B6: {=IFERROR(SUMPRODUCT((nEVAL=CONFIG_METADATA!$B$4)*(COUNTIFS(CONFIG_ASIGNATURAS!$B$2:$B$61,nASIG,CONFIG_ASIGNATURAS!$H$2:$H$61,"Sí",CONFIG_ASIGNATURAS!$G$2:$G$61,"Sí")>0)*1)-COUNTA(_xlfn.UNIQUE(_xlfn._xlws.FILTER(nNIA&"|"&nASIG,(nEVAL=CONFIG_METADATA!$B$4)*(COUNTIFS(CONFIG_ASIGNATURAS!$B$2:$B$61,nASIG,CONFIG_ASIGNATURAS!$H$2:$H$61,"Sí",CONFIG_ASIGNATURAS!$G$2:$G$61,"Sí")>0)))),0)} | C6: Registros de más: quien cursa dos especialidades aparece dos veces en las asignaturas de una sola vez, con la misma nota. Cuentan doble en la media, en la moda y en el reparto. | E6: =IF(DATOS!$I6="","",IFERROR(VLOOKUP(DATOS!$I6,CONFIG_ASIGNATURAS!$B$2:$J$61,9,FALSE()),""))
A7: FueraDeLasCifras | B7: =CALC_EEM!$D$2-CALC_EEM!$D$3-CALC_EEM!$D$4 | C7: Registros que no entran en ninguna cifra: su asignatura no está en CONFIG_ASIGNATURAS, o está pero con Activa = No. Si no es cero, falta algo en la configuración o sobra un No. | E7: =IF(DATOS!$I7="","",IFERROR(VLOOKUP(DATOS!$I7,CONFIG_ASIGNATURAS!$B$2:$J$61,9,FALSE()),""))
A8: FilasConDatos | B8: =IFERROR(LOOKUP(2,1/(DATOS!$A$2:$A20000<>""),ROW(DATOS!$A$2:$A20000)),2) | C8: Última fila de DATOS con algo. Es hasta donde miran todas las fórmulas: sin esto recorrerían las 20.000 filas siempre, y diecinueve de cada veinte lecturas serían de celdas vacías. | E8: =IF(DATOS!$I8="","",IFERROR(VLOOKUP(DATOS!$I8,CONFIG_ASIGNATURAS!$B$2:$J$61,9,FALSE()),""))
E9: =IF(DATOS!$I9="","",IFERROR(VLOOKUP(DATOS!$I9,CONFIG_ASIGNATURAS!$B$2:$J$61,9,FALSE()),""))
E10: =IF(DATOS!$I10="","",IFERROR(VLOOKUP(DATOS!$I10,CONFIG_ASIGNATURAS!$B$2:$J$61,9,FALSE()),""))
E11: =IF(DATOS!$I11="","",IFERROR(VLOOKUP(DATOS!$I11,CONFIG_ASIGNATURAS!$B$2:$J$61,9,FALSE()),""))
E12: =IF(DATOS!$I12="","",IFERROR(VLOOKUP(DATOS!$I12,CONFIG_ASIGNATURAS!$B$2:$J$61,9,FALSE()),""))
E13: =IF(DATOS!$I13="","",IFERROR(VLOOKUP(DATOS!$I13,CONFIG_ASIGNATURAS!$B$2:$J$61,9,FALSE()),""))
E14: =IF(DATOS!$I14="","",IFERROR(VLOOKUP(DATOS!$I14,CONFIG_ASIGNATURAS!$B$2:$J$61,9,FALSE()),""))
E15: =IF(DATOS!$I15="","",IFERROR(VLOOKUP(DATOS!$I15,CONFIG_ASIGNATURAS!$B$2:$J$61,9,FALSE()),""))
E16: =IF(DATOS!$I16="","",IFERROR(VLOOKUP(DATOS!$I16,CONFIG_ASIGNATURAS!$B$2:$J$61,9,FALSE()),""))
E17: =IF(DATOS!$I17="","",IFERROR(VLOOKUP(DATOS!$I17,CONFIG_ASIGNATURAS!$B$2:$J$61,9,FALSE()),""))
E18: =IF(DATOS!$I18="","",IFERROR(VLOOKUP(DATOS!$I18,CONFIG_ASIGNATURAS!$B$2:$J$61,9,FALSE()),""))
E19: =IF(DATOS!$I19="","",IFERROR(VLOOKUP(DATOS!$I19,CONFIG_ASIGNATURAS!$B$2:$J$61,9,FALSE()),""))
E20: =IF(DATOS!$I20="","",IFERROR(VLOOKUP(DATOS!$I20,CONFIG_ASIGNATURAS!$B$2:$J$61,9,FALSE()),""))
... E20000: =IF(DATOS!$I20000="","",IFERROR(VLOOKUP(DATOS!$I20000,CONFIG_ASIGNATURAS!$B$2:$J$61,9,FALSE()),""))

Sheet CONFIG_CORRELACIONES
A1: ID | B1: Curso | C1: Asignatura1 | D1: Asignatura2 | E1: Activa | G1: LEYENDA
A2: 1 | B2: 1EEM | C2: Lenguaje Musical | D2: Coro | E2: Sí | G2: Especialidad = la asignatura de instrumento del alumno
A3: 2 | B3: 1EEM | C3: Lenguaje Musical | D3: Especialidad | E3: Sí | G3: Para añadir nuevas correlaciones, añadir filas aquí
A4: 3 | B4: 1EEM | C4: Coro | D4: Especialidad | E4: Sí
A5: 4 | B5: 2EEM | C5: Lenguaje Musical | D5: Coro | E5: Sí
A6: 5 | B6: 2EEM | C6: Lenguaje Musical | D6: Especialidad | E6: Sí
A7: 6 | B7: 2EEM | C7: Coro | D7: Especialidad | E7: Sí
A8: 7 | B8: 3EEM | C8: Lenguaje Musical | D8: Coro | E8: Sí
A9: 8 | B9: 3EEM | C9: Lenguaje Musical | D9: Conjunto | E9: Sí
A10: 9 | B10: 3EEM | C10: Lenguaje Musical | D10: Especialidad | E10: Sí
A11: 10 | B11: 3EEM | C11: Coro | D11: Conjunto | E11: Sí
A12: 11 | B12: 3EEM | C12: Coro | D12: Especialidad | E12: Sí
A13: 12 | B13: 3EEM | C13: Conjunto | D13: Especialidad | E13: Sí
A14: 13 | B14: 4EEM | C14: Lenguaje Musical | D14: Coro | E14: Sí
A15: 14 | B15: 4EEM | C15: Lenguaje Musical | D15: Conjunto | E15: Sí
... A19: 18 | B19: 4EEM | C19: Conjunto | D19: Especialidad | E19: Sí

Sheet DATOS
A1: NIA | B1: Apellidos | C1: Nombre | D1: Curso | E1: Especialidad | F1: Repite | G1: Evaluación | H1: Código Asig | I1: Contenido | J1: Nota | K1: Nota Numérica | L1: Apto | M1: Profesor | N1: Observ.

Sheet CALC_EEM
A1: Nivel | B1: Asignatura | C1: TipoAsig | D1: Registros | E1: NotaMedia | F1: Desviacion | G1: Moda | H1: PctAprobados | I1: PctSuspendidos | J1: ModaAprobados | K1: ModaSuspendidos | L1: Dist1 | M1: Dist2 | N1: Dist3 | O1: Dist4 | P1: Dist5 | Q1: Dist6 | R1: Dist7 | S1: Dist8 | T1: Dist9 | U1: Dist10 | V1: AplicaACurso
A2: GLOBAL | B2: Total | C2: Total | D2: =COUNTIF(DATOS!G:G,CONFIG_METADATA!$B$4) -> 0 | E2: =IFERROR(AVERAGEIF(DATOS!G:G,CONFIG_METADATA!$B$4,DATOS!K:K),"—") -> — | F2: {=IFERROR(_xlfn.STDEV.P(IF(nEVAL=CONFIG_METADATA!$B$4,nNOTA)),"—")} -> — | G2: {=IFERROR(_xlfn.MODE.SNGL(IF(nEVAL=CONFIG_METADATA!$B$4,nNOTA)),"—")} -> — | H2: =IFERROR(COUNTIFS(DATOS!G:G,CONFIG_METADATA!$B$4,DATOS!L:L,"S")/COUNTIF(DATOS!G:G,CONFIG_METADATA!$B$4),"—") -> — | I2: =IFERROR(COUNTIFS(DATOS!G:G,CONFIG_METADATA!$B$4,DATOS!L:L,"N")/COUNTIF(DATOS!G:G,CONFIG_METADATA!$B$4),"—") -> — | J2: {=IFERROR(_xlfn.MODE.SNGL(IF((nEVAL=CONFIG_METADATA!$B$4)*(nAPTO="S"),nNOTA)),"—")} -> — | K2: {=IFERROR(_xlfn.MODE.SNGL(IF((nEVAL=CONFIG_METADATA!$B$4)*(nAPTO="N"),nNOTA)),"—")} -> — | L2: {=SUMPRODUCT((nEVAL=CONFIG_METADATA!$B$4)*(nNOTA=1))} -> 0 | M2: {=SUMPRODUCT((nEVAL=CONFIG_METADATA!$B$4)*(nNOTA=2))} -> 0 | N2: {=SUMPRODUCT((nEVAL=CONFIG_METADATA!$B$4)*(nNOTA=3))} -> 0 | O2: {=SUMPRODUCT((nEVAL=CONFIG_METADATA!$B$4)*(nNOTA=4))} -> 0 | P2: {=SUMPRODUCT((nEVAL=CONFIG_METADATA!$B$4)*(nNOTA=5))} -> 0 | Q2: {=SUMPRODUCT((nEVAL=CONFIG_METADATA!$B$4)*(nNOTA=6))} -> 0 | R2: {=SUMPRODUCT((nEVAL=CONFIG_METADATA!$B$4)*(nNOTA=7))} -> 0 | S2: {=SUMPRODUCT((nEVAL=CONFIG_METADATA!$B$4)*(nNOTA=8))} -> 0 | T2: {=SUMPRODUCT((nEVAL=CONFIG_METADATA!$B$4)*(nNOTA=9))} -> 0 | U2: {=SUMPRODUCT((nEVAL=CONFIG_METADATA!$B$4)*(nNOTA=10))} -> 0
A3: GLOBAL | B3: Total Especialidad | C3: TotalEsp | D3: =SUMPRODUCT((nEVAL=CONFIG_METADATA!$B$4)*(nCLASE_E="E")*1) | E3: {=IFERROR(AVERAGE(IF((nEVAL=CONFIG_METADATA!$B$4)*(nCLASE_E="E"),nNOTA)),"—")} | F3: {=IFERROR(_xlfn.STDEV.P(IF((nEVAL=CONFIG_METADATA!$B$4)*(nCLASE_E="E"),nNOTA)),"—")} | G3: {=IFERROR(_xlfn.MODE.SNGL(IF((nEVAL=CONFIG_METADATA!$B$4)*(nCLASE_E="E"),nNOTA)),"—")} | H3: =IFERROR(SUMPRODUCT((nEVAL=CONFIG_METADATA!$B$4)*(nCLASE_E="E")*(nAPTO="S"))/SUMPRODUCT((nEVAL=CONFIG_METADATA!$B$4)*(nCLASE_E="E")*1),"—") | I3: =IFERROR(SUMPRODUCT((nEVAL=CONFIG_METADATA!$B$4)*(nCLASE_E="E")*(nAPTO="N"))/SUMPRODUCT((nEVAL=CONFIG_METADATA!$B$4)*(nCLASE_E="E")*1),"—") | J3: {=IFERROR(_xlfn.MODE.SNGL(IF((nEVAL=CONFIG_METADATA!$B$4)*(nCLASE_E="E")*(nAPTO="S"),nNOTA)),"—")} | K3: {=IFERROR(_xlfn.MODE.SNGL(IF((nEVAL=CONFIG_METADATA!$B$4)*(nCLASE_E="E")*(nAPTO="N"),nNOTA)),"—")} | L3: =SUMPRODUCT((nEVAL=CONFIG_METADATA!$B$4)*(nCLASE_E="E")*(nNOTA=1)) | M3: =SUMPRODUCT((nEVAL=CONFIG_METADATA!$B$4)*(nCLASE_E="E")*(nNOTA=2)) | N3: =SUMPRODUCT((nEVAL=CONFIG_METADATA!$B$4)*(nCLASE_E="E")*(nNOTA=3)) | O3: =SUMPRODUCT((nEVAL=CONFIG_METADATA!$B$4)*(nCLASE_E="E")*(nNOTA=4)) | P3: =SUMPRODUCT((nEVAL=CONFIG_METADATA!$B$4)*(nCLASE_E="E")*(nNOTA=5)) | Q3: =SUMPRODUCT((nEVAL=CONFIG_METADATA!$B$4)*(nCLASE_E="E")*(nNOTA=6)) | R3: =SUMPRODUCT((nEVAL=CONFIG_METADATA!$B$4)*(nCLASE_E="E")*(nNOTA=7)) | S3: =SUMPRODUCT((nEVAL=CONFIG_METADATA!$B$4)*(nCLASE_E="E")*(nNOTA=8)) | T3: =SUMPRODUCT((nEVAL=CONFIG_METADATA!$B$4)*(nCLASE_E="E")*(nNOTA=9)) | U3: =SUMPRODUCT((nEVAL=CONFIG_METADATA!$B$4)*(nCLASE_E="E")*(nNOTA=10))
A4: GLOBAL | B4: Total no Especialidad | C4: TotalNoEsp | D4: =SUMPRODUCT((nEVAL=CONFIG_METADATA!$B$4)*((nCLASE_E<>"")*(nCLASE_E<>"E"))*1) | E4: {=IFERROR(AVERAGE(IF((nEVAL=CONFIG_METADATA!$B$4)*((nCLASE_E<>"")*(nCLASE_E<>"E")),nNOTA)),"—")} | F4: {=IFERROR(_xlfn.STDEV.P(IF((nEVAL=CONFIG_METADATA!$B$4)*((nCLASE_E<>"")*(nCLASE_E<>"E")),nNOTA)),"—")} | G4: {=IFERROR(_xlfn.MODE.SNGL(IF((nEVAL=CONFIG_METADATA!$B$4)*((nCLASE_E<>"")*(nCLASE_E<>"E")),nNOTA)),"—")} | H4: =IFERROR(SUMPRODUCT((nEVAL=CONFIG_METADATA!$B$4)*((nCLASE_E<>"")*(nCLASE_E<>"E"))*(nAPTO="S"))/SUMPRODUCT((nEVAL=CONFIG_METADATA!$B$4)*((nCLASE_E<>"")*(nCLASE_E<>"E"))*1),"—") | I4: =IFERROR(SUMPRODUCT((nEVAL=CONFIG_METADATA!$B$4)*((nCLASE_E<>"")*(nCLASE_E<>"E"))*(nAPTO="N"))/SUMPRODUCT((nEVAL=CONFIG_METADATA!$B$4)*((nCLASE_E<>"")*(nCLASE_E<>"E"))*1),"—") | J4: {=IFERROR(_xlfn.MODE.SNGL(IF((nEVAL=CONFIG_METADATA!$B$4)*((nCLASE_E<>"")*(nCLASE_E<>"E"))*(nAPTO="S"),nNOTA)),"—")} | K4: {=IFERROR(_xlfn.MODE.SNGL(IF((nEVAL=CONFIG_METADATA!$B$4)*((nCLASE_E<>"")*(nCLASE_E<>"E"))*(nAPTO="N"),nNOTA)),"—")} | L4: =SUMPRODUCT((nEVAL=CONFIG_METADATA!$B$4)*((nCLASE_E<>"")*(nCLASE_E<>"E"))*(nNOTA=1)) | M4: =SUMPRODUCT((nEVAL=CONFIG_METADATA!$B$4)*((nCLASE_E<>"")*(nCLASE_E<>"E"))*(nNOTA=2)) | N4: =SUMPRODUCT((nEVAL=CONFIG_METADATA!$B$4)*((nCLASE_E<>"")*(nCLASE_E<>"E"))*(nNOTA=3)) | O4: =SUMPRODUCT((nEVAL=CONFIG_METADATA!$B$4)*((nCLASE_E<>"")*(nCLASE_E<>"E"))*(nNOTA=4)) | P4: =SUMPRODUCT((nEVAL=CONFIG_METADATA!$B$4)*((nCLASE_E<>"")*(nCLASE_E<>"E"))*(nNOTA=5)) | Q4: =SUMPRODUCT((nEVAL=CONFIG_METADATA!$B$4)*((nCLASE_E<>"")*(nCLASE_E<>"E"))*(nNOTA=6)) | R4: =SUMPRODUCT((nEVAL=CONFIG_METADATA!$B$4)*((nCLASE_E<>"")*(nCLASE_E<>"E"))*(nNOTA=7)) | S4: =SUMPRODUCT((nEVAL=CONFIG_METADATA!$B$4)*((nCLASE_E<>"")*(nCLASE_E<>"E"))*(nNOTA=8)) | T4: =SUMPRODUCT((nEVAL=CONFIG_METADATA!$B$4)*((nCLASE_E<>"")*(nCLASE_E<>"E"))*(nNOTA=9)) | U4: =SUMPRODUCT((nEVAL=CONFIG_METADATA!$B$4)*((nCLASE_E<>"")*(nCLASE_E<>"E"))*(nNOTA=10))
A5: GLOBAL | B5: {=IFERROR(INDEX(_xlfn._xlws.FILTER(CONFIG_ASIGNATURAS!$B$2:$B$61,CONFIG_ASIGNATURAS!$G$2:$G$61="Sí"),1),"")} | C5: =IF(B5="","",IFERROR(IF(VLOOKUP(B5,CONFIG_ASIGNATURAS!$B$2:$F$61,5,FALSE())="Sí","Especialidad","Asignatura"),"Asignatura")) | D5: =COUNTIFS(DATOS!G:G,CONFIG_METADATA!$B$4,DATOS!I:I,B5) -> 0 | E5: =IFERROR(AVERAGEIFS(DATOS!K:K,DATOS!G:G,CONFIG_METADATA!$B$4,DATOS!I:I,B5),"—") -> — | F5: {=IFERROR(_xlfn.STDEV.P(IF((nEVAL=CONFIG_METADATA!$B$4)*(nASIG=B5),nNOTA)),"—")} -> — | G5: {=IFERROR(_xlfn.MODE.SNGL(IF((nEVAL=CONFIG_METADATA!$B$4)*(nASIG=B5),nNOTA)),"—")} -> — | H5: =IFERROR(COUNTIFS(DATOS!G:G,CONFIG_METADATA!$B$4,DATOS!I:I,B5,DATOS!L:L,"S")/COUNTIFS(DATOS!G:G,CONFIG_METADATA!$B$4,DATOS!I:I,B5),"—") -> — | I5: =IFERROR(COUNTIFS(DATOS!G:G,CONFIG_METADATA!$B$4,DATOS!I:I,B5,DATOS!L:L,"N")/COUNTIFS(DATOS!G:G,CONFIG_METADATA!$B$4,DATOS!I:I,B5),"—") -> — | J5: {=IFERROR(_xlfn.MODE.SNGL(IF((nEVAL=CONFIG_METADATA!$B$4)*(nASIG=B5)*(nAPTO="S"),nNOTA)),"—")} -> — | K5: {=IFERROR(_xlfn.MODE.SNGL(IF((nEVAL=CONFIG_METADATA!$B$4)*(nASIG=B5)*(nAPTO="N"),nNOTA)),"—")} -> — | L5: =COUNTIFS(DATOS!G:G,CONFIG_METADATA!$B$4,DATOS!I:I,B5,DATOS!K:K,1) -> 0 | M5: =COUNTIFS(DATOS!G:G,CONFIG_METADATA!$B$4,DATOS!I:I,B5,DATOS!K:K,2) -> 0 | N5: =COUNTIFS(DATOS!G:G,CONFIG_METADATA!$B$4,DATOS!I:I,B5,DATOS!K:K,3) -> 0 | O5: =COUNTIFS(DATOS!G:G,CONFIG_METADATA!$B$4,DATOS!I:I,B5,DATOS!K:K,4) -> 0 | P5: =COUNTIFS(DATOS!G:G,CONFIG_METADATA!$B$4,DATOS!I:I,B5,DATOS!K:K,5) -> 0 | Q5: =COUNTIFS(DATOS!G:G,CONFIG_METADATA!$B$4,DATOS!I:I,B5,DATOS!K:K,6) -> 0 | R5: =COUNTIFS(DATOS!G:G,CONFIG_METADATA!$B$4,DATOS!I:I,B5,DATOS!K:K,7) -> 0 | S5: =COUNTIFS(DATOS!G:G,CONFIG_METADATA!$B$4,DATOS!I:I,B5,DATOS!K:K,8) -> 0 | T5: =COUNTIFS(DATOS!G:G,CONFIG_METADATA!$B$4,DATOS!I:I,B5,DATOS!K:K,9) -> 0 | U5: =COUNTIFS(DATOS!G:G,CONFIG_METADATA!$B$4,DATOS!I:I,B5,DATOS!K:K,10) -> 0
A6: GLOBAL | B6: {=IFERROR(INDEX(_xlfn._xlws.FILTER(CONFIG_ASIGNATURAS!$B$2:$B$61,CONFIG_ASIGNATURAS!$G$2:$G$61="Sí"),2),"")} | C6: =IF(B6="","",IFERROR(IF(VLOOKUP(B6,CONFIG_ASIGNATURAS!$B$2:$F$61,5,FALSE())="Sí","Especialidad","Asignatura"),"Asignatura")) | D6: =COUNTIFS(DATOS!G:G,CONFIG_METADATA!$B$4,DATOS!I:I,B6) -> 0 | E6: =IFERROR(AVERAGEIFS(DATOS!K:K,DATOS!G:G,CONFIG_METADATA!$B$4,DATOS!I:I,B6),"—") -> — | F6: {=IFERROR(_xlfn.STDEV.P(IF((nEVAL=CONFIG_METADATA!$B$4)*(nASIG=B6),nNOTA)),"—")} -> — | G6: {=IFERROR(_xlfn.MODE.SNGL(IF((nEVAL=CONFIG_METADATA!$B$4)*(nASIG=B6),nNOTA)),"—")} -> — | H6: =IFERROR(COUNTIFS(DATOS!G:G,CONFIG_METADATA!$B$4,DATOS!I:I,B6,DATOS!L:L,"S")/COUNTIFS(DATOS!G:G,CONFIG_METADATA!$B$4,DATOS!I:I,B6),"—") -> — | I6: =IFERROR(COUNTIFS(DATOS!G:G,CONFIG_METADATA!$B$4,DATOS!I:I,B6,DATOS!L:L,"N")/COUNTIFS(DATOS!G:G,CONFIG_METADATA!$B$4,DATOS!I:I,B6),"—") -> — | J6: {=IFERROR(_xlfn.MODE.SNGL(IF((nEVAL=CONFIG_METADATA!$B$4)*(nASIG=B6)*(nAPTO="S"),nNOTA)),"—")} -> — | K6: {=IFERROR(_xlfn.MODE.SNGL(IF((nEVAL=CONFIG_METADATA!$B$4)*(nASIG=B6)*(nAPTO="N"),nNOTA)),"—")} -> — | L6: =COUNTIFS(DATOS!G:G,CONFIG_METADATA!$B$4,DATOS!I:I,B6,DATOS!K:K,1) -> 0 | M6: =COUNTIFS(DATOS!G:G,CONFIG_METADATA!$B$4,DATOS!I:I,B6,DATOS!K:K,2) -> 0 | N6: =COUNTIFS(DATOS!G:G,CONFIG_METADATA!$B$4,DATOS!I:I,B6,DATOS!K:K,3) -> 0 | O6: =COUNTIFS(DATOS!G:G,CONFIG_METADATA!$B$4,DATOS!I:I,B6,DATOS!K:K,4) -> 0 | P6: =COUNTIFS(DATOS!G:G,CONFIG_METADATA!$B$4,DATOS!I:I,B6,DATOS!K:K,5) -> 0 | Q6: =COUNTIFS(DATOS!G:G,CONFIG_METADATA!$B$4,DATOS!I:I,B6,DATOS!K:K,6) -> 0 | R6: =COUNTIFS(DATOS!G:G,CONFIG_METADATA!$B$4,DATOS!I:I,B6,DATOS!K:K,7) -> 0 | S6: =COUNTIFS(DATOS!G:G,CONFIG_METADATA!$B$4,DATOS!I:I,B6,DATOS!K:K,8) -> 0 | T6: =COUNTIFS(DATOS!G:G,CONFIG_METADATA!$B$4,DATOS!I:I,B6,DATOS!K:K,9) -> 0 | U6: =COUNTIFS(DATOS!G:G,CONFIG_METADATA!$B$4,DATOS!I:I,B6,DATOS!K:K,10) -> 0
A7: GLOBAL | B7: {=IFERROR(INDEX(_xlfn._xlws.FILTER(CONFIG_ASIGNATURAS!$B$2:$B$61,CONFIG_ASIGNATURAS!$G$2:$G$61="Sí"),3),"")} | C7: =IF(B7="","",IFERROR(IF(VLOOKUP(B7,CONFIG_ASIGNATURAS!$B$2:$F$61,5,FALSE())="Sí","Especialidad","Asignatura"),"Asignatura")) | D7: =COUNTIFS(DATOS!G:G,CONFIG_METADATA!$B$4,DATOS!I:I,B7) -> 0 | E7: =IFERROR(AVERAGEIFS(DATOS!K:K,DATOS!G:G,CONFIG_METADATA!$B$4,DATOS!I:I,B7),"—") -> — | F7: {=IFERROR(_xlfn.STDEV.P(IF((nEVAL=CONFIG_METADATA!$B$4)*(nASIG=B7),nNOTA)),"—")} -> — | G7: {=IFERROR(_xlfn.MODE.SNGL(IF((nEVAL=CONFIG_METADATA!$B$4)*(nASIG=B7),nNOTA)),"—")} -> — | H7: =IFERROR(COUNTIFS(DATOS!G:G,CONFIG_METADATA!$B$4,DATOS!I:I,B7,DATOS!L:L,"S")/COUNTIFS(DATOS!G:G,CONFIG_METADATA!$B$4,DATOS!I:I,B7),"—") -> — | I7: =IFERROR(COUNTIFS(DATOS!G:G,CONFIG_METADATA!$B$4,DATOS!I:I,B7,DATOS!L:L,"N")/COUNTIFS(DATOS!G:G,CONFIG_METADATA!$B$4,DATOS!I:I,B7),"—") -> — | J7: {=IFERROR(_xlfn.MODE.SNGL(IF((nEVAL=CONFIG_METADATA!$B$4)*(nASIG=B7)*(nAPTO="S"),nNOTA)),"—")} -> — | K7: {=IFERROR(_xlfn.MODE.SNGL(IF((nEVAL=CONFIG_METADATA!$B$4)*(nASIG=B7)*(nAPTO="N"),nNOTA)),"—")} -> — | L7: =COUNTIFS(DATOS!G:G,CONFIG_METADATA!$B$4,DATOS!I:I,B7,DATOS!K:K,1) -> 0 | M7: =COUNTIFS(DATOS!G:G,CONFIG_METADATA!$B$4,DATOS!I:I,B7,DATOS!K:K,2) -> 0 | N7: =COUNTIFS(DATOS!G:G,CONFIG_METADATA!$B$4,DATOS!I:I,B7,DATOS!K:K,3) -> 0 | O7: =COUNTIFS(DATOS!G:G,CONFIG_METADATA!$B$4,DATOS!I:I,B7,DATOS!K:K,4) -> 0 | P7: =COUNTIFS(DATOS!G:G,CONFIG_METADATA!$B$4,DATOS!I:I,B7,DATOS!K:K,5) -> 0 | Q7: =COUNTIFS(DATOS!G:G,CONFIG_METADATA!$B$4,DATOS!I:I,B7,DATOS!K:K,6) -> 0 | R7: =COUNTIFS(DATOS!G:G,CONFIG_METADATA!$B$4,DATOS!I:I,B7,DATOS!K:K,7) -> 0 | S7: =COUNTIFS(DATOS!G:G,CONFIG_METADATA!$B$4,DATOS!I:I,B7,DATOS!K:K,8) -> 0 | T7: =COUNTIFS(DATOS!G:G,CONFIG_METADATA!$B$4,DATOS!I:I,B7,DATOS!K:K,9) -> 0 | U7: =COUNTIFS(DATOS!G:G,CONFIG_METADATA!$B$4,DATOS!I:I,B7,DATOS!K:K,10) -> 0
A8: GLOBAL | B8: {=IFERROR(INDEX(_xlfn._xlws.FILTER(CONFIG_ASIGNATURAS!$B$2:$B$61,CONFIG_ASIGNATURAS!$G$2:$G$61="Sí"),4),"")} | C8: =IF(B8="","",IFERROR(IF(VLOOKUP(B8,CONFIG_ASIGNATURAS!$B$2:$F$61,5,FALSE())="Sí","Especialidad","Asignatura"),"Asignatura")) | D8: =COUNTIFS(DATOS!G:G,CONFIG_METADATA!$B$4,DATOS!I:I,B8) -> 0 | E8: =IFERROR(AVERAGEIFS(DATOS!K:K,DATOS!G:G,CONFIG_METADATA!$B$4,DATOS!I:I,B8),"—") -> — | F8: {=IFERROR(_xlfn.STDEV.P(IF((nEVAL=CONFIG_METADATA!$B$4)*(nASIG=B8),nNOTA)),"—")} -> — | G8: {=IFERROR(_xlfn.MODE.SNGL(IF((nEVAL=CONFIG_METADATA!$B$4)*(nASIG=B8),nNOTA)),"—")} -> — | H8: =IFERROR(COUNTIFS(DATOS!G:G,CONFIG_METADATA!$B$4,DATOS!I:I,B8,DATOS!L:L,"S")/COUNTIFS(DATOS!G:G,CONFIG_METADATA!$B$4,DATOS!I:I,B8),"—") -> — | I8: =IFERROR(COUNTIFS(DATOS!G:G,CONFIG_METADATA!$B$4,DATOS!I:I,B8,DATOS!L:L,"N")/COUNTIFS(DATOS!G:G,CONFIG_METADATA!$B$4,DATOS!I:I,B8),"—") -> — | J8: {=IFERROR(_xlfn.MODE.SNGL(IF((nEVAL=CONFIG_METADATA!$B$4)*(nASIG=B8)*(nAPTO="S"),nNOTA)),"—")} -> — | K8: {=IFERROR(_xlfn.MODE.SNGL(IF((nEVAL=CONFIG_METADATA!$B$4)*(nASIG=B8)*(nAPTO="N"),nNOTA)),"—")} -> — | L8: =COUNTIFS(DATOS!G:G,CONFIG_METADATA!$B$4,DATOS!I:I,B8,DATOS!K:K,1) -> 0 | M8: =COUNTIFS(DATOS!G:G,CONFIG_METADATA!$B$4,DATOS!I:I,B8,DATOS!K:K,2) -> 0 | N8: =COUNTIFS(DATOS!G:G,CONFIG_METADATA!$B$4,DATOS!I:I,B8,DATOS!K:K,3) -> 0 | O8: =COUNTIFS(DATOS!G:G,CONFIG_METADATA!$B$4,DATOS!I:I,B8,DATOS!K:K,4) -> 0 | P8: =COUNTIFS(DATOS!G:G,CONFIG_METADATA!$B$4,DATOS!I:I,B8,DATOS!K:K,5) -> 0 | Q8: =COUNTIFS(DATOS!G:G,CONFIG_METADATA!$B$4,DATOS!I:I,B8,DATOS!K:K,6) -> 0 | R8: =COUNTIFS(DATOS!G:G,CONFIG_METADATA!$B$4,DATOS!I:I,B8,DATOS!K:K,7) -> 0 | S8: =COUNTIFS(DATOS!G:G,CONFIG_METADATA!$B$4,DATOS!I:I,B8,DATOS!K:K,8) -> 0 | T8: =COUNTIFS(DATOS!G:G,CONFIG_METADATA!$B$4,DATOS!I:I,B8,DATOS!K:K,9) -> 0 | U8: =COUNTIFS(DATOS!G:G,CONFIG_METADATA!$B$4,DATOS!I:I,B8,DATOS!K:K,10) -> 0
A9: GLOBAL | B9: {=IFERROR(INDEX(_xlfn._xlws.FILTER(CONFIG_ASIGNATURAS!$B$2:$B$61,CONFIG_ASIGNATURAS!$G$2:$G$61="Sí"),5),"")} | C9: =IF(B9="","",IFERROR(IF(VLOOKUP(B9,CONFIG_ASIGNATURAS!$B$2:$F$61,5,FALSE())="Sí","Especialidad","Asignatura"),"Asignatura")) | D9: =COUNTIFS(DATOS!G:G,CONFIG_METADATA!$B$4,DATOS!I:I,B9) -> 0 | E9: =IFERROR(AVERAGEIFS(DATOS!K:K,DATOS!G:G,CONFIG_METADATA!$B$4,DATOS!I:I,B9),"—") -> — | F9: {=IFERROR(_xlfn.STDEV.P(IF((nEVAL=CONFIG_METADATA!$B$4)*(nASIG=B9),nNOTA)),"—")} -> — | G9: {=IFERROR(_xlfn.MODE.SNGL(IF((nEVAL=CONFIG_METADATA!$B$4)*(nASIG=B9),nNOTA)),"—")} -> — | H9: =IFERROR(COUNTIFS(DATOS!G:G,CONFIG_METADATA!$B$4,DATOS!I:I,B9,DATOS!L:L,"S")/COUNTIFS(DATOS!G:G,CONFIG_METADATA!$B$4,DATOS!I:I,B9),"—") -> — | I9: =IFERROR(COUNTIFS(DATOS!G:G,CONFIG_METADATA!$B$4,DATOS!I:I,B9,DATOS!L:L,"N")/COUNTIFS(DATOS!G:G,CONFIG_METADATA!$B$4,DATOS!I:I,B9),"—") -> — | J9: {=IFERROR(_xlfn.MODE.SNGL(IF((nEVAL=CONFIG_METADATA!$B$4)*(nASIG=B9)*(nAPTO="S"),nNOTA)),"—")} -> — | K9: {=IFERROR(_xlfn.MODE.SNGL(IF((nEVAL=CONFIG_METADATA!$B$4)*(nASIG=B9)*(nAPTO="N"),nNOTA)),"—")} -> — | L9: =COUNTIFS(DATOS!G:G,CONFIG_METADATA!$B$4,DATOS!I:I,B9,DATOS!K:K,1) -> 0 | M9: =COUNTIFS(DATOS!G:G,CONFIG_METADATA!$B$4,DATOS!I:I,B9,DATOS!K:K,2) -> 0 | N9: =COUNTIFS(DATOS!G:G,CONFIG_METADATA!$B$4,DATOS!I:I,B9,DATOS!K:K,3) -> 0 | O9: =COUNTIFS(DATOS!G:G,CONFIG_METADATA!$B$4,DATOS!I:I,B9,DATOS!K:K,4) -> 0 | P9: =COUNTIFS(DATOS!G:G,CONFIG_METADATA!$B$4,DATOS!I:I,B9,DATOS!K:K,5) -> 0 | Q9: =COUNTIFS(DATOS!G:G,CONFIG_METADATA!$B$4,DATOS!I:I,B9,DATOS!K:K,6) -> 0 | R9: =COUNTIFS(DATOS!G:G,CONFIG_METADATA!$B$4,DATOS!I:I,B9,DATOS!K:K,7) -> 0 | S9: =COUNTIFS(DATOS!G:G,CONFIG_METADATA!$B$4,DATOS!I:I,B9,DATOS!K:K,8) -> 0 | T9: =COUNTIFS(DATOS!G:G,CONFIG_METADATA!$B$4,DATOS!I:I,B9,DATOS!K:K,9) -> 0 | U9: =COUNTIFS(DATOS!G:G,CONFIG_METADATA!$B$4,DATOS!I:I,B9,DATOS!K:K,10) -> 0
A10: GLOBAL | B10: {=IFERROR(INDEX(_xlfn._xlws.FILTER(CONFIG_ASIGNATURAS!$B$2:$B$61,CONFIG_ASIGNATURAS!$G$2:$G$61="Sí"),6),"")} | C10: =IF(B10="","",IFERROR(IF(VLOOKUP(B10,CONFIG_ASIGNATURAS!$B$2:$F$61,5,FALSE())="Sí","Especialidad","Asignatura"),"Asignatura")) | D10: =COUNTIFS(DATOS!G:G,CONFIG_METADATA!$B$4,DATOS!I:I,B10) -> 0 | E10: =IFERROR(AVERAGEIFS(DATOS!K:K,DATOS!G:G,CONFIG_METADATA!$B$4,DATOS!I:I,B10),"—") -> — | F10: {=IFERROR(_xlfn.STDEV.P(IF((nEVAL=CONFIG_METADATA!$B$4)*(nASIG=B10),nNOTA)),"—")} -> — | G10: {=IFERROR(_xlfn.MODE.SNGL(IF((nEVAL=CONFIG_METADATA!$B$4)*(nASIG=B10),nNOTA)),"—")} -> — | H10: =IFERROR(COUNTIFS(DATOS!G:G,CONFIG_METADATA!$B$4,DATOS!I:I,B10,DATOS!L:L,"S")/COUNTIFS(DATOS!G:G,CONFIG_METADATA!$B$4,DATOS!I:I,B10),"—") -> — | I10: =IFERROR(COUNTIFS(DATOS!G:G,CONFIG_METADATA!$B$4,DATOS!I:I,B10,DATOS!L:L,"N")/COUNTIFS(DATOS!G:G,CONFIG_METADATA!$B$4,DATOS!I:I,B10),"—") -> — | J10: {=IFERROR(_xlfn.MODE.SNGL(IF((nEVAL=CONFIG_METADATA!$B$4)*(nASIG=B10)*(nAPTO="S"),nNOTA)),"—")} -> — | K10: {=IFERROR(_xlfn.MODE.SNGL(IF((nEVAL=CONFIG_METADATA!$B$4)*(nASIG=B10)*(nAPTO="N"),nNOTA)),"—")} -> — | L10: =COUNTIFS(DATOS!G:G,CONFIG_METADATA!$B$4,DATOS!I:I,B10,DATOS!K:K,1) -> 0 | M10: =COUNTIFS(DATOS!G:G,CONFIG_METADATA!$B$4,DATOS!I:I,B10,DATOS!K:K,2) -> 0 | N10: =COUNTIFS(DATOS!G:G,CONFIG_METADATA!$B$4,DATOS!I:I,B10,DATOS!K:K,3) -> 0 | O10: =COUNTIFS(DATOS!G:G,CONFIG_METADATA!$B$4,DATOS!I:I,B10,DATOS!K:K,4) -> 0 | P10: =COUNTIFS(DATOS!G:G,CONFIG_METADATA!$B$4,DATOS!I:I,B10,DATOS!K:K,5) -> 0 | Q10: =COUNTIFS(DATOS!G:G,CONFIG_METADATA!$B$4,DATOS!I:I,B10,DATOS!K:K,6) -> 0 | R10: =COUNTIFS(DATOS!G:G,CONFIG_METADATA!$B$4,DATOS!I:I,B10,DATOS!K:K,7) -> 0 | S10: =COUNTIFS(DATOS!G:G,CONFIG_METADATA!$B$4,DATOS!I:I,B10,DATOS!K:K,8) -> 0 | T10: =COUNTIFS(DATOS!G:G,CONFIG_METADATA!$B$4,DATOS!I:I,B10,DATOS!K:K,9) -> 0 | U10: =COUNTIFS(DATOS!G:G,CONFIG_METADATA!$B$4,DATOS!I:I,B10,DATOS!K:K,10) -> 0
A11: GLOBAL | B11: {=IFERROR(INDEX(_xlfn._xlws.FILTER(CONFIG_ASIGNATURAS!$B$2:$B$61,CONFIG_ASIGNATURAS!$G$2:$G$61="Sí"),7),"")} | C11: =IF(B11="","",IFERROR(IF(VLOOKUP(B11,CONFIG_ASIGNATURAS!$B$2:$F$61,5,FALSE())="Sí","Especialidad","Asignatura"),"Asignatura")) | D11: =COUNTIFS(DATOS!G:G,CONFIG_METADATA!$B$4,DATOS!I:I,B11) -> 0 | E11: =IFERROR(AVERAGEIFS(DATOS!K:K,DATOS!G:G,CONFIG_METADATA!$B$4,DATOS!I:I,B11),"—") -> — | F11: {=IFERROR(_xlfn.STDEV.P(IF((nEVAL=CONFIG_METADATA!$B$4)*(nASIG=B11),nNOTA)),"—")} -> — | G11: {=IFERROR(_xlfn.MODE.SNGL(IF((nEVAL=CONFIG_METADATA!$B$4)*(nASIG=B11),nNOTA)),"—")} -> — | H11: =IFERROR(COUNTIFS(DATOS!G:G,CONFIG_METADATA!$B$4,DATOS!I:I,B11,DATOS!L:L,"S")/COUNTIFS(DATOS!G:G,CONFIG_METADATA!$B$4,DATOS!I:I,B11),"—") -> — | I11: =IFERROR(COUNTIFS(DATOS!G:G,CONFIG_METADATA!$B$4,DATOS!I:I,B11,DATOS!L:L,"N")/COUNTIFS(DATOS!G:G,CONFIG_METADATA!$B$4,DATOS!I:I,B11),"—") -> — | J11: {=IFERROR(_xlfn.MODE.SNGL(IF((nEVAL=CONFIG_METADATA!$B$4)*(nASIG=B11)*(nAPTO="S"),nNOTA)),"—")} -> — | K11: {=IFERROR(_xlfn.MODE.SNGL(IF((nEVAL=CONFIG_METADATA!$B$4)*(nASIG=B11)*(nAPTO="N"),nNOTA)),"—")} -> — | L11: =COUNTIFS(DATOS!G:G,CONFIG_METADATA!$B$4,DATOS!I:I,B11,DATOS!K:K,1) -> 0 | M11: =COUNTIFS(DATOS!G:G,CONFIG_METADATA!$B$4,DATOS!I:I,B11,DATOS!K:K,2) -> 0 | N11: =COUNTIFS(DATOS!G:G,CONFIG_METADATA!$B$4,DATOS!I:I,B11,DATOS!K:K,3) -> 0 | O11: =COUNTIFS(DATOS!G:G,CONFIG_METADATA!$B$4,DATOS!I:I,B11,DATOS!K:K,4) -> 0 | P11: =COUNTIFS(DATOS!G:G,CONFIG_METADATA!$B$4,DATOS!I:I,B11,DATOS!K:K,5) -> 0 | Q11: =COUNTIFS(DATOS!G:G,CONFIG_METADATA!$B$4,DATOS!I:I,B11,DATOS!K:K,6) -> 0 | R11: =COUNTIFS(DATOS!G:G,CONFIG_METADATA!$B$4,DATOS!I:I,B11,DATOS!K:K,7) -> 0 | S11: =COUNTIFS(DATOS!G:G,CONFIG_METADATA!$B$4,DATOS!I:I,B11,DATOS!K:K,8) -> 0 | T11: =COUNTIFS(DATOS!G:G,CONFIG_METADATA!$B$4,DATOS!I:I,B11,DATOS!K:K,9) -> 0 | U11: =COUNTIFS(DATOS!G:G,CONFIG_METADATA!$B$4,DATOS!I:I,B11,DATOS!K:K,10) -> 0
A12: GLOBAL | B12: {=IFERROR(INDEX(_xlfn._xlws.FILTER(CONFIG_ASIGNATURAS!$B$2:$B$61,CONFIG_ASIGNATURAS!$G$2:$G$61="Sí"),8),"")} | C12: =IF(B12="","",IFERROR(IF(VLOOKUP(B12,CONFIG_ASIGNATURAS!$B$2:$F$61,5,FALSE())="Sí","Especialidad","Asignatura"),"Asignatura")) | D12: =COUNTIFS(DATOS!G:G,CONFIG_METADATA!$B$4,DATOS!I:I,B12) -> 0 | E12: =IFERROR(AVERAGEIFS(DATOS!K:K,DATOS!G:G,CONFIG_METADATA!$B$4,DATOS!I:I,B12),"—") -> — | F12: {=IFERROR(_xlfn.STDEV.P(IF((nEVAL=CONFIG_METADATA!$B$4)*(nASIG=B12),nNOTA)),"—")} -> — | G12: {=IFERROR(_xlfn.MODE.SNGL(IF((nEVAL=CONFIG_METADATA!$B$4)*(nASIG=B12),nNOTA)),"—")} -> — | H12: =IFERROR(COUNTIFS(DATOS!G:G,CONFIG_METADATA!$B$4,DATOS!I:I,B12,DATOS!L:L,"S")/COUNTIFS(DATOS!G:G,CONFIG_METADATA!$B$4,DATOS!I:I,B12),"—") -> — | I12: =IFERROR(COUNTIFS(DATOS!G:G,CONFIG_METADATA!$B$4,DATOS!I:I,B12,DATOS!L:L,"N")/COUNTIFS(DATOS!G:G,CONFIG_METADATA!$B$4,DATOS!I:I,B12),"—") -> — | J12: {=IFERROR(_xlfn.MODE.SNGL(IF((nEVAL=CONFIG_METADATA!$B$4)*(nASIG=B12)*(nAPTO="S"),nNOTA)),"—")} -> — | K12: {=IFERROR(_xlfn.MODE.SNGL(IF((nEVAL=CONFIG_METADATA!$B$4)*(nASIG=B12)*(nAPTO="N"),nNOTA)),"—")} -> — | L12: =COUNTIFS(DATOS!G:G,CONFIG_METADATA!$B$4,DATOS!I:I,B12,DATOS!K:K,1) -> 0 | M12: =COUNTIFS(DATOS!G:G,CONFIG_METADATA!$B$4,DATOS!I:I,B12,DATOS!K:K,2) -> 0 | N12: =COUNTIFS(DATOS!G:G,CONFIG_METADATA!$B$4,DATOS!I:I,B12,DATOS!K:K,3) -> 0 | O12: =COUNTIFS(DATOS!G:G,CONFIG_METADATA!$B$4,DATOS!I:I,B12,DATOS!K:K,4) -> 0 | P12: =COUNTIFS(DATOS!G:G,CONFIG_METADATA!$B$4,DATOS!I:I,B12,DATOS!K:K,5) -> 0 | Q12: =COUNTIFS(DATOS!G:G,CONFIG_METADATA!$B$4,DATOS!I:I,B12,DATOS!K:K,6) -> 0 | R12: =COUNTIFS(DATOS!G:G,CONFIG_METADATA!$B$4,DATOS!I:I,B12,DATOS!K:K,7) -> 0 | S12: =COUNTIFS(DATOS!G:G,CONFIG_METADATA!$B$4,DATOS!I:I,B12,DATOS!K:K,8) -> 0 | T12: =COUNTIFS(DATOS!G:G,CONFIG_METADATA!$B$4,DATOS!I:I,B12,DATOS!K:K,9) -> 0 | U12: =COUNTIFS(DATOS!G:G,CONFIG_METADATA!$B$4,DATOS!I:I,B12,DATOS!K:K,10) -> 0
A13: GLOBAL | B13: {=IFERROR(INDEX(_xlfn._xlws.FILTER(CONFIG_ASIGNATURAS!$B$2:$B$61,CONFIG_ASIGNATURAS!$G$2:$G$61="Sí"),9),"")} | C13: =IF(B13="","",IFERROR(IF(VLOOKUP(B13,CONFIG_ASIGNATURAS!$B$2:$F$61,5,FALSE())="Sí","Especialidad","Asignatura"),"Asignatura")) | D13: =COUNTIFS(DATOS!G:G,CONFIG_METADATA!$B$4,DATOS!I:I,B13) -> 0 | E13: =IFERROR(AVERAGEIFS(DATOS!K:K,DATOS!G:G,CONFIG_METADATA!$B$4,DATOS!I:I,B13),"—") -> — | F13: {=IFERROR(_xlfn.STDEV.P(IF((nEVAL=CONFIG_METADATA!$B$4)*(nASIG=B13),nNOTA)),"—")} -> — | G13: {=IFERROR(_xlfn.MODE.SNGL(IF((nEVAL=CONFIG_METADATA!$B$4)*(nASIG=B13),nNOTA)),"—")} -> — | H13: =IFERROR(COUNTIFS(DATOS!G:G,CONFIG_METADATA!$B$4,DATOS!I:I,B13,DATOS!L:L,"S")/COUNTIFS(DATOS!G:G,CONFIG_METADATA!$B$4,DATOS!I:I,B13),"—") -> — | I13: =IFERROR(COUNTIFS(DATOS!G:G,CONFIG_METADATA!$B$4,DATOS!I:I,B13,DATOS!L:L,"N")/COUNTIFS(DATOS!G:G,CONFIG_METADATA!$B$4,DATOS!I:I,B13),"—") -> — | J13: {=IFERROR(_xlfn.MODE.SNGL(IF((nEVAL=CONFIG_METADATA!$B$4)*(nASIG=B13)*(nAPTO="S"),nNOTA)),"—")} -> — | K13: {=IFERROR(_xlfn.MODE.SNGL(IF((nEVAL=CONFIG_METADATA!$B$4)*(nASIG=B13)*(nAPTO="N"),nNOTA)),"—")} -> — | L13: =COUNTIFS(DATOS!G:G,CONFIG_METADATA!$B$4,DATOS!I:I,B13,DATOS!K:K,1) -> 0 | M13: =COUNTIFS(DATOS!G:G,CONFIG_METADATA!$B$4,DATOS!I:I,B13,DATOS!K:K,2) -> 0 | N13: =COUNTIFS(DATOS!G:G,CONFIG_METADATA!$B$4,DATOS!I:I,B13,DATOS!K:K,3) -> 0 | O13: =COUNTIFS(DATOS!G:G,CONFIG_METADATA!$B$4,DATOS!I:I,B13,DATOS!K:K,4) -> 0 | P13: =COUNTIFS(DATOS!G:G,CONFIG_METADATA!$B$4,DATOS!I:I,B13,DATOS!K:K,5) -> 0 | Q13: =COUNTIFS(DATOS!G:G,CONFIG_METADATA!$B$4,DATOS!I:I,B13,DATOS!K:K,6) -> 0 | R13: =COUNTIFS(DATOS!G:G,CONFIG_METADATA!$B$4,DATOS!I:I,B13,DATOS!K:K,7) -> 0 | S13: =COUNTIFS(DATOS!G:G,CONFIG_METADATA!$B$4,DATOS!I:I,B13,DATOS!K:K,8) -> 0 | T13: =COUNTIFS(DATOS!G:G,CONFIG_METADATA!$B$4,DATOS!I:I,B13,DATOS!K:K,9) -> 0 | U13: =COUNTIFS(DATOS!G:G,CONFIG_METADATA!$B$4,DATOS!I:I,B13,DATOS!K:K,10) -> 0
A14: GLOBAL | B14: {=IFERROR(INDEX(_xlfn._xlws.FILTER(CONFIG_ASIGNATURAS!$B$2:$B$61,CONFIG_ASIGNATURAS!$G$2:$G$61="Sí"),10),"")} | C14: =IF(B14="","",IFERROR(IF(VLOOKUP(B14,CONFIG_ASIGNATURAS!$B$2:$F$61,5,FALSE())="Sí","Especialidad","Asignatura"),"Asignatura")) | D14: =COUNTIFS(DATOS!G:G,CONFIG_METADATA!$B$4,DATOS!I:I,B14) -> 0 | E14: =IFERROR(AVERAGEIFS(DATOS!K:K,DATOS!G:G,CONFIG_METADATA!$B$4,DATOS!I:I,B14),"—") -> — | F14: {=IFERROR(_xlfn.STDEV.P(IF((nEVAL=CONFIG_METADATA!$B$4)*(nASIG=B14),nNOTA)),"—")} -> — | G14: {=IFERROR(_xlfn.MODE.SNGL(IF((nEVAL=CONFIG_METADATA!$B$4)*(nASIG=B14),nNOTA)),"—")} -> — | H14: =IFERROR(COUNTIFS(DATOS!G:G,CONFIG_METADATA!$B$4,DATOS!I:I,B14,DATOS!L:L,"S")/COUNTIFS(DATOS!G:G,CONFIG_METADATA!$B$4,DATOS!I:I,B14),"—") -> — | I14: =IFERROR(COUNTIFS(DATOS!G:G,CONFIG_METADATA!$B$4,DATOS!I:I,B14,DATOS!L:L,"N")/COUNTIFS(DATOS!G:G,CONFIG_METADATA!$B$4,DATOS!I:I,B14),"—") -> — | J14: {=IFERROR(_xlfn.MODE.SNGL(IF((nEVAL=CONFIG_METADATA!$B$4)*(nASIG=B14)*(nAPTO="S"),nNOTA)),"—")} -> — | K14: {=IFERROR(_xlfn.MODE.SNGL(IF((nEVAL=CONFIG_METADATA!$B$4)*(nASIG=B14)*(nAPTO="N"),nNOTA)),"—")} -> — | L14: =COUNTIFS(DATOS!G:G,CONFIG_METADATA!$B$4,DATOS!I:I,B14,DATOS!K:K,1) -> 0 | M14: =COUNTIFS(DATOS!G:G,CONFIG_METADATA!$B$4,DATOS!I:I,B14,DATOS!K:K,2) -> 0 | N14: =COUNTIFS(DATOS!G:G,CONFIG_METADATA!$B$4,DATOS!I:I,B14,DATOS!K:K,3) -> 0 | O14: =COUNTIFS(DATOS!G:G,CONFIG_METADATA!$B$4,DATOS!I:I,B14,DATOS!K:K,4) -> 0 | P14: =COUNTIFS(DATOS!G:G,CONFIG_METADATA!$B$4,DATOS!I:I,B14,DATOS!K:K,5) -> 0 | Q14: =COUNTIFS(DATOS!G:G,CONFIG_METADATA!$B$4,DATOS!I:I,B14,DATOS!K:K,6) -> 0 | R14: =COUNTIFS(DATOS!G:G,CONFIG_METADATA!$B$4,DATOS!I:I,B14,DATOS!K:K,7) -> 0 | S14: =COUNTIFS(DATOS!G:G,CONFIG_METADATA!$B$4,DATOS!I:I,B14,DATOS!K:K,8) -> 0 | T14: =COUNTIFS(DATOS!G:G,CONFIG_METADATA!$B$4,DATOS!I:I,B14,DATOS!K:K,9) -> 0 | U14: =COUNTIFS(DATOS!G:G,CONFIG_METADATA!$B$4,DATOS!I:I,B14,DATOS!K:K,10) -> 0
A15: GLOBAL | B15: {=IFERROR(INDEX(_xlfn._xlws.FILTER(CONFIG_ASIGNATURAS!$B$2:$B$61,CONFIG_ASIGNATURAS!$G$2:$G$61="Sí"),11),"")} | C15: =IF(B15="","",IFERROR(IF(VLOOKUP(B15,CONFIG_ASIGNATURAS!$B$2:$F$61,5,FALSE())="Sí","Especialidad","Asignatura"),"Asignatura")) | D15: =COUNTIFS(DATOS!G:G,CONFIG_METADATA!$B$4,DATOS!I:I,B15) -> 0 | E15: =IFERROR(AVERAGEIFS(DATOS!K:K,DATOS!G:G,CONFIG_METADATA!$B$4,DATOS!I:I,B15),"—") -> — | F15: {=IFERROR(_xlfn.STDEV.P(IF((nEVAL=CONFIG_METADATA!$B$4)*(nASIG=B15),nNOTA)),"—")} -> — | G15: {=IFERROR(_xlfn.MODE.SNGL(IF((nEVAL=CONFIG_METADATA!$B$4)*(nASIG=B15),nNOTA)),"—")} -> — | H15: =IFERROR(COUNTIFS(DATOS!G:G,CONFIG_METADATA!$B$4,DATOS!I:I,B15,DATOS!L:L,"S")/COUNTIFS(DATOS!G:G,CONFIG_METADATA!$B$4,DATOS!I:I,B15),"—") -> — | I15: =IFERROR(COUNTIFS(DATOS!G:G,CONFIG_METADATA!$B$4,DATOS!I:I,B15,DATOS!L:L,"N")/COUNTIFS(DATOS!G:G,CONFIG_METADATA!$B$4,DATOS!I:I,B15),"—") -> — | J15: {=IFERROR(_xlfn.MODE.SNGL(IF((nEVAL=CONFIG_METADATA!$B$4)*(nASIG=B15)*(nAPTO="S"),nNOTA)),"—")} -> — | K15: {=IFERROR(_xlfn.MODE.SNGL(IF((nEVAL=CONFIG_METADATA!$B$4)*(nASIG=B15)*(nAPTO="N"),nNOTA)),"—")} -> — | L15: =COUNTIFS(DATOS!G:G,CONFIG_METADATA!$B$4,DATOS!I:I,B15,DATOS!K:K,1) -> 0 | M15: =COUNTIFS(DATOS!G:G,CONFIG_METADATA!$B$4,DATOS!I:I,B15,DATOS!K:K,2) -> 0 | N15: =COUNTIFS(DATOS!G:G,CONFIG_METADATA!$B$4,DATOS!I:I,B15,DATOS!K:K,3) -> 0 | O15: =COUNTIFS(DATOS!G:G,CONFIG_METADATA!$B$4,DATOS!I:I,B15,DATOS!K:K,4) -> 0 | P15: =COUNTIFS(DATOS!G:G,CONFIG_METADATA!$B$4,DATOS!I:I,B15,DATOS!K:K,5) -> 0 | Q15: =COUNTIFS(DATOS!G:G,CONFIG_METADATA!$B$4,DATOS!I:I,B15,DATOS!K:K,6) -> 0 | R15: =COUNTIFS(DATOS!G:G,CONFIG_METADATA!$B$4,DATOS!I:I,B15,DATOS!K:K,7) -> 0 | S15: =COUNTIFS(DATOS!G:G,CONFIG_METADATA!$B$4,DATOS!I:I,B15,DATOS!K:K,8) -> 0 | T15: =COUNTIFS(DATOS!G:G,CONFIG_METADATA!$B$4,DATOS!I:I,B15,DATOS!K:K,9) -> 0 | U15: =COUNTIFS(DATOS!G:G,CONFIG_METADATA!$B$4,DATOS!I:I,B15,DATOS!K:K,10) -> 0
A16: GLOBAL | B16: {=IFERROR(INDEX(_xlfn._xlws.FILTER(CONFIG_ASIGNATURAS!$B$2:$B$61,CONFIG_ASIGNATURAS!$G$2:$G$61="Sí"),12),"")} | C16: =IF(B16="","",IFERROR(IF(VLOOKUP(B16,CONFIG_ASIGNATURAS!$B$2:$F$61,5,FALSE())="Sí","Especialidad","Asignatura"),"Asignatura")) | D16: =COUNTIFS(DATOS!G:G,CONFIG_METADATA!$B$4,DATOS!I:I,B16) -> 0 | E16: =IFERROR(AVERAGEIFS(DATOS!K:K,DATOS!G:G,CONFIG_METADATA!$B$4,DATOS!I:I,B16),"—") -> — | F16: {=IFERROR(_xlfn.STDEV.P(IF((nEVAL=CONFIG_METADATA!$B$4)*(nASIG=B16),nNOTA)),"—")} -> — | G16: {=IFERROR(_xlfn.MODE.SNGL(IF((nEVAL=CONFIG_METADATA!$B$4)*(nASIG=B16),nNOTA)),"—")} -> — | H16: =IFERROR(COUNTIFS(DATOS!G:G,CONFIG_METADATA!$B$4,DATOS!I:I,B16,DATOS!L:L,"S")/COUNTIFS(DATOS!G:G,CONFIG_METADATA!$B$4,DATOS!I:I,B16),"—") -> — | I16: =IFERROR(COUNTIFS(DATOS!G:G,CONFIG_METADATA!$B$4,DATOS!I:I,B16,DATOS!L:L,"N")/COUNTIFS(DATOS!G:G,CONFIG_METADATA!$B$4,DATOS!I:I,B16),"—") -> — | J16: {=IFERROR(_xlfn.MODE.SNGL(IF((nEVAL=CONFIG_METADATA!$B$4)*(nASIG=B16)*(nAPTO="S"),nNOTA)),"—")} -> — | K16: {=IFERROR(_xlfn.MODE.SNGL(IF((nEVAL=CONFIG_METADATA!$B$4)*(nASIG=B16)*(nAPTO="N"),nNOTA)),"—")} -> — | L16: =COUNTIFS(DATOS!G:G,CONFIG_METADATA!$B$4,DATOS!I:I,B16,DATOS!K:K,1) -> 0 | M16: =COUNTIFS(DATOS!G:G,CONFIG_METADATA!$B$4,DATOS!I:I,B16,DATOS!K:K,2) -> 0 | N16: =COUNTIFS(DATOS!G:G,CONFIG_METADATA!$B$4,DATOS!I:I,B16,DATOS!K:K,3) -> 0 | O16: =COUNTIFS(DATOS!G:G,CONFIG_METADATA!$B$4,DATOS!I:I,B16,DATOS!K:K,4) -> 0 | P16: =COUNTIFS(DATOS!G:G,CONFIG_METADATA!$B$4,DATOS!I:I,B16,DATOS!K:K,5) -> 0 | Q16: =COUNTIFS(DATOS!G:G,CONFIG_METADATA!$B$4,DATOS!I:I,B16,DATOS!K:K,6) -> 0 | R16: =COUNTIFS(DATOS!G:G,CONFIG_METADATA!$B$4,DATOS!I:I,B16,DATOS!K:K,7) -> 0 | S16: =COUNTIFS(DATOS!G:G,CONFIG_METADATA!$B$4,DATOS!I:I,B16,DATOS!K:K,8) -> 0 | T16: =COUNTIFS(DATOS!G:G,CONFIG_METADATA!$B$4,DATOS!I:I,B16,DATOS!K:K,9) -> 0 | U16: =COUNTIFS(DATOS!G:G,CONFIG_METADATA!$B$4,DATOS!I:I,B16,DATOS!K:K,10) -> 0
A17: GLOBAL | B17: {=IFERROR(INDEX(_xlfn._xlws.FILTER(CONFIG_ASIGNATURAS!$B$2:$B$61,CONFIG_ASIGNATURAS!$G$2:$G$61="Sí"),13),"")} | C17: =IF(B17="","",IFERROR(IF(VLOOKUP(B17,CONFIG_ASIGNATURAS!$B$2:$F$61,5,FALSE())="Sí","Especialidad","Asignatura"),"Asignatura")) | D17: =COUNTIFS(DATOS!G:G,CONFIG_METADATA!$B$4,DATOS!I:I,B17) -> 0 | E17: =IFERROR(AVERAGEIFS(DATOS!K:K,DATOS!G:G,CONFIG_METADATA!$B$4,DATOS!I:I,B17),"—") -> — | F17: {=IFERROR(_xlfn.STDEV.P(IF((nEVAL=CONFIG_METADATA!$B$4)*(nASIG=B17),nNOTA)),"—")} -> — | G17: {=IFERROR(_xlfn.MODE.SNGL(IF((nEVAL=CONFIG_METADATA!$B$4)*(nASIG=B17),nNOTA)),"—")} -> — | H17: =IFERROR(COUNTIFS(DATOS!G:G,CONFIG_METADATA!$B$4,DATOS!I:I,B17,DATOS!L:L,"S")/COUNTIFS(DATOS!G:G,CONFIG_METADATA!$B$4,DATOS!I:I,B17),"—") -> — | I17: =IFERROR(COUNTIFS(DATOS!G:G,CONFIG_METADATA!$B$4,DATOS!I:I,B17,DATOS!L:L,"N")/COUNTIFS(DATOS!G:G,CONFIG_METADATA!$B$4,DATOS!I:I,B17),"—") -> — | J17: {=IFERROR(_xlfn.MODE.SNGL(IF((nEVAL=CONFIG_METADATA!$B$4)*(nASIG=B17)*(nAPTO="S"),nNOTA)),"—")} -> — | K17: {=IFERROR(_xlfn.MODE.SNGL(IF((nEVAL=CONFIG_METADATA!$B$4)*(nASIG=B17)*(nAPTO="N"),nNOTA)),"—")} -> — | L17: =COUNTIFS(DATOS!G:G,CONFIG_METADATA!$B$4,DATOS!I:I,B17,DATOS!K:K,1) -> 0 | M17: =COUNTIFS(DATOS!G:G,CONFIG_METADATA!$B$4,DATOS!I:I,B17,DATOS!K:K,2) -> 0 | N17: =COUNTIFS(DATOS!G:G,CONFIG_METADATA!$B$4,DATOS!I:I,B17,DATOS!K:K,3) -> 0 | O17: =COUNTIFS(DATOS!G:G,CONFIG_METADATA!$B$4,DATOS!I:I,B17,DATOS!K:K,4) -> 0 | P17: =COUNTIFS(DATOS!G:G,CONFIG_METADATA!$B$4,DATOS!I:I,B17,DATOS!K:K,5) -> 0 | Q17: =COUNTIFS(DATOS!G:G,CONFIG_METADATA!$B$4,DATOS!I:I,B17,DATOS!K:K,6) -> 0 | R17: =COUNTIFS(DATOS!G:G,CONFIG_METADATA!$B$4,DATOS!I:I,B17,DATOS!K:K,7) -> 0 | S17: =COUNTIFS(DATOS!G:G,CONFIG_METADATA!$B$4,DATOS!I:I,B17,DATOS!K:K,8) -> 0 | T17: =COUNTIFS(DATOS!G:G,CONFIG_METADATA!$B$4,DATOS!I:I,B17,DATOS!K:K,9) -> 0 | U17: =COUNTIFS(DATOS!G:G,CONFIG_METADATA!$B$4,DATOS!I:I,B17,DATOS!K:K,10) -> 0
A18: GLOBAL | B18: {=IFERROR(INDEX(_xlfn._xlws.FILTER(CONFIG_ASIGNATURAS!$B$2:$B$61,CONFIG_ASIGNATURAS!$G$2:$G$61="Sí"),14),"")} | C18: =IF(B18="","",IFERROR(IF(VLOOKUP(B18,CONFIG_ASIGNATURAS!$B$2:$F$61,5,FALSE())="Sí","Especialidad","Asignatura"),"Asignatura")) | D18: =COUNTIFS(DATOS!G:G,CONFIG_METADATA!$B$4,DATOS!I:I,B18) -> 0 | E18: =IFERROR(AVERAGEIFS(DATOS!K:K,DATOS!G:G,CONFIG_METADATA!$B$4,DATOS!I:I,B18),"—") -> — | F18: {=IFERROR(_xlfn.STDEV.P(IF((nEVAL=CONFIG_METADATA!$B$4)*(nASIG=B18),nNOTA)),"—")} -> — | G18: {=IFERROR(_xlfn.MODE.SNGL(IF((nEVAL=CONFIG_METADATA!$B$4)*(nASIG=B18),nNOTA)),"—")} -> — | H18: =IFERROR(COUNTIFS(DATOS!G:G,CONFIG_METADATA!$B$4,DATOS!I:I,B18,DATOS!L:L,"S")/COUNTIFS(DATOS!G:G,CONFIG_METADATA!$B$4,DATOS!I:I,B18),"—") -> — | I18: =IFERROR(COUNTIFS(DATOS!G:G,CONFIG_METADATA!$B$4,DATOS!I:I,B18,DATOS!L:L,"N")/COUNTIFS(DATOS!G:G,CONFIG_METADATA!$B$4,DATOS!I:I,B18),"—") -> — | J18: {=IFERROR(_xlfn.MODE.SNGL(IF((nEVAL=CONFIG_METADATA!$B$4)*(nASIG=B18)*(nAPTO="S"),nNOTA)),"—")} -> — | K18: {=IFERROR(_xlfn.MODE.SNGL(IF((nEVAL=CONFIG_METADATA!$B$4)*(nASIG=B18)*(nAPTO="N"),nNOTA)),"—")} -> — | L18: =COUNTIFS(DATOS!G:G,CONFIG_METADATA!$B$4,DATOS!I:I,B18,DATOS!K:K,1) -> 0 | M18: =COUNTIFS(DATOS!G:G,CONFIG_METADATA!$B$4,DATOS!I:I,B18,DATOS!K:K,2) -> 0 | N18: =COUNTIFS(DATOS!G:G,CONFIG_METADATA!$B$4,DATOS!I:I,B18,DATOS!K:K,3) -> 0 | O18: =COUNTIFS(DATOS!G:G,CONFIG_METADATA!$B$4,DATOS!I:I,B18,DATOS!K:K,4) -> 0 | P18: =COUNTIFS(DATOS!G:G,CONFIG_METADATA!$B$4,DATOS!I:I,B18,DATOS!K:K,5) -> 0 | Q18: =COUNTIFS(DATOS!G:G,CONFIG_METADATA!$B$4,DATOS!I:I,B18,DATOS!K:K,6) -> 0 | R18: =COUNTIFS(DATOS!G:G,CONFIG_METADATA!$B$4,DATOS!I:I,B18,DATOS!K:K,7) -> 0 | S18: =COUNTIFS(DATOS!G:G,CONFIG_METADATA!$B$4,DATOS!I:I,B18,DATOS!K:K,8) -> 0 | T18: =COUNTIFS(DATOS!G:G,CONFIG_METADATA!$B$4,DATOS!I:I,B18,DATOS!K:K,9) -> 0 | U18: =COUNTIFS(DATOS!G:G,CONFIG_METADATA!$B$4,DATOS!I:I,B18,DATOS!K:K,10) -> 0
A19: GLOBAL | B19: {=IFERROR(INDEX(_xlfn._xlws.FILTER(CONFIG_ASIGNATURAS!$B$2:$B$61,CONFIG_ASIGNATURAS!$G$2:$G$61="Sí"),15),"")} | C19: =IF(B19="","",IFERROR(IF(VLOOKUP(B19,CONFIG_ASIGNATURAS!$B$2:$F$61,5,FALSE())="Sí","Especialidad","Asignatura"),"Asignatura")) | D19: =COUNTIFS(DATOS!G:G,CONFIG_METADATA!$B$4,DATOS!I:I,B19) -> 0 | E19: =IFERROR(AVERAGEIFS(DATOS!K:K,DATOS!G:G,CONFIG_METADATA!$B$4,DATOS!I:I,B19),"—") -> — | F19: {=IFERROR(_xlfn.STDEV.P(IF((nEVAL=CONFIG_METADATA!$B$4)*(nASIG=B19),nNOTA)),"—")} -> — | G19: {=IFERROR(_xlfn.MODE.SNGL(IF((nEVAL=CONFIG_METADATA!$B$4)*(nASIG=B19),nNOTA)),"—")} -> — | H19: =IFERROR(COUNTIFS(DATOS!G:G,CONFIG_METADATA!$B$4,DATOS!I:I,B19,DATOS!L:L,"S")/COUNTIFS(DATOS!G:G,CONFIG_METADATA!$B$4,DATOS!I:I,B19),"—") -> — | I19: =IFERROR(COUNTIFS(DATOS!G:G,CONFIG_METADATA!$B$4,DATOS!I:I,B19,DATOS!L:L,"N")/COUNTIFS(DATOS!G:G,CONFIG_METADATA!$B$4,DATOS!I:I,B19),"—") -> — | J19: {=IFERROR(_xlfn.MODE.SNGL(IF((nEVAL=CONFIG_METADATA!$B$4)*(nASIG=B19)*(nAPTO="S"),nNOTA)),"—")} -> — | K19: {=IFERROR(_xlfn.MODE.SNGL(IF((nEVAL=CONFIG_METADATA!$B$4)*(nASIG=B19)*(nAPTO="N"),nNOTA)),"—")} -> — | L19: =COUNTIFS(DATOS!G:G,CONFIG_METADATA!$B$4,DATOS!I:I,B19,DATOS!K:K,1) -> 0 | M19: =COUNTIFS(DATOS!G:G,CONFIG_METADATA!$B$4,DATOS!I:I,B19,DATOS!K:K,2) -> 0 | N19: =COUNTIFS(DATOS!G:G,CONFIG_METADATA!$B$4,DATOS!I:I,B19,DATOS!K:K,3) -> 0 | O19: =COUNTIFS(DATOS!G:G,CONFIG_METADATA!$B$4,DATOS!I:I,B19,DATOS!K:K,4) -> 0 | P19: =COUNTIFS(DATOS!G:G,CONFIG_METADATA!$B$4,DATOS!I:I,B19,DATOS!K:K,5) -> 0 | Q19: =COUNTIFS(DATOS!G:G,CONFIG_METADATA!$B$4,DATOS!I:I,B19,DATOS!K:K,6) -> 0 | R19: =COUNTIFS(DATOS!G:G,CONFIG_METADATA!$B$4,DATOS!I:I,B19,DATOS!K:K,7) -> 0 | S19: =COUNTIFS(DATOS!G:G,CONFIG_METADATA!$B$4,DATOS!I:I,B19,DATOS!K:K,8) -> 0 | T19: =COUNTIFS(DATOS!G:G,CONFIG_METADATA!$B$4,DATOS!I:I,B19,DATOS!K:K,9) -> 0 | U19: =COUNTIFS(DATOS!G:G,CONFIG_METADATA!$B$4,DATOS!I:I,B19,DATOS!K:K,10) -> 0
A20: GLOBAL | B20: {=IFERROR(INDEX(_xlfn._xlws.FILTER(CONFIG_ASIGNATURAS!$B$2:$B$61,CONFIG_ASIGNATURAS!$G$2:$G$61="Sí"),16),"")} | C20: =IF(B20="","",IFERROR(IF(VLOOKUP(B20,CONFIG_ASIGNATURAS!$B$2:$F$61,5,FALSE())="Sí","Especialidad","Asignatura"),"Asignatura")) | D20: =COUNTIFS(DATOS!G:G,CONFIG_METADATA!$B$4,DATOS!I:I,B20) -> 0 | E20: =IFERROR(AVERAGEIFS(DATOS!K:K,DATOS!G:G,CONFIG_METADATA!$B$4,DATOS!I:I,B20),"—") -> — | F20: {=IFERROR(_xlfn.STDEV.P(IF((nEVAL=CONFIG_METADATA!$B$4)*(nASIG=B20),nNOTA)),"—")} -> — | G20: {=IFERROR(_xlfn.MODE.SNGL(IF((nEVAL=CONFIG_METADATA!$B$4)*(nASIG=B20),nNOTA)),"—")} -> — | H20: =IFERROR(COUNTIFS(DATOS!G:G,CONFIG_METADATA!$B$4,DATOS!I:I,B20,DATOS!L:L,"S")/COUNTIFS(DATOS!G:G,CONFIG_METADATA!$B$4,DATOS!I:I,B20),"—") -> — | I20: =IFERROR(COUNTIFS(DATOS!G:G,CONFIG_METADATA!$B$4,DATOS!I:I,B20,DATOS!L:L,"N")/COUNTIFS(DATOS!G:G,CONFIG_METADATA!$B$4,DATOS!I:I,B20),"—") -> — | J20: {=IFERROR(_xlfn.MODE.SNGL(IF((nEVAL=CONFIG_METADATA!$B$4)*(nASIG=B20)*(nAPTO="S"),nNOTA)),"—")} -> — | K20: {=IFERROR(_xlfn.MODE.SNGL(IF((nEVAL=CONFIG_METADATA!$B$4)*(nASIG=B20)*(nAPTO="N"),nNOTA)),"—")} -> — | L20: =COUNTIFS(DATOS!G:G,CONFIG_METADATA!$B$4,DATOS!I:I,B20,DATOS!K:K,1) -> 0 | M20: =COUNTIFS(DATOS!G:G,CONFIG_METADATA!$B$4,DATOS!I:I,B20,DATOS!K:K,2) -> 0 | N20: =COUNTIFS(DATOS!G:G,CONFIG_METADATA!$B$4,DATOS!I:I,B20,DATOS!K:K,3) -> 0 | O20: =COUNTIFS(DATOS!G:G,CONFIG_METADATA!$B$4,DATOS!I:I,B20,DATOS!K:K,4) -> 0 | P20: =COUNTIFS(DATOS!G:G,CONFIG_METADATA!$B$4,DATOS!I:I,B20,DATOS!K:K,5) -> 0 | Q20: =COUNTIFS(DATOS!G:G,CONFIG_METADATA!$B$4,DATOS!I:I,B20,DATOS!K:K,6) -> 0 | R20: =COUNTIFS(DATOS!G:G,CONFIG_METADATA!$B$4,DATOS!I:I,B20,DATOS!K:K,7) -> 0 | S20: =COUNTIFS(DATOS!G:G,CONFIG_METADATA!$B$4,DATOS!I:I,B20,DATOS!K:K,8) -> 0 | T20: =COUNTIFS(DATOS!G:G,CONFIG_METADATA!$B$4,DATOS!I:I,B20,DATOS!K:K,9) -> 0 | U20: =COUNTIFS(DATOS!G:G,CONFIG_METADATA!$B$4,DATOS!I:I,B20,DATOS!K:K,10) -> 0
A21: GLOBAL | B21: {=IFERROR(INDEX(_xlfn._xlws.FILTER(CONFIG_ASIGNATURAS!$B$2:$B$61,CONFIG_ASIGNATURAS!$G$2:$G$61="Sí"),17),"")} | C21: =IF(B21="","",IFERROR(IF(VLOOKUP(B21,CONFIG_ASIGNATURAS!$B$2:$F$61,5,FALSE())="Sí","Especialidad","Asignatura"),"Asignatura")) | D21: =COUNTIFS(DATOS!G:G,CONFIG_METADATA!$B$4,DATOS!I:I,B21) -> 0 | E21: =IFERROR(AVERAGEIFS(DATOS!K:K,DATOS!G:G,CONFIG_METADATA!$B$4,DATOS!I:I,B21),"—") -> — | F21: {=IFERROR(_xlfn.STDEV.P(IF((nEVAL=CONFIG_METADATA!$B$4)*(nASIG=B21),nNOTA)),"—")} -> — | G21: {=IFERROR(_xlfn.MODE.SNGL(IF((nEVAL=CONFIG_METADATA!$B$4)*(nASIG=B21),nNOTA)),"—")} -> — | H21: =IFERROR(COUNTIFS(DATOS!G:G,CONFIG_METADATA!$B$4,DATOS!I:I,B21,DATOS!L:L,"S")/COUNTIFS(DATOS!G:G,CONFIG_METADATA!$B$4,DATOS!I:I,B21),"—") -> — | I21: =IFERROR(COUNTIFS(DATOS!G:G,CONFIG_METADATA!$B$4,DATOS!I:I,B21,DATOS!L:L,"N")/COUNTIFS(DATOS!G:G,CONFIG_METADATA!$B$4,DATOS!I:I,B21),"—") -> — | J21: {=IFERROR(_xlfn.MODE.SNGL(IF((nEVAL=CONFIG_METADATA!$B$4)*(nASIG=B21)*(nAPTO="S"),nNOTA)),"—")} -> — | K21: {=IFERROR(_xlfn.MODE.SNGL(IF((nEVAL=CONFIG_METADATA!$B$4)*(nASIG=B21)*(nAPTO="N"),nNOTA)),"—")} -> — | L21: =COUNTIFS(DATOS!G:G,CONFIG_METADATA!$B$4,DATOS!I:I,B21,DATOS!K:K,1) -> 0 | M21: =COUNTIFS(DATOS!G:G,CONFIG_METADATA!$B$4,DATOS!I:I,B21,DATOS!K:K,2) -> 0 | N21: =COUNTIFS(DATOS!G:G,CONFIG_METADATA!$B$4,DATOS!I:I,B21,DATOS!K:K,3) -> 0 | O21: =COUNTIFS(DATOS!G:G,CONFIG_METADATA!$B$4,DATOS!I:I,B21,DATOS!K:K,4) -> 0 | P21: =COUNTIFS(DATOS!G:G,CONFIG_METADATA!$B$4,DATOS!I:I,B21,DATOS!K:K,5) -> 0 | Q21: =COUNTIFS(DATOS!G:G,CONFIG_METADATA!$B$4,DATOS!I:I,B21,DATOS!K:K,6) -> 0 | R21: =COUNTIFS(DATOS!G:G,CONFIG_METADATA!$B$4,DATOS!I:I,B21,DATOS!K:K,7) -> 0 | S21: =COUNTIFS(DATOS!G:G,CONFIG_METADATA!$B$4,DATOS!I:I,B21,DATOS!K:K,8) -> 0 | T21: =COUNTIFS(DATOS!G:G,CONFIG_METADATA!$B$4,DATOS!I:I,B21,DATOS!K:K,9) -> 0 | U21: =COUNTIFS(DATOS!G:G,CONFIG_METADATA!$B$4,DATOS!I:I,B21,DATOS!K:K,10) -> 0
A22: GLOBAL | B22: {=IFERROR(INDEX(_xlfn._xlws.FILTER(CONFIG_ASIGNATURAS!$B$2:$B$61,CONFIG_ASIGNATURAS!$G$2:$G$61="Sí"),18),"")} | C22: =IF(B22="","",IFERROR(IF(VLOOKUP(B22,CONFIG_ASIGNATURAS!$B$2:$F$61,5,FALSE())="Sí","Especialidad","Asignatura"),"Asignatura")) | D22: =COUNTIFS(DATOS!G:G,CONFIG_METADATA!$B$4,DATOS!I:I,B22) -> 0 | E22: =IFERROR(AVERAGEIFS(DATOS!K:K,DATOS!G:G,CONFIG_METADATA!$B$4,DATOS!I:I,B22),"—") -> — | F22: {=IFERROR(_xlfn.STDEV.P(IF((nEVAL=CONFIG_METADATA!$B$4)*(nASIG=B22),nNOTA)),"—")} -> — | G22: {=IFERROR(_xlfn.MODE.SNGL(IF((nEVAL=CONFIG_METADATA!$B$4)*(nASIG=B22),nNOTA)),"—")} -> — | H22: =IFERROR(COUNTIFS(DATOS!G:G,CONFIG_METADATA!$B$4,DATOS!I:I,B22,DATOS!L:L,"S")/COUNTIFS(DATOS!G:G,CONFIG_METADATA!$B$4,DATOS!I:I,B22),"—") -> — | I22: =IFERROR(COUNTIFS(DATOS!G:G,CONFIG_METADATA!$B$4,DATOS!I:I,B22,DATOS!L:L,"N")/COUNTIFS(DATOS!G:G,CONFIG_METADATA!$B$4,DATOS!I:I,B22),"—") -> — | J22: {=IFERROR(_xlfn.MODE.SNGL(IF((nEVAL=CONFIG_METADATA!$B$4)*(nASIG=B22)*(nAPTO="S"),nNOTA)),"—")} -> — | K22: {=IFERROR(_xlfn.MODE.SNGL(IF((nEVAL=CONFIG_METADATA!$B$4)*(nASIG=B22)*(nAPTO="N"),nNOTA)),"—")} -> — | L22: =COUNTIFS(DATOS!G:G,CONFIG_METADATA!$B$4,DATOS!I:I,B22,DATOS!K:K,1) -> 0 | M22: =COUNTIFS(DATOS!G:G,CONFIG_METADATA!$B$4,DATOS!I:I,B22,DATOS!K:K,2) -> 0 | N22: =COUNTIFS(DATOS!G:G,CONFIG_METADATA!$B$4,DATOS!I:I,B22,DATOS!K:K,3) -> 0 | O22: =COUNTIFS(DATOS!G:G,CONFIG_METADATA!$B$4,DATOS!I:I,B22,DATOS!K:K,4) -> 0 | P22: =COUNTIFS(DATOS!G:G,CONFIG_METADATA!$B$4,DATOS!I:I,B22,DATOS!K:K,5) -> 0 | Q22: =COUNTIFS(DATOS!G:G,CONFIG_METADATA!$B$4,DATOS!I:I,B22,DATOS!K:K,6) -> 0 | R22: =COUNTIFS(DATOS!G:G,CONFIG_METADATA!$B$4,DATOS!I:I,B22,DATOS!K:K,7) -> 0 | S22: =COUNTIFS(DATOS!G:G,CONFIG_METADATA!$B$4,DATOS!I:I,B22,DATOS!K:K,8) -> 0 | T22: =COUNTIFS(DATOS!G:G,CONFIG_METADATA!$B$4,DATOS!I:I,B22,DATOS!K:K,9) -> 0 | U22: =COUNTIFS(DATOS!G:G,CONFIG_METADATA!$B$4,DATOS!I:I,B22,DATOS!K:K,10) -> 0
A23: GLOBAL | B23: {=IFERROR(INDEX(_xlfn._xlws.FILTER(CONFIG_ASIGNATURAS!$B$2:$B$61,CONFIG_ASIGNATURAS!$G$2:$G$61="Sí"),19),"")} | C23: =IF(B23="","",IFERROR(IF(VLOOKUP(B23,CONFIG_ASIGNATURAS!$B$2:$F$61,5,FALSE())="Sí","Especialidad","Asignatura"),"Asignatura")) | D23: =COUNTIFS(DATOS!G:G,CONFIG_METADATA!$B$4,DATOS!I:I,B23) -> 0 | E23: =IFERROR(AVERAGEIFS(DATOS!K:K,DATOS!G:G,CONFIG_METADATA!$B$4,DATOS!I:I,B23),"—") -> — | F23: {=IFERROR(_xlfn.STDEV.P(IF((nEVAL=CONFIG_METADATA!$B$4)*(nASIG=B23),nNOTA)),"—")} -> — | G23: {=IFERROR(_xlfn.MODE.SNGL(IF((nEVAL=CONFIG_METADATA!$B$4)*(nASIG=B23),nNOTA)),"—")} -> — | H23: =IFERROR(COUNTIFS(DATOS!G:G,CONFIG_METADATA!$B$4,DATOS!I:I,B23,DATOS!L:L,"S")/COUNTIFS(DATOS!G:G,CONFIG_METADATA!$B$4,DATOS!I:I,B23),"—") -> — | I23: =IFERROR(COUNTIFS(DATOS!G:G,CONFIG_METADATA!$B$4,DATOS!I:I,B23,DATOS!L:L,"N")/COUNTIFS(DATOS!G:G,CONFIG_METADATA!$B$4,DATOS!I:I,B23),"—") -> — | J23: {=IFERROR(_xlfn.MODE.SNGL(IF((nEVAL=CONFIG_METADATA!$B$4)*(nASIG=B23)*(nAPTO="S"),nNOTA)),"—")} -> — | K23: {=IFERROR(_xlfn.MODE.SNGL(IF((nEVAL=CONFIG_METADATA!$B$4)*(nASIG=B23)*(nAPTO="N"),nNOTA)),"—")} -> — | L23: =COUNTIFS(DATOS!G:G,CONFIG_METADATA!$B$4,DATOS!I:I,B23,DATOS!K:K,1) -> 0 | M23: =COUNTIFS(DATOS!G:G,CONFIG_METADATA!$B$4,DATOS!I:I,B23,DATOS!K:K,2) -> 0 | N23: =COUNTIFS(DATOS!G:G,CONFIG_METADATA!$B$4,DATOS!I:I,B23,DATOS!K:K,3) -> 0 | O23: =COUNTIFS(DATOS!G:G,CONFIG_METADATA!$B$4,DATOS!I:I,B23,DATOS!K:K,4) -> 0 | P23: =COUNTIFS(DATOS!G:G,CONFIG_METADATA!$B$4,DATOS!I:I,B23,DATOS!K:K,5) -> 0 | Q23: =COUNTIFS(DATOS!G:G,CONFIG_METADATA!$B$4,DATOS!I:I,B23,DATOS!K:K,6) -> 0 | R23: =COUNTIFS(DATOS!G:G,CONFIG_METADATA!$B$4,DATOS!I:I,B23,DATOS!K:K,7) -> 0 | S23: =COUNTIFS(DATOS!G:G,CONFIG_METADATA!$B$4,DATOS!I:I,B23,DATOS!K:K,8) -> 0 | T23: =COUNTIFS(DATOS!G:G,CONFIG_METADATA!$B$4,DATOS!I:I,B23,DATOS!K:K,9) -> 0 | U23: =COUNTIFS(DATOS!G:G,CONFIG_METADATA!$B$4,DATOS!I:I,B23,DATOS!K:K,10) -> 0
A24: GLOBAL | B24: {=IFERROR(INDEX(_xlfn._xlws.FILTER(CONFIG_ASIGNATURAS!$B$2:$B$61,CONFIG_ASIGNATURAS!$G$2:$G$61="Sí"),20),"")} | C24: =IF(B24="","",IFERROR(IF(VLOOKUP(B24,CONFIG_ASIGNATURAS!$B$2:$F$61,5,FALSE())="Sí","Especialidad","Asignatura"),"Asignatura")) | D24: =COUNTIFS(DATOS!G:G,CONFIG_METADATA!$B$4,DATOS!I:I,B24) -> 0 | E24: =IFERROR(AVERAGEIFS(DATOS!K:K,DATOS!G:G,CONFIG_METADATA!$B$4,DATOS!I:I,B24),"—") -> — | F24: {=IFERROR(_xlfn.STDEV.P(IF((nEVAL=CONFIG_METADATA!$B$4)*(nASIG=B24),nNOTA)),"—")} -> — | G24: {=IFERROR(_xlfn.MODE.SNGL(IF((nEVAL=CONFIG_METADATA!$B$4)*(nASIG=B24),nNOTA)),"—")} -> — | H24: =IFERROR(COUNTIFS(DATOS!G:G,CONFIG_METADATA!$B$4,DATOS!I:I,B24,DATOS!L:L,"S")/COUNTIFS(DATOS!G:G,CONFIG_METADATA!$B$4,DATOS!I:I,B24),"—") -> — | I24: =IFERROR(COUNTIFS(DATOS!G:G,CONFIG_METADATA!$B$4,DATOS!I:I,B24,DATOS!L:L,"N")/COUNTIFS(DATOS!G:G,CONFIG_METADATA!$B$4,DATOS!I:I,B24),"—") -> — | J24: {=IFERROR(_xlfn.MODE.SNGL(IF((nEVAL=CONFIG_METADATA!$B$4)*(nASIG=B24)*(nAPTO="S"),nNOTA)),"—")} -> — | K24: {=IFERROR(_xlfn.MODE.SNGL(IF((nEVAL=CONFIG_METADATA!$B$4)*(nASIG=B24)*(nAPTO="N"),nNOTA)),"—")} -> — | L24: =COUNTIFS(DATOS!G:G,CONFIG_METADATA!$B$4,DATOS!I:I,B24,DATOS!K:K,1) -> 0 | M24: =COUNTIFS(DATOS!G:G,CONFIG_METADATA!$B$4,DATOS!I:I,B24,DATOS!K:K,2) -> 0 | N24: =COUNTIFS(DATOS!G:G,CONFIG_METADATA!$B$4,DATOS!I:I,B24,DATOS!K:K,3) -> 0 | O24: =COUNTIFS(DATOS!G:G,CONFIG_METADATA!$B$4,DATOS!I:I,B24,DATOS!K:K,4) -> 0 | P24: =COUNTIFS(DATOS!G:G,CONFIG_METADATA!$B$4,DATOS!I:I,B24,DATOS!K:K,5) -> 0 | Q24: =COUNTIFS(DATOS!G:G,CONFIG_METADATA!$B$4,DATOS!I:I,B24,DATOS!K:K,6) -> 0 | R24: =COUNTIFS(DATOS!G:G,CONFIG_METADATA!$B$4,DATOS!I:I,B24,DATOS!K:K,7) -> 0 | S24: =COUNTIFS(DATOS!G:G,CONFIG_METADATA!$B$4,DATOS!I:I,B24,DATOS!K:K,8) -> 0 | T24: =COUNTIFS(DATOS!G:G,CONFIG_METADATA!$B$4,DATOS!I:I,B24,DATOS!K:K,9) -> 0 | U24: =COUNTIFS(DATOS!G:G,CONFIG_METADATA!$B$4,DATOS!I:I,B24,DATOS!K:K,10) -> 0
A25: GLOBAL | B25: {=IFERROR(INDEX(_xlfn._xlws.FILTER(CONFIG_ASIGNATURAS!$B$2:$B$61,CONFIG_ASIGNATURAS!$G$2:$G$61="Sí"),21),"")} | C25: =IF(B25="","",IFERROR(IF(VLOOKUP(B25,CONFIG_ASIGNATURAS!$B$2:$F$61,5,FALSE())="Sí","Especialidad","Asignatura"),"Asignatura")) | D25: =COUNTIFS(DATOS!G:G,CONFIG_METADATA!$B$4,DATOS!I:I,B25) -> 0 | E25: =IFERROR(AVERAGEIFS(DATOS!K:K,DATOS!G:G,CONFIG_METADATA!$B$4,DATOS!I:I,B25),"—") -> — | F25: {=IFERROR(_xlfn.STDEV.P(IF((nEVAL=CONFIG_METADATA!$B$4)*(nASIG=B25),nNOTA)),"—")} -> — | G25: {=IFERROR(_xlfn.MODE.SNGL(IF((nEVAL=CONFIG_METADATA!$B$4)*(nASIG=B25),nNOTA)),"—")} -> — | H25: =IFERROR(COUNTIFS(DATOS!G:G,CONFIG_METADATA!$B$4,DATOS!I:I,B25,DATOS!L:L,"S")/COUNTIFS(DATOS!G:G,CONFIG_METADATA!$B$4,DATOS!I:I,B25),"—") -> — | I25: =IFERROR(COUNTIFS(DATOS!G:G,CONFIG_METADATA!$B$4,DATOS!I:I,B25,DATOS!L:L,"N")/COUNTIFS(DATOS!G:G,CONFIG_METADATA!$B$4,DATOS!I:I,B25),"—") -> — | J25: {=IFERROR(_xlfn.MODE.SNGL(IF((nEVAL=CONFIG_METADATA!$B$4)*(nASIG=B25)*(nAPTO="S"),nNOTA)),"—")} -> — | K25: {=IFERROR(_xlfn.MODE.SNGL(IF((nEVAL=CONFIG_METADATA!$B$4)*(nASIG=B25)*(nAPTO="N"),nNOTA)),"—")} -> — | L25: =COUNTIFS(DATOS!G:G,CONFIG_METADATA!$B$4,DATOS!I:I,B25,DATOS!K:K,1) -> 0 | M25: =COUNTIFS(DATOS!G:G,CONFIG_METADATA!$B$4,DATOS!I:I,B25,DATOS!K:K,2) -> 0 | N25: =COUNTIFS(DATOS!G:G,CONFIG_METADATA!$B$4,DATOS!I:I,B25,DATOS!K:K,3) -> 0 | O25: =COUNTIFS(DATOS!G:G,CONFIG_METADATA!$B$4,DATOS!I:I,B25,DATOS!K:K,4) -> 0 | P25: =COUNTIFS(DATOS!G:G,CONFIG_METADATA!$B$4,DATOS!I:I,B25,DATOS!K:K,5) -> 0 | Q25: =COUNTIFS(DATOS!G:G,CONFIG_METADATA!$B$4,DATOS!I:I,B25,DATOS!K:K,6) -> 0 | R25: =COUNTIFS(DATOS!G:G,CONFIG_METADATA!$B$4,DATOS!I:I,B25,DATOS!K:K,7) -> 0 | S25: =COUNTIFS(DATOS!G:G,CONFIG_METADATA!$B$4,DATOS!I:I,B25,DATOS!K:K,8) -> 0 | T25: =COUNTIFS(DATOS!G:G,CONFIG_METADATA!$B$4,DATOS!I:I,B25,DATOS!K:K,9) -> 0 | U25: =COUNTIFS(DATOS!G:G,CONFIG_METADATA!$B$4,DATOS!I:I,B25,DATOS!K:K,10) -> 0
