Workbook
Name nNIA: DATOS!$A$2:INDEX(DATOS!$A:$A,CONFIG_METADATA!$B$8)
Name nCURSO: DATOS!$D$2:INDEX(DATOS!$D:$D,CONFIG_METADATA!$B$8)
Name nESPEC: DATOS!$E$2:INDEX(DATOS!$E:$E,CONFIG_METADATA!$B$8)
Name nEVAL: DATOS!$G$2:INDEX(DATOS!$G:$G,CONFIG_METADATA!$B$8)
Name nASIG: DATOS!$I$2:INDEX(DATOS!$I:$I,CONFIG_METADATA!$B$8)
Name nNOTA: DATOS!$K$2:INDEX(DATOS!$K:$K,CONFIG_METADATA!$B$8)
Name nAPTO: DATOS!$L$2:INDEX(DATOS!$L:$L,CONFIG_METADATA!$B$8)
Name nCUENTA: CONFIG_METADATA!$G$2:INDEX(CONFIG_METADATA!$G:$G,CONFIG_METADATA!$B$8)
Name nCLAVE: CONFIG_METADATA!$F$2:INDEX(CONFIG_METADATA!$F:$F,CONFIG_METADATA!$B$8)
Name nEXSINOR: CONFIG_METADATA!$H$2:INDEX(CONFIG_METADATA!$H:$H,CONFIG_METADATA!$B$8)
Name nCLASE_I: CONFIG_METADATA!$I$2:INDEX(CONFIG_METADATA!$I:$I,CONFIG_METADATA!$B$8)

Sheet PORTADA_EPM
B2: Analizador de calificaciones
B3: Enseñanzas Profesionales de Música · Conservatorios
B5: EMPEZAR
B6: 1 · Pega las calificaciones en la hoja DATOS
B7: Una fila por alumno, asignatura y evaluación. Las columnas ya están puestas: respeta su orden y sus nombres.
B9: 2 · Elige la evaluación
B10: CONFIG_METADATA!B4
B11: Códigos: 1EV · 2EV · 3EV · OR · EX · OR+EX
B12: OR+EX es la foto definitiva del curso: la ordinaria como base, y cada recuperación de la extraordinaria sustituyendo a la suya.
B13: Para usarla, pega la ordinaria y AÑADE DEBAJO las filas de la extraordinaria. No las sustituyas: hacen falta las dos.
B14: EX a solas enseña solo lo que se suspendió en junio, así que su media no es la del centro.
B16: 3 · Mira los avisos antes de fiarte de las cifras
... B61: Versión 2.0 · agosto 2026

Sheet CONFIG_ASIGNATURAS
A1: ID | B1: Asignatura | C1: Cursos | D1: Grupo1 | E1: Grupo2 | F1: EsEspecialidad | G1: Activa | H1: UnaSolaVez | I1: Tipo | J1: Clase (calculada) | K1: CÓMO AÑADIR UNA ASIGNATURA
A2: 1 | B2: Lenguaje Musical | C2: 1EPM;2EPM | D2: Referencia | E2: TeoricaTroncal | F2: No | G2: Sí | H2: Sí | I2: Obligatoria | J2: =IF($G2<>"Sí","",IF($D2="Especialidad","E",IF($E2="TeoricaTroncal","NT","N"))) | K2: 1. Escríbela en la primera fila libre (marcada abajo con una flecha). No hace falta
A3: 2 | B3: Armonía | C3: 3EPM;4EPM | D3: Referencia | E3: TeoricaTroncal | F3: No | G3: Sí | H3: Sí | I3: Obligatoria | J3: =IF($G3<>"Sí","",IF($D3="Especialidad","E",IF($E3="TeoricaTroncal","NT","N"))) | K3: insertar filas ni ordenar nada: las fórmulas no miran POSICIONES, miran columnas.
A4: 3 | B4: Análisis | C4: 5EPM;6EPM | D4: Referencia | E4: TeoricaTroncal | F4: No | G4: Sí | H4: Sí | I4: Obligatoria | J4: =IF($G4<>"Sí","",IF($D4="Especialidad","E",IF($E4="TeoricaTroncal","NT","N"))) | K4: 2. B Asignatura — EXACTAMENTE igual que en el fichero de calificaciones que
A5: 4 | B5: Música de Cámara | C5: 3EPM;4EPM;5EPM;6EPM | D5: Referencia | E5: NoEspecialidad | F5: No | G5: Sí | H5: No | I5: Obligatoria | J5: =IF($G5<>"Sí","",IF($D5="Especialidad","E",IF($E5="TeoricaTroncal","NT","N"))) | K5: pegas en DATOS. Si no coincide letra por letra, esa asignatura no aparece
A6: 5 | B6: Orquesta/Banda/Conjunto | C6: 1EPM;2EPM;3EPM;4EPM;5EPM;6EPM | D6: Referencia | E6: NoEspecialidad | F6: No | G6: Sí | H6: No | I6: Obligatoria | J6: =IF($G6<>"Sí","",IF($D6="Especialidad","E",IF($E6="TeoricaTroncal","NT","N"))) | K6: ni con un cero, y sus registros los cuenta el aviso «FueraDeLasCifras».
A7: 6 | B7: Arpa | C7: 1EPM;2EPM;3EPM;4EPM;5EPM;6EPM | D7: Especialidad | E7: Cuerda | F7: Sí | G7: Sí | H7: No | I7: Obligatoria | J7: =IF($G7<>"Sí","",IF($D7="Especialidad","E",IF($E7="TeoricaTroncal","NT","N"))) | K7: 3. C Cursos — separados por punto y coma. Solo sale en los cursos que pongas.
A8: 7 | B8: Bajo Eléctrico | C8: 1EPM;2EPM;3EPM;4EPM;5EPM;6EPM | D8: Especialidad | E8: Cuerda | F8: Sí | G8: Sí | H8: No | I8: Obligatoria | J8: =IF($G8<>"Sí","",IF($D8="Especialidad","E",IF($E8="TeoricaTroncal","NT","N"))) | K8: 4. D Grupo1 — «Especialidad» si es un instrumento: decide en qué total cuenta.
A9: 8 | B9: Canto | C9: 1EPM;2EPM;3EPM;4EPM;5EPM;6EPM | D9: Especialidad | F9: Sí | G9: Sí | H9: No | I9: Obligatoria | J9: =IF($G9<>"Sí","",IF($D9="Especialidad","E",IF($E9="TeoricaTroncal","NT","N"))) | K9: 5. G Activa — «Sí». Sin eso no sale por ningún sitio.
A10: 9 | B10: Clarinete | C10: 1EPM;2EPM;3EPM;4EPM;5EPM;6EPM | D10: Especialidad | E10: Madera | F10: Sí | G10: Sí | H10: No | I10: Obligatoria | J10: =IF($G10<>"Sí","",IF($D10="Especialidad","E",IF($E10="TeoricaTroncal","NT","N"))) | K10: 6. H UnaSolaVez — «Sí» solo si NO se vuelve a cursar con un segundo instrumento.
A11: 10 | B11: Contrabajo | C11: 1EPM;2EPM;3EPM;4EPM;5EPM;6EPM | D11: Especialidad | E11: Cuerda | F11: Sí | G11: Sí | H11: No | I11: Obligatoria | J11: =IF($G11<>"Sí","",IF($D11="Especialidad","E",IF($E11="TeoricaTroncal","NT","N"))) | K11: 7. I Tipo — Obligatoria / Optativa / De centro.
A12: 11 | B12: Dulzaina | C12: 1EPM;2EPM;3EPM;4EPM;5EPM;6EPM | D12: Especialidad | E12: Madera | F12: Sí | G12: Sí | H12: No | I12: Obligatoria | J12: =IF($G12<>"Sí","",IF($D12="Especialidad","E",IF($E12="TeoricaTroncal","NT","N"))) | K12: J Clase se calcula sola. Si sale vacía, esa fila no está activa.
A13: 12 | B13: Fagot | C13: 1EPM;2EPM;3EPM;4EPM;5EPM;6EPM | D13: Especialidad | E13: Madera | F13: Sí | G13: Sí | H13: No | I13: Obligatoria | J13: =IF($G13<>"Sí","",IF($D13="Especialidad","E",IF($E13="TeoricaTroncal","NT","N")))
A14: 13 | B14: Flauta Travesera | C14: 1EPM;2EPM;3EPM;4EPM;5EPM;6EPM | D14: Especialidad | E14: Madera | F14: Sí | G14: Sí | H14: No | I14: Obligatoria | J14: =IF($G14<>"Sí","",IF($D14="Especialidad","E",IF($E14="TeoricaTroncal","NT","N")))
A15: 14 | B15: Guitarra | C15: 1EPM;2EPM;3EPM;4EPM;5EPM;6EPM | D15: Especialidad | E15: Cuerda | F15: Sí | G15: Sí | H15: No | I15: Obligatoria | J15: =IF($G15<>"Sí","",IF($D15="Especialidad","E",IF($E15="TeoricaTroncal","NT","N")))
A16: 15 | B16: Guitarra Eléctrica | C16: 1EPM;2EPM;3EPM;4EPM;5EPM;6EPM | D16: Especialidad | E16: Cuerda | F16: Sí | G16: Sí | H16: No | I16: Obligatoria | J16: =IF($G16<>"Sí","",IF($D16="Especialidad","E",IF($E16="TeoricaTroncal","NT","N")))
A17: 16 | B17: Oboe | C17: 1EPM;2EPM;3EPM;4EPM;5EPM;6EPM | D17: Especialidad | E17: Madera | F17: Sí | G17: Sí | H17: No | I17: Obligatoria | J17: =IF($G17<>"Sí","",IF($D17="Especialidad","E",IF($E17="TeoricaTroncal","NT","N")))
A18: 17 | B18: Percusión | C18: 1EPM;2EPM;3EPM;4EPM;5EPM;6EPM | D18: Especialidad | E18: Metal | F18: Sí | G18: Sí | H18: No | I18: Obligatoria | J18: =IF($G18<>"Sí","",IF($D18="Especialidad","E",IF($E18="TeoricaTroncal","NT","N")))
A19: 18 | B19: Piano | C19: 1EPM;2EPM;3EPM;4EPM;5EPM;6EPM | D19: Especialidad | E19: Tecla | F19: Sí | G19: Sí | H19: No | I19: Obligatoria | J19: =IF($G19<>"Sí","",IF($D19="Especialidad","E",IF($E19="TeoricaTroncal","NT","N")))
A20: 19 | B20: Saxofón | C20: 1EPM;2EPM;3EPM;4EPM;5EPM;6EPM | D20: Especialidad | E20: Madera | F20: Sí | G20: Sí | H20: No | I20: Obligatoria | J20: =IF($G20<>"Sí","",IF($D20="Especialidad","E",IF($E20="TeoricaTroncal","NT","N")))
A21: 20 | B21: Trombón | C21: 1EPM;2EPM;3EPM;4EPM;5EPM;6EPM | D21: Especialidad | E21: Metal | F21: Sí | G21: Sí | H21: No | I21: Obligatoria | J21: =IF($G21<>"Sí","",IF($D21="Especialidad","E",IF($E21="TeoricaTroncal","NT","N")))
A22: 21 | B22: Trompa | C22: 1EPM;2EPM;3EPM;4EPM;5EPM;6EPM | D22: Especialidad | E22: Metal | F22: Sí | G22: Sí | H22: No | I22: Obligatoria | J22: =IF($G22<>"Sí","",IF($D22="Especialidad","E",IF($E22="TeoricaTroncal","NT","N")))
A23: 22 | B23: Trompeta | C23: 1EPM;2EPM;3EPM;4EPM;5EPM;6EPM | D23: Especialidad | E23: Metal | F23: Sí | G23: Sí | H23: No | I23: Obligatoria | J23: =IF($G23<>"Sí","",IF($D23="Especialidad","E",IF($E23="TeoricaTroncal","NT","N")))
A24: 23 | B24: Tuba | C24: 1EPM;2EPM;3EPM;4EPM;5EPM;6EPM | D24: Especialidad | E24: Metal | F24: Sí | G24: Sí | H24: No | I24: Obligatoria | J24: =IF($G24<>"Sí","",IF($D24="Especialidad","E",IF($E24="TeoricaTroncal","NT","N")))
... A27: 26 | B27: Violoncello | C27: 1EPM;2EPM;3EPM;4EPM;5EPM;6EPM | D27: Especialidad | E27: Cuerda | F27: Sí | G27: Sí | H27: No | I27: Obligatoria | J27: =IF($G27<>"Sí","",IF($D27="Especialidad","E",IF($E27="TeoricaTroncal","NT","N")))
A28: 27 | B28: Piano Complementario | C28: 2EPM;3EPM;4EPM | D28: NoEspecialidad | F28: No | G28: Sí | H28: Sí | I28: Obligatoria | J28: =IF($G28<>"Sí","",IF($D28="Especialidad","E",IF($E28="TeoricaTroncal","NT","N")))
A29: 28 | B29: Conjunto | C29: 1EPM;2EPM | D29: NoEspecialidad | F29: No | G29: Sí | H29: No | I29: Obligatoria | J29: =IF($G29<>"Sí","",IF($D29="Especialidad","E",IF($E29="TeoricaTroncal","NT","N")))
A30: 29 | B30: Acompañamiento | C30: 5EPM;6EPM | D30: NoEspecialidad | F30: No | G30: Sí | H30: No | I30: Obligatoria | J30: =IF($G30<>"Sí","",IF($D30="Especialidad","E",IF($E30="TeoricaTroncal","NT","N")))
A31: 30 | B31: Coro | C31: 3EPM;4EPM | D31: NoEspecialidad | F31: No | G31: Sí | H31: Sí | I31: Obligatoria | J31: =IF($G31<>"Sí","",IF($D31="Especialidad","E",IF($E31="TeoricaTroncal","NT","N")))
A32: 31 | B32: Idioma Aplicado al Canto | C32: 1EPM;2EPM;3EPM;4EPM;5EPM;6EPM | D32: NoEspecialidad | F32: No | G32: Sí | H32: No | I32: Obligatoria | J32: =IF($G32<>"Sí","",IF($D32="Especialidad","E",IF($E32="TeoricaTroncal","NT","N")))
A33: 32 | B33: Tabalet | C33: 1EPM;2EPM | D33: NoEspecialidad | F33: No | G33: Sí | H33: No | I33: Obligatoria | J33: =IF($G33<>"Sí","",IF($D33="Especialidad","E",IF($E33="TeoricaTroncal","NT","N")))
A34: 33 | B34: Historia de la Música | C34: 5EPM;6EPM | D34: NoEspecialidad | F34: No | G34: Sí | H34: Sí | I34: Obligatoria | J34: =IF($G34<>"Sí","",IF($D34="Especialidad","E",IF($E34="TeoricaTroncal","NT","N")))
A35: 34 | B35: Creatividad y Música | C35: 5EPM;6EPM | D35: Optativas | F35: No | G35: Sí | H35: No | I35: Optativa | J35: =IF($G35<>"Sí","",IF($D35="Especialidad","E",IF($E35="TeoricaTroncal","NT","N")))
A36: 35 | B36: Cultura Audiovisual | C36: 5EPM;6EPM | D36: Optativas | F36: No | G36: Sí | H36: No | I36: Optativa | J36: =IF($G36<>"Sí","",IF($D36="Especialidad","E",IF($E36="TeoricaTroncal","NT","N")))
A37: 36 | B37: Complemento Coral | C37: 5EPM;6EPM | D37: Optativas | F37: No | G37: Sí | H37: No | I37: Optativa | J37: =IF($G37<>"Sí","",IF($D37="Especialidad","E",IF($E37="TeoricaTroncal","NT","N")))
A38: 37 | B38: Fundamentos de Composición | C38: 5EPM;6EPM | D38: Optativas | F38: No | G38: Sí | H38: No | I38: Optativa | J38: =IF($G38<>"Sí","",IF($D38="Especialidad","E",IF($E38="TeoricaTroncal","NT","N")))
A39: 38 | B39: Introducción a la Pedagogía Musical | C39: 5EPM;6EPM | D39: Optativas | F39: No | G39: Sí | H39: No | I39: De centro | J39: =IF($G39<>"Sí","",IF($D39="Especialidad","E",IF($E39="TeoricaTroncal","NT","N")))
... A43: 42 | B43: Improvisación y Jazz | C43: 5EPM;6EPM | D43: Optativas | F43: No | G43: Sí | H43: No | I43: De centro | J43: =IF($G43<>"Sí","",IF($D43="Especialidad","E",IF($E43="TeoricaTroncal","NT","N")))
J44: =IF($G44<>"Sí","",IF($D44="Especialidad","E",IF($E44="TeoricaTroncal","NT","N"))) | M44: ↓ primera fila libre
J45: =IF($G45<>"Sí","",IF($D45="Especialidad","E",IF($E45="TeoricaTroncal","NT","N")))
...

Sheet CONFIG_METADATA
A1: Campo | B1: Valor | D1: Evaluaciones | F1: Clave de matrícula | G1: Cuenta | H1: EX sin OR | I1: =IF(DATOS!$I1="","",IFERROR(VLOOKUP(DATOS!$I1,CONFIG_ASIGNATURAS!$B$2:$J$91,9,FALSE()),""))
A2: Centro | B2: CPM Mestre Tárrega | D2: 1EV | F2: =IF(DATOS!$A2="","",DATOS!$A2&"|"&DATOS!$D2&"|"&DATOS!$E2&"|"&DATOS!$I2) | G2: =IF(DATOS!$A2="",0,IF(CONFIG_METADATA!$B$4<>"OR+EX",--(DATOS!$G2=CONFIG_METADATA!$B$4),IF(DATOS!$G2="EX",1,IF(DATOS!$G2="OR",--(COUNTIFS(nNIA,DATOS!$A2,nCURSO,DATOS!$D2,nESPEC,DATOS!$E2,nASIG,DATOS!$I2,nEVAL,"EX")=0),0)))) | H2: =IF(DATOS!$G2<>"EX",0,--(COUNTIFS(nNIA,DATOS!$A2,nCURSO,DATOS!$D2,nESPEC,DATOS!$E2,nASIG,DATOS!$I2,nEVAL,"OR")=0)) | I2: =IF(DATOS!$I2="","",IFERROR(VLOOKUP(DATOS!$I2,CONFIG_ASIGNATURAS!$B$2:$J$91,9,FALSE()),""))
A3: CursoAcademico | B3: 25/26 | D3: 2EV | F3: =IF(DATOS!$A3="","",DATOS!$A3&"|"&DATOS!$D3&"|"&DATOS!$E3&"|"&DATOS!$I3) | G3: =IF(DATOS!$A3="",0,IF(CONFIG_METADATA!$B$4<>"OR+EX",--(DATOS!$G3=CONFIG_METADATA!$B$4),IF(DATOS!$G3="EX",1,IF(DATOS!$G3="OR",--(COUNTIFS(nNIA,DATOS!$A3,nCURSO,DATOS!$D3,nESPEC,DATOS!$E3,nASIG,DATOS!$I3,nEVAL,"EX")=0),0)))) | H3: =IF(DATOS!$G3<>"EX",0,--(COUNTIFS(nNIA,DATOS!$A3,nCURSO,DATOS!$D3,nESPEC,DATOS!$E3,nASIG,DATOS!$I3,nEVAL,"OR")=0)) | I3: =IF(DATOS!$I3="","",IFERROR(VLOOKUP(DATOS!$I3,CONFIG_ASIGNATURAS!$B$2:$J$91,9,FALSE()),""))
A4: Evaluacion | B4: 1EV | D4: 3EV | F4: =IF(DATOS!$A4="","",DATOS!$A4&"|"&DATOS!$D4&"|"&DATOS!$E4&"|"&DATOS!$I4) | G4: =IF(DATOS!$A4="",0,IF(CONFIG_METADATA!$B$4<>"OR+EX",--(DATOS!$G4=CONFIG_METADATA!$B$4),IF(DATOS!$G4="EX",1,IF(DATOS!$G4="OR",--(COUNTIFS(nNIA,DATOS!$A4,nCURSO,DATOS!$D4,nESPEC,DATOS!$E4,nASIG,DATOS!$I4,nEVAL,"EX")=0),0)))) | H4: =IF(DATOS!$G4<>"EX",0,--(COUNTIFS(nNIA,DATOS!$A4,nCURSO,DATOS!$D4,nESPEC,DATOS!$E4,nASIG,DATOS!$I4,nEVAL,"OR")=0)) | I4: =IF(DATOS!$I4="","",IFERROR(VLOOKUP(DATOS!$I4,CONFIG_ASIGNATURAS!$B$2:$J$91,9,FALSE()),""))
D5: OR | F5: =IF(DATOS!$A5="","",DATOS!$A5&"|"&DATOS!$D5&"|"&DATOS!$E5&"|"&DATOS!$I5) | G5: =IF(DATOS!$A5="",0,IF(CONFIG_METADATA!$B$4<>"OR+EX",--(DATOS!$G5=CONFIG_METADATA!$B$4),IF(DATOS!$G5="EX",1,IF(DATOS!$G5="OR",--(COUNTIFS(nNIA,DATOS!$A5,nCURSO,DATOS!$D5,nESPEC,DATOS!$E5,nASIG,DATOS!$I5,nEVAL,"EX")=0),0)))) | H5: =IF(DATOS!$G5<>"EX",0,--(COUNTIFS(nNIA,DATOS!$A5,nCURSO,DATOS!$D5,nESPEC,DATOS!$E5,nASIG,DATOS!$I5,nEVAL,"OR")=0)) | I5: =IF(DATOS!$I5="","",IFERROR(VLOOKUP(DATOS!$I5,CONFIG_ASIGNATURAS!$B$2:$J$91,9,FALSE()),""))
A6: ExtraordinariaSinOrdinaria | B6: =SUM(nEXSINOR) | C6: Filas de extraordinaria que no tienen su fila de ordinaria. No se recupera lo que no se suspendió: si no es cero, falta por pegar la ordinaria o sobra algo en la extraordinaria. | D6: EX | F6: =IF(DATOS!$A6="","",DATOS!$A6&"|"&DATOS!$D6&"|"&DATOS!$E6&"|"&DATOS!$I6) | G6: =IF(DATOS!$A6="",0,IF(CONFIG_METADATA!$B$4<>"OR+EX",--(DATOS!$G6=CONFIG_METADATA!$B$4),IF(DATOS!$G6="EX",1,IF(DATOS!$G6="OR",--(COUNTIFS(nNIA,DATOS!$A6,nCURSO,DATOS!$D6,nESPEC,DATOS!$E6,nASIG,DATOS!$I6,nEVAL,"EX")=0),0)))) | H6: =IF(DATOS!$G6<>"EX",0,--(COUNTIFS(nNIA,DATOS!$A6,nCURSO,DATOS!$D6,nESPEC,DATOS!$E6,nASIG,DATOS!$I6,nEVAL,"OR")=0)) | I6: =IF(DATOS!$I6="","",IFERROR(VLOOKUP(DATOS!$I6,CONFIG_ASIGNATURAS!$B$2:$J$91,9,FALSE()),""))
A7: ComoSeLee | C7: Con OR+EX manda la ordinaria y cada fila de extraordinaria pisa la suya. Es la única opción que da la foto definitiva del curso: EX a solas enseña solo lo que se suspendió en junio. | D7: OR+EX | F7: =IF(DATOS!$A7="","",DATOS!$A7&"|"&DATOS!$D7&"|"&DATOS!$E7&"|"&DATOS!$I7) | G7: =IF(DATOS!$A7="",0,IF(CONFIG_METADATA!$B$4<>"OR+EX",--(DATOS!$G7=CONFIG_METADATA!$B$4),IF(DATOS!$G7="EX",1,IF(DATOS!$G7="OR",--(COUNTIFS(nNIA,DATOS!$A7,nCURSO,DATOS!$D7,nESPEC,DATOS!$E7,nASIG,DATOS!$I7,nEVAL,"EX")=0),0)))) | H7: =IF(DATOS!$G7<>"EX",0,--(COUNTIFS(nNIA,DATOS!$A7,nCURSO,DATOS!$D7,nESPEC,DATOS!$E7,nASIG,DATOS!$I7,nEVAL,"OR")=0)) | I7: =IF(DATOS!$I7="","",IFERROR(VLOOKUP(DATOS!$I7,CONFIG_ASIGNATURAS!$B$2:$J$91,9,FALSE()),""))
A8: FilasConDatos | B8: =IFERROR(LOOKUP(2,1/(DATOS!$A$2:$A20000<>""),ROW(DATOS!$A$2:$A20000)),2) | C8: Última fila de DATOS con algo. Es hasta donde miran todas las fórmulas: sin esto recorrerían las 20.000 filas siempre, y diecinueve de cada veinte lecturas serían de celdas vacías. | F8: =IF(DATOS!$A8="","",DATOS!$A8&"|"&DATOS!$D8&"|"&DATOS!$E8&"|"&DATOS!$I8) | G8: =IF(DATOS!$A8="",0,IF(CONFIG_METADATA!$B$4<>"OR+EX",--(DATOS!$G8=CONFIG_METADATA!$B$4),IF(DATOS!$G8="EX",1,IF(DATOS!$G8="OR",--(COUNTIFS(nNIA,DATOS!$A8,nCURSO,DATOS!$D8,nESPEC,DATOS!$E8,nASIG,DATOS!$I8,nEVAL,"EX")=0),0)))) | H8: =IF(DATOS!$G8<>"EX",0,--(COUNTIFS(nNIA,DATOS!$A8,nCURSO,DATOS!$D8,nESPEC,DATOS!$E8,nASIG,DATOS!$I8,nEVAL,"OR")=0)) | I8: =IF(DATOS!$I8="","",IFERROR(VLOOKUP(DATOS!$I8,CONFIG_ASIGNATURAS!$B$2:$J$91,9,FALSE()),""))
A9: DobleEspecialidad | B9: {=IFERROR(SUMPRODUCT((nCUENTA=1)*(COUNTIFS(CONFIG_ASIGNATURAS!$B$2:$B$91,nASIG,CONFIG_ASIGNATURAS!$H$2:$H$91,"Sí",CONFIG_ASIGNATURAS!$G$2:$G$91,"Sí")>0)*1)-COUNTA(_xlfn.UNIQUE(_xlfn._xlws.FILTER(nCLAVE,(nCUENTA=1)*(COUNTIFS(CONFIG_ASIGNATURAS!$B$2:$B$91,nASIG,CONFIG_ASIGNATURAS!$H$2:$H$91,"Sí",CONFIG_ASIGNATURAS!$G$2:$G$91,"Sí")>0)))),0)} | C9: Registros de más: quien cursa dos especialidades aparece dos veces en las asignaturas de una sola vez, con la misma nota. Cuentan doble en la media, en la moda y en el reparto. | F9: =IF(DATOS!$A9="","",DATOS!$A9&"|"&DATOS!$D9&"|"&DATOS!$E9&"|"&DATOS!$I9) | G9: =IF(DATOS!$A9="",0,IF(CONFIG_METADATA!$B$4<>"OR+EX",--(DATOS!$G9=CONFIG_METADATA!$B$4),IF(DATOS!$G9="EX",1,IF(DATOS!$G9="OR",--(COUNTIFS(nNIA,DATOS!$A9,nCURSO,DATOS!$D9,nESPEC,DATOS!$E9,nASIG,DATOS!$I9,nEVAL,"EX")=0),0)))) | H9: =IF(DATOS!$G9<>"EX",0,--(COUNTIFS(nNIA,DATOS!$A9,nCURSO,DATOS!$D9,nESPEC,DATOS!$E9,nASIG,DATOS!$I9,nEVAL,"OR")=0)) | I9: =IF(DATOS!$I9="","",IFERROR(VLOOKUP(DATOS!$I9,CONFIG_ASIGNATURAS!$B$2:$J$91,9,FALSE()),""))
A10: FueraDeLasCifras | B10: =CALC_EPM!$D$2-CALC_EPM!$D$3-CALC_EPM!$D$4 | C10: Registros que no entran en ninguna cifra: su asignatura no está en CONFIG_ASIGNATURAS, o está pero con Activa = No. Si no es cero, falta algo en la configuración o sobra un No. | F10: =IF(DATOS!$A10="","",DATOS!$A10&"|"&DATOS!$D10&"|"&DATOS!$E10&"|"&DATOS!$I10) | G10: =IF(DATOS!$A10="",0,IF(CONFIG_METADATA!$B$4<>"OR+EX",--(DATOS!$G10=CONFIG_METADATA!$B$4),IF(DATOS!$G10="EX",1,IF(DATOS!$G10="OR",--(COUNTIFS(nNIA,DATOS!$A10,nCURSO,DATOS!$D10,nESPEC,DATOS!$E10,nASIG,DATOS!$I10,nEVAL,"EX")=0),0)))) | H10: =IF(DATOS!$G10<>"EX",0,--(COUNTIFS(nNIA,DATOS!$A10,nCURSO,DATOS!$D10,nESPEC,DATOS!$E10,nASIG,DATOS!$I10,nEVAL,"OR")=0)) | I10: =IF(DATOS!$I10="","",IFERROR(VLOOKUP(DATOS!$I10,CONFIG_ASIGNATURAS!$B$2:$J$91,9,FALSE()),""))
F11: =IF(DATOS!$A11="","",DATOS!$A11&"|"&DATOS!$D11&"|"&DATOS!$E11&"|"&DATOS!$I11) | G11: =IF(DATOS!$A11="",0,IF(CONFIG_METADATA!$B$4<>"OR+EX",--(DATOS!$G11=CONFIG_METADATA!$B$4),IF(DATOS!$G11="EX",1,IF(DATOS!$G11="OR",--(COUNTIFS(nNIA,DATOS!$A11,nCURSO,DATOS!$D11,nESPEC,DATOS!$E11,nASIG,DATOS!$I11,nEVAL,"EX")=0),0)))) | H11: =IF(DATOS!$G11<>"EX",0,--(COUNTIFS(nNIA,DATOS!$A11,nCURSO,DATOS!$D11,nESPEC,DATOS!$E11,nASIG,DATOS!$I11,nEVAL,"OR")=0)) | I11: =IF(DATOS!$I11="","",IFERROR(VLOOKUP(DATOS!$I11,CONFIG_ASIGNATURAS!$B$2:$J$91,9,FALSE()),""))
F12: =IF(DATOS!$A12="","",DATOS!$A12&"|"&DATOS!$D12&"|"&DATOS!$E12&"|"&DATOS!$I12) | G12: =IF(DATOS!$A12="",0,IF(CONFIG_METADATA!$B$4<>"OR+EX",--(DATOS!$G12=CONFIG_METADATA!$B$4),IF(DATOS!$G12="EX",1,IF(DATOS!$G12="OR",--(COUNTIFS(nNIA,DATOS!$A12,nCURSO,DATOS!$D12,nESPEC,DATOS!$E12,nASIG,DATOS!$I12,nEVAL,"EX")=0),0)))) | H12: =IF(DATOS!$G12<>"EX",0,--(COUNTIFS(nNIA,DATOS!$A12,nCURSO,DATOS!$D12,nESPEC,DATOS!$E12,nASIG,DATOS!$I12,nEVAL,"OR")=0)) | I12: =IF(DATOS!$I12="","",IFERROR(VLOOKUP(DATOS!$I12,CONFIG_ASIGNATURAS!$B$2:$J$91,9,FALSE()),""))
F13: =IF(DATOS!$A13="","",DATOS!$A13&"|"&DATOS!$D13&"|"&DATOS!$E13&"|"&DATOS!$I13) | G13: =IF(DATOS!$A13="",0,IF(CONFIG_METADATA!$B$4<>"OR+EX",--(DATOS!$G13=CONFIG_METADATA!$B$4),IF(DATOS!$G13="EX",1,IF(DATOS!$G13="OR",--(COUNTIFS(nNIA,DATOS!$A13,nCURSO,DATOS!$D13,nESPEC,DATOS!$E13,nASIG,DATOS!$I13,nEVAL,"EX")=0),0)))) | H13: =IF(DATOS!$G13<>"EX",0,--(COUNTIFS(nNIA,DATOS!$A13,nCURSO,DATOS!$D13,nESPEC,DATOS!$E13,nASIG,DATOS!$I13,nEVAL,"OR")=0)) | I13: =IF(DATOS!$I13="","",IFERROR(VLOOKUP(DATOS!$I13,CONFIG_ASIGNATURAS!$B$2:$J$91,9,FALSE()),""))
F14: =IF(DATOS!$A14="","",DATOS!$A14&"|"&DATOS!$D14&"|"&DATOS!$E14&"|"&DATOS!$I14) | G14: =IF(DATOS!$A14="",0,IF(CONFIG_METADATA!$B$4<>"OR+EX",--(DATOS!$G14=CONFIG_METADATA!$B$4),IF(DATOS!$G14="EX",1,IF(DATOS!$G14="OR",--(COUNTIFS(nNIA,DATOS!$A14,nCURSO,DATOS!$D14,nESPEC,DATOS!$E14,nASIG,DATOS!$I14,nEVAL,"EX")=0),0)))) | H14: =IF(DATOS!$G14<>"EX",0,--(COUNTIFS(nNIA,DATOS!$A14,nCURSO,DATOS!$D14,nESPEC,DATOS!$E14,nASIG,DATOS!$I14,nEVAL,"OR")=0)) | I14: =IF(DATOS!$I14="","",IFERROR(VLOOKUP(DATOS!$I14,CONFIG_ASIGNATURAS!$B$2:$J$91,9,FALSE()),""))
F15: =IF(DATOS!$A15="","",DATOS!$A15&"|"&DATOS!$D15&"|"&DATOS!$E15&"|"&DATOS!$I15) | G15: =IF(DATOS!$A15="",0,IF(CONFIG_METADATA!$B$4<>"OR+EX",--(DATOS!$G15=CONFIG_METADATA!$B$4),IF(DATOS!$G15="EX",1,IF(DATOS!$G15="OR",--(COUNTIFS(nNIA,DATOS!$A15,nCURSO,DATOS!$D15,nESPEC,DATOS!$E15,nASIG,DATOS!$I15,nEVAL,"EX")=0),0)))) | H15: =IF(DATOS!$G15<>"EX",0,--(COUNTIFS(nNIA,DATOS!$A15,nCURSO,DATOS!$D15,nESPEC,DATOS!$E15,nASIG,DATOS!$I15,nEVAL,"OR")=0)) | I15: =IF(DATOS!$I15="","",IFERROR(VLOOKUP(DATOS!$I15,CONFIG_ASIGNATURAS!$B$2:$J$91,9,FALSE()),""))
F16: =IF(DATOS!$A16="","",DATOS!$A16&"|"&DATOS!$D16&"|"&DATOS!$E16&"|"&DATOS!$I16) | G16: =IF(DATOS!$A16="",0,IF(CONFIG_METADATA!$B$4<>"OR+EX",--(DATOS!$G16=CONFIG_METADATA!$B$4),IF(DATOS!$G16="EX",1,IF(DATOS!$G16="OR",--(COUNTIFS(nNIA,DATOS!$A16,nCURSO,DATOS!$D16,nESPEC,DATOS!$E16,nASIG,DATOS!$I16,nEVAL,"EX")=0),0)))) | H16: =IF(DATOS!$G16<>"EX",0,--(COUNTIFS(nNIA,DATOS!$A16,nCURSO,DATOS!$D16,nESPEC,DATOS!$E16,nASIG,DATOS!$I16,nEVAL,"OR")=0)) | I16: =IF(DATOS!$I16="","",IFERROR(VLOOKUP(DATOS!$I16,CONFIG_ASIGNATURAS!$B$2:$J$91,9,FALSE()),""))
F17: =IF(DATOS!$A17="","",DATOS!$A17&"|"&DATOS!$D17&"|"&DATOS!$E17&"|"&DATOS!$I17) | G17: =IF(DATOS!$A17="",0,IF(CONFIG_METADATA!$B$4<>"OR+EX",--(DATOS!$G17=CONFIG_METADATA!$B$4),IF(DATOS!$G17="EX",1,IF(DATOS!$G17="OR",--(COUNTIFS(nNIA,DATOS!$A17,nCURSO,DATOS!$D17,nESPEC,DATOS!$E17,nASIG,DATOS!$I17,nEVAL,"EX")=0),0)))) | H17: =IF(DATOS!$G17<>"EX",0,--(COUNTIFS(nNIA,DATOS!$A17,nCURSO,DATOS!$D17,nESPEC,DATOS!$E17,nASIG,DATOS!$I17,nEVAL,"OR")=0)) | I17: =IF(DATOS!$I17="","",IFERROR(VLOOKUP(DATOS!$I17,CONFIG_ASIGNATURAS!$B$2:$J$91,9,FALSE()),""))
F18: =IF(DATOS!$A18="","",DATOS!$A18&"|"&DATOS!$D18&"|"&DATOS!$E18&"|"&DATOS!$I18) | G18: =IF(DATOS!$A18="",0,IF(CONFIG_METADATA!$B$4<>"OR+EX",--(DATOS!$G18=CONFIG_METADATA!$B$4),IF(DATOS!$G18="EX",1,IF(DATOS!$G18="OR",--(COUNTIFS(nNIA,DATOS!$A18,nCURSO,DATOS!$D18,nESPEC,DATOS!$E18,nASIG,DATOS!$I18,nEVAL,"EX")=0),0)))) | H18: =IF(DATOS!$G18<>"EX",0,--(COUNTIFS(nNIA,DATOS!$A18,nCURSO,DATOS!$D18,nESPEC,DATOS!$E18,nASIG,DATOS!$I18,nEVAL,"OR")=0)) | I18: =IF(DATOS!$I18="","",IFERROR(VLOOKUP(DATOS!$I18,CONFIG_ASIGNATURAS!$B$2:$J$91,9,FALSE()),""))
F19: =IF(DATOS!$A19="","",DATOS!$A19&"|"&DATOS!$D19&"|"&DATOS!$E19&"|"&DATOS!$I19) | G19: =IF(DATOS!$A19="",0,IF(CONFIG_METADATA!$B$4<>"OR+EX",--(DATOS!$G19=CONFIG_METADATA!$B$4),IF(DATOS!$G19="EX",1,IF(DATOS!$G19="OR",--(COUNTIFS(nNIA,DATOS!$A19,nCURSO,DATOS!$D19,nESPEC,DATOS!$E19,nASIG,DATOS!$I19,nEVAL,"EX")=0),0)))) | H19: =IF(DATOS!$G19<>"EX",0,--(COUNTIFS(nNIA,DATOS!$A19,nCURSO,DATOS!$D19,nESPEC,DATOS!$E19,nASIG,DATOS!$I19,nEVAL,"OR")=0)) | I19: =IF(DATOS!$I19="","",IFERROR(VLOOKUP(DATOS!$I19,CONFIG_ASIGNATURAS!$B$2:$J$91,9,FALSE()),""))
F20: =IF(DATOS!$A20="","",DATOS!$A20&"|"&DATOS!$D20&"|"&DATOS!$E20&"|"&DATOS!$I20) | G20: =IF(DATOS!$A20="",0,IF(CONFIG_METADATA!$B$4<>"OR+EX",--(DATOS!$G20=CONFIG_METADATA!$B$4),IF(DATOS!$G20="EX",1,IF(DATOS!$G20="OR",--(COUNTIFS(nNIA,DATOS!$A20,nCURSO,DATOS!$D20,nESPEC,DATOS!$E20,nASIG,DATOS!$I20,nEVAL,"EX")=0),0)))) | H20: =IF(DATOS!$G20<>"EX",0,--(COUNTIFS(nNIA,DATOS!$A20,nCURSO,DATOS!$D20,nESPEC,DATOS!$E20,nASIG,DATOS!$I20,nEVAL,"OR")=0)) | I20: =IF(DATOS!$I20="","",IFERROR(VLOOKUP(DATOS!$I20,CONFIG_ASIGNATURAS!$B$2:$J$91,9,FALSE()),""))
F21: =IF(DATOS!$A21="","",DATOS!$A21&"|"&DATOS!$D21&"|"&DATOS!$E21&"|"&DATOS!$I21) | G21: =IF(DATOS!$A21="",0,IF(CONFIG_METADATA!$B$4<>"OR+EX",--(DATOS!$G21=CONFIG_METADATA!$B$4),IF(DATOS!$G21="EX",1,IF(DATOS!$G21="OR",--(COUNTIFS(nNIA,DATOS!$A21,nCURSO,DATOS!$D21,nESPEC,DATOS!$E21,nASIG,DATOS!$I21,nEVAL,"EX")=0),0)))) | H21: =IF(DATOS!$G21<>"EX",0,--(COUNTIFS(nNIA,DATOS!$A21,nCURSO,DATOS!$D21,nESPEC,DATOS!$E21,nASIG,DATOS!$I21,nEVAL,"OR")=0)) | I21: =IF(DATOS!$I21="","",IFERROR(VLOOKUP(DATOS!$I21,CONFIG_ASIGNATURAS!$B$2:$J$91,9,FALSE()),""))
F22: =IF(DATOS!$A22="","",DATOS!$A22&"|"&DATOS!$D22&"|"&DATOS!$E22&"|"&DATOS!$I22) | G22: =IF(DATOS!$A22="",0,IF(CONFIG_METADATA!$B$4<>"OR+EX",--(DATOS!$G22=CONFIG_METADATA!$B$4),IF(DATOS!$G22="EX",1,IF(DATOS!$G22="OR",--(COUNTIFS(nNIA,DATOS!$A22,nCURSO,DATOS!$D22,nESPEC,DATOS!$E22,nASIG,DATOS!$I22,nEVAL,"EX")=0),0)))) | H22: =IF(DATOS!$G22<>"EX",0,--(COUNTIFS(nNIA,DATOS!$A22,nCURSO,DATOS!$D22,nESPEC,DATOS!$E22,nASIG,DATOS!$I22,nEVAL,"OR")=0)) | I22: =IF(DATOS!$I22="","",IFERROR(VLOOKUP(DATOS!$I22,CONFIG_ASIGNATURAS!$B$2:$J$91,9,FALSE()),""))
... F20000: =IF(DATOS!$A20000="","",DATOS!$A20000&"|"&DATOS!$D20000&"|"&DATOS!$E20000&"|"&DATOS!$I20000) | G20000: =IF(DATOS!$A20000="",0,IF(CONFIG_METADATA!$B$4<>"OR+EX",--(DATOS!$G20000=CONFIG_METADATA!$B$4),IF(DATOS!$G20000="EX",1,IF(DATOS!$G20000="OR",--(COUNTIFS(nNIA,DATOS!$A20000,nCURSO,DATOS!$D20000,nESPEC,DATOS!$E20000,nASIG,DATOS!$I20000,nEVAL,"EX")=0),0)))) | H20000: =IF(DATOS!$G20000<>"EX",0,--(COUNTIFS(nNIA,DATOS!$A20000,nCURSO,DATOS!$D20000,nESPEC,DATOS!$E20000,nASIG,DATOS!$I20000,nEVAL,"OR")=0)) | I20000: =IF(DATOS!$I20000="","",IFERROR(VLOOKUP(DATOS!$I20000,CONFIG_ASIGNATURAS!$B$2:$J$91,9,FALSE()),""))

Sheet CONFIG_CORRELACIONES
A1: ID | B1: Curso | C1: Asignatura1 | D1: Asignatura2 | E1: Activa
A2: 1 | B2: 1EPM | C2: Lenguaje Musical | D2: Orquesta/Banda/Conjunto | E2: Sí
A3: 2 | B3: 1EPM | C3: Lenguaje Musical | D3: Conjunto | E3: Sí
A4: 3 | B4: 1EPM | C4: Lenguaje Musical | D4: Especialidad | E4: Sí
A5: 4 | B5: 1EPM | C5: Orquesta/Banda/Conjunto | D5: Conjunto | E5: Sí
A6: 5 | B6: 1EPM | C6: Orquesta/Banda/Conjunto | D6: Especialidad | E6: Sí
A7: 6 | B7: 1EPM | C7: Conjunto | D7: Especialidad | E7: Sí
A8: 7 | B8: 2EPM | C8: Lenguaje Musical | D8: Orquesta/Banda/Conjunto | E8: Sí
A9: 8 | B9: 2EPM | C9: Lenguaje Musical | D9: Conjunto | E9: Sí
A10: 9 | B10: 2EPM | C10: Lenguaje Musical | D10: Especialidad | E10: Sí
A11: 10 | B11: 2EPM | C11: Orquesta/Banda/Conjunto | D11: Conjunto | E11: Sí
A12: 11 | B12: 2EPM | C12: Orquesta/Banda/Conjunto | D12: Especialidad | E12: Sí
A13: 12 | B13: 2EPM | C13: Conjunto | D13: Especialidad | E13: Sí
... A37: 36 | B37: 6EPM | C37: Música de Cámara | D37: Especialidad | E37: Sí

Sheet DATOS
A1: NIA | B1: Apellidos | C1: Nombre | D1: Curso | E1: Especialidad | F1: Repite | G1: Evaluación | H1: Código Asig | I1: Contenido | J1: Nota | K1: Nota Numérica | L1: Apto | M1: Profesor | N1: Observ.

Sheet CALC_EPM
A1: Nivel | B1: Asignatura | C1: TipoAsig | D1: Registros | E1: NotaMedia | F1: Desviacion | G1: Moda | H1: PctAprobados | I1: PctSuspendidos | J1: ModaAprobados | K1: ModaSuspendidos | L1: Dist1 | M1: Dist2 | N1: Dist3 | O1: Dist4 | P1: Dist5 | Q1: Dist6 | R1: Dist7 | S1: Dist8 | T1: Dist9 | U1: Dist10
A2: GLOBAL | B2: Total | C2: Total | D2: =SUMPRODUCT((nCUENTA=1)*1) -> 0 | E2: =IFERROR(SUMPRODUCT((nCUENTA=1)*(nNOTA))/D2,"—") -> — | F2: {=IFERROR(_xlfn.STDEV.P(_xlfn._xlws.FILTER(nNOTA,nCUENTA=1)),"—")} -> — | G2: {=IFERROR(_xlfn.MODE.SNGL(_xlfn._xlws.FILTER(nNOTA,nCUENTA=1)),"—")} -> — | H2: =IFERROR(SUMPRODUCT((nCUENTA=1)*(nAPTO="S"))/D2,"—") -> — | I2: =IFERROR(SUMPRODUCT((nCUENTA=1)*(nAPTO="N"))/D2,"—") -> — | J2: {=IFERROR(_xlfn.MODE.SNGL(_xlfn._xlws.FILTER(nNOTA,(nCUENTA=1)*(nAPTO="S"))),"—")} -> — | K2: {=IFERROR(_xlfn.MODE.SNGL(_xlfn._xlws.FILTER(nNOTA,(nCUENTA=1)*(nAPTO="N"))),"—")} -> — | L2: =SUMPRODUCT((nCUENTA=1)*(nNOTA=1)) -> 0 | M2: =SUMPRODUCT((nCUENTA=1)*(nNOTA=2)) -> 0 | N2: =SUMPRODUCT((nCUENTA=1)*(nNOTA=3)) -> 0 | O2: =SUMPRODUCT((nCUENTA=1)*(nNOTA=4)) -> 0 | P2: =SUMPRODUCT((nCUENTA=1)*(nNOTA=5)) -> 0 | Q2: =SUMPRODUCT((nCUENTA=1)*(nNOTA=6)) -> 0 | R2: =SUMPRODUCT((nCUENTA=1)*(nNOTA=7)) -> 0 | S2: =SUMPRODUCT((nCUENTA=1)*(nNOTA=8)) -> 0 | T2: =SUMPRODUCT((nCUENTA=1)*(nNOTA=9)) -> 0 | U2: =SUMPRODUCT((nCUENTA=1)*(nNOTA=10)) -> 0
A3: GLOBAL | B3: Total Especialidad | C3: TotalEsp | D3: =SUMPRODUCT((nCUENTA=1)*(nCLASE_I="E")*1) | E3: {=IFERROR(AVERAGE(IF((nCUENTA=1)*(nCLASE_I="E"),nNOTA)),"—")} | F3: {=IFERROR(_xlfn.STDEV.P(IF((nCUENTA=1)*(nCLASE_I="E"),nNOTA)),"—")} | G3: {=IFERROR(_xlfn.MODE.SNGL(IF((nCUENTA=1)*(nCLASE_I="E"),nNOTA)),"—")} | H3: =IFERROR(SUMPRODUCT((nCUENTA=1)*(nCLASE_I="E")*(nAPTO="S"))/SUMPRODUCT((nCUENTA=1)*(nCLASE_I="E")*1),"—") | I3: =IFERROR(SUMPRODUCT((nCUENTA=1)*(nCLASE_I="E")*(nAPTO="N"))/SUMPRODUCT((nCUENTA=1)*(nCLASE_I="E")*1),"—") | J3: {=IFERROR(_xlfn.MODE.SNGL(IF((nCUENTA=1)*(nCLASE_I="E")*(nAPTO="S"),nNOTA)),"—")} | K3: {=IFERROR(_xlfn.MODE.SNGL(IF((nCUENTA=1)*(nCLASE_I="E")*(nAPTO="N"),nNOTA)),"—")} | L3: =SUMPRODUCT((nCUENTA=1)*(nCLASE_I="E")*(nNOTA=1)) | M3: =SUMPRODUCT((nCUENTA=1)*(nCLASE_I="E")*(nNOTA=2)) | N3: =SUMPRODUCT((nCUENTA=1)*(nCLASE_I="E")*(nNOTA=3)) | O3: =SUMPRODUCT((nCUENTA=1)*(nCLASE_I="E")*(nNOTA=4)) | P3: =SUMPRODUCT((nCUENTA=1)*(nCLASE_I="E")*(nNOTA=5)) | Q3: =SUMPRODUCT((nCUENTA=1)*(nCLASE_I="E")*(nNOTA=6)) | R3: =SUMPRODUCT((nCUENTA=1)*(nCLASE_I="E")*(nNOTA=7)) | S3: =SUMPRODUCT((nCUENTA=1)*(nCLASE_I="E")*(nNOTA=8)) | T3: =SUMPRODUCT((nCUENTA=1)*(nCLASE_I="E")*(nNOTA=9)) | U3: =SUMPRODUCT((nCUENTA=1)*(nCLASE_I="E")*(nNOTA=10))
A4: GLOBAL | B4: Total No Especialidad | C4: TotalNoEsp | D4: =SUMPRODUCT((nCUENTA=1)*((nCLASE_I<>"")*(nCLASE_I<>"E"))*1) | E4: {=IFERROR(AVERAGE(IF((nCUENTA=1)*((nCLASE_I<>"")*(nCLASE_I<>"E")),nNOTA)),"—")} | F4: {=IFERROR(_xlfn.STDEV.P(IF((nCUENTA=1)*((nCLASE_I<>"")*(nCLASE_I<>"E")),nNOTA)),"—")} | G4: {=IFERROR(_xlfn.MODE.SNGL(IF((nCUENTA=1)*((nCLASE_I<>"")*(nCLASE_I<>"E")),nNOTA)),"—")} | H4: =IFERROR(SUMPRODUCT((nCUENTA=1)*((nCLASE_I<>"")*(nCLASE_I<>"E"))*(nAPTO="S"))/SUMPRODUCT((nCUENTA=1)*((nCLASE_I<>"")*(nCLASE_I<>"E"))*1),"—") | I4: =IFERROR(SUMPRODUCT((nCUENTA=1)*((nCLASE_I<>"")*(nCLASE_I<>"E"))*(nAPTO="N"))/SUMPRODUCT((nCUENTA=1)*((nCLASE_I<>"")*(nCLASE_I<>"E"))*1),"—") | J4: {=IFERROR(_xlfn.MODE.SNGL(IF((nCUENTA=1)*((nCLASE_I<>"")*(nCLASE_I<>"E"))*(nAPTO="S"),nNOTA)),"—")} | K4: {=IFERROR(_xlfn.MODE.SNGL(IF((nCUENTA=1)*((nCLASE_I<>"")*(nCLASE_I<>"E"))*(nAPTO="N"),nNOTA)),"—")} | L4: =SUMPRODUCT((nCUENTA=1)*((nCLASE_I<>"")*(nCLASE_I<>"E"))*(nNOTA=1)) | M4: =SUMPRODUCT((nCUENTA=1)*((nCLASE_I<>"")*(nCLASE_I<>"E"))*(nNOTA=2)) | N4: =SUMPRODUCT((nCUENTA=1)*((nCLASE_I<>"")*(nCLASE_I<>"E"))*(nNOTA=3)) | O4: =SUMPRODUCT((nCUENTA=1)*((nCLASE_I<>"")*(nCLASE_I<>"E"))*(nNOTA=4)) | P4: =SUMPRODUCT((nCUENTA=1)*((nCLASE_I<>"")*(nCLASE_I<>"E"))*(nNOTA=5)) | Q4: =SUMPRODUCT((nCUENTA=1)*((nCLASE_I<>"")*(nCLASE_I<>"E"))*(nNOTA=6)) | R4: =SUMPRODUCT((nCUENTA=1)*((nCLASE_I<>"")*(nCLASE_I<>"E"))*(nNOTA=7)) | S4: =SUMPRODUCT((nCUENTA=1)*((nCLASE_I<>"")*(nCLASE_I<>"E"))*(nNOTA=8)) | T4: =SUMPRODUCT((nCUENTA=1)*((nCLASE_I<>"")*(nCLASE_I<>"E"))*(nNOTA=9)) | U4: =SUMPRODUCT((nCUENTA=1)*((nCLASE_I<>"")*(nCLASE_I<>"E"))*(nNOTA=10))
A5: GLOBAL | B5: Teórica Troncal | C5: TeoricaTroncal | D5: =SUMPRODUCT((nCUENTA=1)*(nCLASE_I="NT")*1) | E5: {=IFERROR(AVERAGE(IF((nCUENTA=1)*(nCLASE_I="NT"),nNOTA)),"—")} | F5: {=IFERROR(_xlfn.STDEV.P(IF((nCUENTA=1)*(nCLASE_I="NT"),nNOTA)),"—")} | G5: {=IFERROR(_xlfn.MODE.SNGL(IF((nCUENTA=1)*(nCLASE_I="NT"),nNOTA)),"—")} | H5: =IFERROR(SUMPRODUCT((nCUENTA=1)*(nCLASE_I="NT")*(nAPTO="S"))/SUMPRODUCT((nCUENTA=1)*(nCLASE_I="NT")*1),"—") | I5: =IFERROR(SUMPRODUCT((nCUENTA=1)*(nCLASE_I="NT")*(nAPTO="N"))/SUMPRODUCT((nCUENTA=1)*(nCLASE_I="NT")*1),"—") | J5: {=IFERROR(_xlfn.MODE.SNGL(IF((nCUENTA=1)*(nCLASE_I="NT")*(nAPTO="S"),nNOTA)),"—")} | K5: {=IFERROR(_xlfn.MODE.SNGL(IF((nCUENTA=1)*(nCLASE_I="NT")*(nAPTO="N"),nNOTA)),"—")} | L5: =SUMPRODUCT((nCUENTA=1)*(nCLASE_I="NT")*(nNOTA=1)) | M5: =SUMPRODUCT((nCUENTA=1)*(nCLASE_I="NT")*(nNOTA=2)) | N5: =SUMPRODUCT((nCUENTA=1)*(nCLASE_I="NT")*(nNOTA=3)) | O5: =SUMPRODUCT((nCUENTA=1)*(nCLASE_I="NT")*(nNOTA=4)) | P5: =SUMPRODUCT((nCUENTA=1)*(nCLASE_I="NT")*(nNOTA=5)) | Q5: =SUMPRODUCT((nCUENTA=1)*(nCLASE_I="NT")*(nNOTA=6)) | R5: =SUMPRODUCT((nCUENTA=1)*(nCLASE_I="NT")*(nNOTA=7)) | S5: =SUMPRODUCT((nCUENTA=1)*(nCLASE_I="NT")*(nNOTA=8)) | T5: =SUMPRODUCT((nCUENTA=1)*(nCLASE_I="NT")*(nNOTA=9)) | U5: =SUMPRODUCT((nCUENTA=1)*(nCLASE_I="NT")*(nNOTA=10))
A6: GLOBAL | B6: {=IFERROR(INDEX(_xlfn._xlws.FILTER(CONFIG_ASIGNATURAS!$B$2:$B$91,CONFIG_ASIGNATURAS!$G$2:$G$91="Sí"),1),"")} | C6: =IF(B6="","",IFERROR(VLOOKUP(B6,CONFIG_ASIGNATURAS!$B$2:$D$91,3,FALSE()),"Asignatura")) | D6: =SUMPRODUCT((nCUENTA=1)*(nASIG=B6)) -> 0 | E6: =IFERROR(SUMPRODUCT((nCUENTA=1)*(nASIG=B6)*(nNOTA))/D6,"—") -> — | F6: {=IFERROR(_xlfn.STDEV.P(_xlfn._xlws.FILTER(nNOTA,(nCUENTA=1)*(nASIG=B6))),"—")} -> — | G6: {=IFERROR(_xlfn.MODE.SNGL(_xlfn._xlws.FILTER(nNOTA,(nCUENTA=1)*(nASIG=B6))),"—")} -> — | H6: =IFERROR(SUMPRODUCT((nCUENTA=1)*(nASIG=B6)*(nAPTO="S"))/D6,"—") -> — | I6: =IFERROR(SUMPRODUCT((nCUENTA=1)*(nASIG=B6)*(nAPTO="N"))/D6,"—") -> — | J6: {=IFERROR(_xlfn.MODE.SNGL(_xlfn._xlws.FILTER(nNOTA,(nCUENTA=1)*(nASIG=B6)*(nAPTO="S"))),"—")} -> — | K6: {=IFERROR(_xlfn.MODE.SNGL(_xlfn._xlws.FILTER(nNOTA,(nCUENTA=1)*(nASIG=B6)*(nAPTO="N"))),"—")} -> — | L6: =SUMPRODUCT((nCUENTA=1)*(nASIG=B6)*(nNOTA=1)) -> 0 | M6: =SUMPRODUCT((nCUENTA=1)*(nASIG=B6)*(nNOTA=2)) -> 0 | N6: =SUMPRODUCT((nCUENTA=1)*(nASIG=B6)*(nNOTA=3)) -> 0 | O6: =SUMPRODUCT((nCUENTA=1)*(nASIG=B6)*(nNOTA=4)) -> 0 | P6: =SUMPRODUCT((nCUENTA=1)*(nASIG=B6)*(nNOTA=5)) -> 0 | Q6: =SUMPRODUCT((nCUENTA=1)*(nASIG=B6)*(nNOTA=6)) -> 0 | R6: =SUMPRODUCT((nCUENTA=1)*(nASIG=B6)*(nNOTA=7)) -> 0 | S6: =SUMPRODUCT((nCUENTA=1)*(nASIG=B6)*(nNOTA=8)) -> 0 | T6: =SUMPRODUCT((nCUENTA=1)*(nASIG=B6)*(nNOTA=9)) -> 0 | U6: =SUMPRODUCT((nCUENTA=1)*(nASIG=B6)*(nNOTA=10)) -> 0
A7: GLOBAL | B7: {=IFERROR(INDEX(_xlfn._xlws.FILTER(CONFIG_ASIGNATURAS!$B$2:$B$91,CONFIG_ASIGNATURAS!$G$2:$G$91="Sí"),2),"")} | C7: =IF(B7="","",IFERROR(VLOOKUP(B7,CONFIG_ASIGNATURAS!$B$2:$D$91,3,FALSE()),"Asignatura")) | D7: =SUMPRODUCT((nCUENTA=1)*(nASIG=B7)) -> 0 | E7: =IFERROR(SUMPRODUCT((nCUENTA=1)*(nASIG=B7)*(nNOTA))/D7,"—") -> — | F7: {=IFERROR(_xlfn.STDEV.P(_xlfn._xlws.FILTER(nNOTA,(nCUENTA=1)*(nASIG=B7))),"—")} -> — | G7: {=IFERROR(_xlfn.MODE.SNGL(_xlfn._xlws.FILTER(nNOTA,(nCUENTA=1)*(nASIG=B7))),"—")} -> — | H7: =IFERROR(SUMPRODUCT((nCUENTA=1)*(nASIG=B7)*(nAPTO="S"))/D7,"—") -> — | I7: =IFERROR(SUMPRODUCT((nCUENTA=1)*(nASIG=B7)*(nAPTO="N"))/D7,"—") -> — | J7: {=IFERROR(_xlfn.MODE.SNGL(_xlfn._xlws.FILTER(nNOTA,(nCUENTA=1)*(nASIG=B7)*(nAPTO="S"))),"—")} -> — | K7: {=IFERROR(_xlfn.MODE.SNGL(_xlfn._xlws.FILTER(nNOTA,(nCUENTA=1)*(nASIG=B7)*(nAPTO="N"))),"—")} -> — | L7: =SUMPRODUCT((nCUENTA=1)*(nASIG=B7)*(nNOTA=1)) -> 0 | M7: =SUMPRODUCT((nCUENTA=1)*(nASIG=B7)*(nNOTA=2)) -> 0 | N7: =SUMPRODUCT((nCUENTA=1)*(nASIG=B7)*(nNOTA=3)) -> 0 | O7: =SUMPRODUCT((nCUENTA=1)*(nASIG=B7)*(nNOTA=4)) -> 0 | P7: =SUMPRODUCT((nCUENTA=1)*(nASIG=B7)*(nNOTA=5)) -> 0 | Q7: =SUMPRODUCT((nCUENTA=1)*(nASIG=B7)*(nNOTA=6)) -> 0 | R7: =SUMPRODUCT((nCUENTA=1)*(nASIG=B7)*(nNOTA=7)) -> 0 | S7: =SUMPRODUCT((nCUENTA=1)*(nASIG=B7)*(nNOTA=8)) -> 0 | T7: =SUMPRODUCT((nCUENTA=1)*(nASIG=B7)*(nNOTA=9)) -> 0 | U7: =SUMPRODUCT((nCUENTA=1)*(nASIG=B7)*(nNOTA=10)) -> 0
A8: GLOBAL | B8: {=IFERROR(INDEX(_xlfn._xlws.FILTER(CONFIG_ASIGNATURAS!$B$2:$B$91,CONFIG_ASIGNATURAS!$G$2:$G$91="Sí"),3),"")} | C8: =IF(B8="","",IFERROR(VLOOKUP(B8,CONFIG_ASIGNATURAS!$B$2:$D$91,3,FALSE()),"Asignatura")) | D8: =SUMPRODUCT((nCUENTA=1)*(nASIG=B8)) -> 0 | E8: =IFERROR(SUMPRODUCT((nCUENTA=1)*(nASIG=B8)*(nNOTA))/D8,"—") -> — | F8: {=IFERROR(_xlfn.STDEV.P(_xlfn._xlws.FILTER(nNOTA,(nCUENTA=1)*(nASIG=B8))),"—")} -> — | G8: {=IFERROR(_xlfn.MODE.SNGL(_xlfn._xlws.FILTER(nNOTA,(nCUENTA=1)*(nASIG=B8))),"—")} -> — | H8: =IFERROR(SUMPRODUCT((nCUENTA=1)*(nASIG=B8)*(nAPTO="S"))/D8,"—") -> — | I8: =IFERROR(SUMPRODUCT((nCUENTA=1)*(nASIG=B8)*(nAPTO="N"))/D8,"—") -> — | J8: {=IFERROR(_xlfn.MODE.SNGL(_xlfn._xlws.FILTER(nNOTA,(nCUENTA=1)*(nASIG=B8)*(nAPTO="S"))),"—")} -> — | K8: {=IFERROR(_xlfn.MODE.SNGL(_xlfn._xlws.FILTER(nNOTA,(nCUENTA=1)*(nASIG=B8)*(nAPTO="N"))),"—")} -> — | L8: =SUMPRODUCT((nCUENTA=1)*(nASIG=B8)*(nNOTA=1)) -> 0 | M8: =SUMPRODUCT((nCUENTA=1)*(nASIG=B8)*(nNOTA=2)) -> 0 | N8: =SUMPRODUCT((nCUENTA=1)*(nASIG=B8)*(nNOTA=3)) -> 0 | O8: =SUMPRODUCT((nCUENTA=1)*(nASIG=B8)*(nNOTA=4)) -> 0 | P8: =SUMPRODUCT((nCUENTA=1)*(nASIG=B8)*(nNOTA=5)) -> 0 | Q8: =SUMPRODUCT((nCUENTA=1)*(nASIG=B8)*(nNOTA=6)) -> 0 | R8: =SUMPRODUCT((nCUENTA=1)*(nASIG=B8)*(nNOTA=7)) -> 0 | S8: =SUMPRODUCT((nCUENTA=1)*(nASIG=B8)*(nNOTA=8)) -> 0 | T8: =SUMPRODUCT((nCUENTA=1)*(nASIG=B8)*(nNOTA=9)) -> 0 | U8: =SUMPRODUCT((nCUENTA=1)*(nASIG=B8)*(nNOTA=10)) -> 0
A9: GLOBAL | B9: {=IFERROR(INDEX(_xlfn._xlws.FILTER(CONFIG_ASIGNATURAS!$B$2:$B$91,CONFIG_ASIGNATURAS!$G$2:$G$91="Sí"),4),"")} | C9: =IF(B9="","",IFERROR(VLOOKUP(B9,CONFIG_ASIGNATURAS!$B$2:$D$91,3,FALSE()),"Asignatura")) | D9: =SUMPRODUCT((nCUENTA=1)*(nASIG=B9)) -> 0 | E9: =IFERROR(SUMPRODUCT((nCUENTA=1)*(nASIG=B9)*(nNOTA))/D9,"—") -> — | F9: {=IFERROR(_xlfn.STDEV.P(_xlfn._xlws.FILTER(nNOTA,(nCUENTA=1)*(nASIG=B9))),"—")} -> — | G9: {=IFERROR(_xlfn.MODE.SNGL(_xlfn._xlws.FILTER(nNOTA,(nCUENTA=1)*(nASIG=B9))),"—")} -> — | H9: =IFERROR(SUMPRODUCT((nCUENTA=1)*(nASIG=B9)*(nAPTO="S"))/D9,"—") -> — | I9: =IFERROR(SUMPRODUCT((nCUENTA=1)*(nASIG=B9)*(nAPTO="N"))/D9,"—") -> — | J9: {=IFERROR(_xlfn.MODE.SNGL(_xlfn._xlws.FILTER(nNOTA,(nCUENTA=1)*(nASIG=B9)*(nAPTO="S"))),"—")} -> — | K9: {=IFERROR(_xlfn.MODE.SNGL(_xlfn._xlws.FILTER(nNOTA,(nCUENTA=1)*(nASIG=B9)*(nAPTO="N"))),"—")} -> — | L9: =SUMPRODUCT((nCUENTA=1)*(nASIG=B9)*(nNOTA=1)) -> 0 | M9: =SUMPRODUCT((nCUENTA=1)*(nASIG=B9)*(nNOTA=2)) -> 0 | N9: =SUMPRODUCT((nCUENTA=1)*(nASIG=B9)*(nNOTA=3)) -> 0 | O9: =SUMPRODUCT((nCUENTA=1)*(nASIG=B9)*(nNOTA=4)) -> 0 | P9: =SUMPRODUCT((nCUENTA=1)*(nASIG=B9)*(nNOTA=5)) -> 0 | Q9: =SUMPRODUCT((nCUENTA=1)*(nASIG=B9)*(nNOTA=6)) -> 0 | R9: =SUMPRODUCT((nCUENTA=1)*(nASIG=B9)*(nNOTA=7)) -> 0 | S9: =SUMPRODUCT((nCUENTA=1)*(nASIG=B9)*(nNOTA=8)) -> 0 | T9: =SUMPRODUCT((nCUENTA=1)*(nASIG=B9)*(nNOTA=9)) -> 0 | U9: =SUMPRODUCT((nCUENTA=1)*(nASIG=B9)*(nNOTA=10)) -> 0
A10: GLOBAL | B10: {=IFERROR(INDEX(_xlfn._xlws.FILTER(CONFIG_ASIGNATURAS!$B$2:$B$91,CONFIG_ASIGNATURAS!$G$2:$G$91="Sí"),5),"")} | C10: =IF(B10="","",IFERROR(VLOOKUP(B10,CONFIG_ASIGNATURAS!$B$2:$D$91,3,FALSE()),"Asignatura")) | D10: =SUMPRODUCT((nCUENTA=1)*(nASIG=B10)) -> 0 | E10: =IFERROR(SUMPRODUCT((nCUENTA=1)*(nASIG=B10)*(nNOTA))/D10,"—") -> — | F10: {=IFERROR(_xlfn.STDEV.P(_xlfn._xlws.FILTER(nNOTA,(nCUENTA=1)*(nASIG=B10))),"—")} -> — | G10: {=IFERROR(_xlfn.MODE.SNGL(_xlfn._xlws.FILTER(nNOTA,(nCUENTA=1)*(nASIG=B10))),"—")} -> — | H10: =IFERROR(SUMPRODUCT((nCUENTA=1)*(nASIG=B10)*(nAPTO="S"))/D10,"—") -> — | I10: =IFERROR(SUMPRODUCT((nCUENTA=1)*(nASIG=B10)*(nAPTO="N"))/D10,"—") -> — | J10: {=IFERROR(_xlfn.MODE.SNGL(_xlfn._xlws.FILTER(nNOTA,(nCUENTA=1)*(nASIG=B10)*(nAPTO="S"))),"—")} -> — | K10: {=IFERROR(_xlfn.MODE.SNGL(_xlfn._xlws.FILTER(nNOTA,(nCUENTA=1)*(nASIG=B10)*(nAPTO="N"))),"—")} -> — | L10: =SUMPRODUCT((nCUENTA=1)*(nASIG=B10)*(nNOTA=1)) -> 0 | M10: =SUMPRODUCT((nCUENTA=1)*(nASIG=B10)*(nNOTA=2)) -> 0 | N10: =SUMPRODUCT((nCUENTA=1)*(nASIG=B10)*(nNOTA=3)) -> 0 | O10: =SUMPRODUCT((nCUENTA=1)*(nASIG=B10)*(nNOTA=4)) -> 0 | P10: =SUMPRODUCT((nCUENTA=1)*(nASIG=B10)*(nNOTA=5)) -> 0 | Q10: =SUMPRODUCT((nCUENTA=1)*(nASIG=B10)*(nNOTA=6)) -> 0 | R10: =SUMPRODUCT((nCUENTA=1)*(nASIG=B10)*(nNOTA=7)) -> 0 | S10: =SUMPRODUCT((nCUENTA=1)*(nASIG=B10)*(nNOTA=8)) -> 0 | T10: =SUMPRODUCT((nCUENTA=1)*(nASIG=B10)*(nNOTA=9)) -> 0 | U10: =SUMPRODUCT((nCUENTA=1)*(nASIG=B10)*(nNOTA=10)) -> 0
A11: GLOBAL | B11: {=IFERROR(INDEX(_xlfn._xlws.FILTER(CONFIG_ASIGNATURAS!$B$2:$B$91,CONFIG_ASIGNATURAS!$G$2:$G$91="Sí"),6),"")} | C11: =IF(B11="","",IFERROR(VLOOKUP(B11,CONFIG_ASIGNATURAS!$B$2:$D$91,3,FALSE()),"Asignatura")) | D11: =SUMPRODUCT((nCUENTA=1)*(nASIG=B11)) -> 0 | E11: =IFERROR(SUMPRODUCT((nCUENTA=1)*(nASIG=B11)*(nNOTA))/D11,"—") -> — | F11: {=IFERROR(_xlfn.STDEV.P(_xlfn._xlws.FILTER(nNOTA,(nCUENTA=1)*(nASIG=B11))),"—")} -> — | G11: {=IFERROR(_xlfn.MODE.SNGL(_xlfn._xlws.FILTER(nNOTA,(nCUENTA=1)*(nASIG=B11))),"—")} -> — | H11: =IFERROR(SUMPRODUCT((nCUENTA=1)*(nASIG=B11)*(nAPTO="S"))/D11,"—") -> — | I11: =IFERROR(SUMPRODUCT((nCUENTA=1)*(nASIG=B11)*(nAPTO="N"))/D11,"—") -> — | J11: {=IFERROR(_xlfn.MODE.SNGL(_xlfn._xlws.FILTER(nNOTA,(nCUENTA=1)*(nASIG=B11)*(nAPTO="S"))),"—")} -> — | K11: {=IFERROR(_xlfn.MODE.SNGL(_xlfn._xlws.FILTER(nNOTA,(nCUENTA=1)*(nASIG=B11)*(nAPTO="N"))),"—")} -> — | L11: =SUMPRODUCT((nCUENTA=1)*(nASIG=B11)*(nNOTA=1)) -> 0 | M11: =SUMPRODUCT((nCUENTA=1)*(nASIG=B11)*(nNOTA=2)) -> 0 | N11: =SUMPRODUCT((nCUENTA=1)*(nASIG=B11)*(nNOTA=3)) -> 0 | O11: =SUMPRODUCT((nCUENTA=1)*(nASIG=B11)*(nNOTA=4)) -> 0 | P11: =SUMPRODUCT((nCUENTA=1)*(nASIG=B11)*(nNOTA=5)) -> 0 | Q11: =SUMPRODUCT((nCUENTA=1)*(nASIG=B11)*(nNOTA=6)) -> 0 | R11: =SUMPRODUCT((nCUENTA=1)*(nASIG=B11)*(nNOTA=7)) -> 0 | S11: =SUMPRODUCT((nCUENTA=1)*(nASIG=B11)*(nNOTA=8)) -> 0 | T11: =SUMPRODUCT((nCUENTA=1)*(nASIG=B11)*(nNOTA=9)) -> 0 | U11: =SUMPRODUCT((nCUENTA=1)*(nASIG=B11)*(nNOTA=10)) -> 0
A12: GLOBAL | B12: {=IFERROR(INDEX(_xlfn._xlws.FILTER(CONFIG_ASIGNATURAS!$B$2:$B$91,CONFIG_ASIGNATURAS!$G$2:$G$91="Sí"),7),"")} | C12: =IF(B12="","",IFERROR(VLOOKUP(B12,CONFIG_ASIGNATURAS!$B$2:$D$91,3,FALSE()),"Asignatura")) | D12: =SUMPRODUCT((nCUENTA=1)*(nASIG=B12)) -> 0 | E12: =IFERROR(SUMPRODUCT((nCUENTA=1)*(nASIG=B12)*(nNOTA))/D12,"—") -> — | F12: {=IFERROR(_xlfn.STDEV.P(_xlfn._xlws.FILTER(nNOTA,(nCUENTA=1)*(nASIG=B12))),"—")} -> — | G12: {=IFERROR(_xlfn.MODE.SNGL(_xlfn._xlws.FILTER(nNOTA,(nCUENTA=1)*(nASIG=B12))),"—")} -> — | H12: =IFERROR(SUMPRODUCT((nCUENTA=1)*(nASIG=B12)*(nAPTO="S"))/D12,"—") -> — | I12: =IFERROR(SUMPRODUCT((nCUENTA=1)*(nASIG=B12)*(nAPTO="N"))/D12,"—") -> — | J12: {=IFERROR(_xlfn.MODE.SNGL(_xlfn._xlws.FILTER(nNOTA,(nCUENTA=1)*(nASIG=B12)*(nAPTO="S"))),"—")} -> — | K12: {=IFERROR(_xlfn.MODE.SNGL(_xlfn._xlws.FILTER(nNOTA,(nCUENTA=1)*(nASIG=B12)*(nAPTO="N"))),"—")} -> — | L12: =SUMPRODUCT((nCUENTA=1)*(nASIG=B12)*(nNOTA=1)) -> 0 | M12: =SUMPRODUCT((nCUENTA=1)*(nASIG=B12)*(nNOTA=2)) -> 0 | N12: =SUMPRODUCT((nCUENTA=1)*(nASIG=B12)*(nNOTA=3)) -> 0 | O12: =SUMPRODUCT((nCUENTA=1)*(nASIG=B12)*(nNOTA=4)) -> 0 | P12: =SUMPRODUCT((nCUENTA=1)*(nASIG=B12)*(nNOTA=5)) -> 0 | Q12: =SUMPRODUCT((nCUENTA=1)*(nASIG=B12)*(nNOTA=6)) -> 0 | R12: =SUMPRODUCT((nCUENTA=1)*(nASIG=B12)*(nNOTA=7)) -> 0 | S12: =SUMPRODUCT((nCUENTA=1)*(nASIG=B12)*(nNOTA=8)) -> 0 | T12: =SUMPRODUCT((nCUENTA=1)*(nASIG=B12)*(nNOTA=9)) -> 0 | U12: =SUMPRODUCT((nCUENTA=1)*(nASIG=B12)*(nNOTA=10)) -> 0
A13: GLOBAL | B13: {=IFERROR(INDEX(_xlfn._xlws.FILTER(CONFIG_ASIGNATURAS!$B$2:$B$91,CONFIG_ASIGNATURAS!$G$2:$G$91="Sí"),8),"")} | C13: =IF(B13="","",IFERROR(VLOOKUP(B13,CONFIG_ASIGNATURAS!$B$2:$D$91,3,FALSE()),"Asignatura")) | D13: =SUMPRODUCT((nCUENTA=1)*(nASIG=B13)) -> 0 | E13: =IFERROR(SUMPRODUCT((nCUENTA=1)*(nASIG=B13)*(nNOTA))/D13,"—") -> — | F13: {=IFERROR(_xlfn.STDEV.P(_xlfn._xlws.FILTER(nNOTA,(nCUENTA=1)*(nASIG=B13))),"—")} -> — | G13: {=IFERROR(_xlfn.MODE.SNGL(_xlfn._xlws.FILTER(nNOTA,(nCUENTA=1)*(nASIG=B13))),"—")} -> — | H13: =IFERROR(SUMPRODUCT((nCUENTA=1)*(nASIG=B13)*(nAPTO="S"))/D13,"—") -> — | I13: =IFERROR(SUMPRODUCT((nCUENTA=1)*(nASIG=B13)*(nAPTO="N"))/D13,"—") -> — | J13: {=IFERROR(_xlfn.MODE.SNGL(_xlfn._xlws.FILTER(nNOTA,(nCUENTA=1)*(nASIG=B13)*(nAPTO="S"))),"—")} -> — | K13: {=IFERROR(_xlfn.MODE.SNGL(_xlfn._xlws.FILTER(nNOTA,(nCUENTA=1)*(nASIG=B13)*(nAPTO="N"))),"—")} -> — | L13: =SUMPRODUCT((nCUENTA=1)*(nASIG=B13)*(nNOTA=1)) -> 0 | M13: =SUMPRODUCT((nCUENTA=1)*(nASIG=B13)*(nNOTA=2)) -> 0 | N13: =SUMPRODUCT((nCUENTA=1)*(nASIG=B13)*(nNOTA=3)) -> 0 | O13: =SUMPRODUCT((nCUENTA=1)*(nASIG=B13)*(nNOTA=4)) -> 0 | P13: =SUMPRODUCT((nCUENTA=1)*(nASIG=B13)*(nNOTA=5)) -> 0 | Q13: =SUMPRODUCT((nCUENTA=1)*(nASIG=B13)*(nNOTA=6)) -> 0 | R13: =SUMPRODUCT((nCUENTA=1)*(nASIG=B13)*(nNOTA=7)) -> 0 | S13: =SUMPRODUCT((nCUENTA=1)*(nASIG=B13)*(nNOTA=8)) -> 0 | T13: =SUMPRODUCT((nCUENTA=1)*(nASIG=B13)*(nNOTA=9)) -> 0 | U13: =SUMPRODUCT((nCUENTA=1)*(nASIG=B13)*(nNOTA=10)) -> 0
A14: GLOBAL | B14: {=IFERROR(INDEX(_xlfn._xlws.FILTER(CONFIG_ASIGNATURAS!$B$2:$B$91,CONFIG_ASIGNATURAS!$G$2:$G$91="Sí"),9),"")} | C14: =IF(B14="","",IFERROR(VLOOKUP(B14,CONFIG_ASIGNATURAS!$B$2:$D$91,3,FALSE()),"Asignatura")) | D14: =SUMPRODUCT((nCUENTA=1)*(nASIG=B14)) -> 0 | E14: =IFERROR(SUMPRODUCT((nCUENTA=1)*(nASIG=B14)*(nNOTA))/D14,"—") -> — | F14: {=IFERROR(_xlfn.STDEV.P(_xlfn._xlws.FILTER(nNOTA,(nCUENTA=1)*(nASIG=B14))),"—")} -> — | G14: {=IFERROR(_xlfn.MODE.SNGL(_xlfn._xlws.FILTER(nNOTA,(nCUENTA=1)*(nASIG=B14))),"—")} -> — | H14: =IFERROR(SUMPRODUCT((nCUENTA=1)*(nASIG=B14)*(nAPTO="S"))/D14,"—") -> — | I14: =IFERROR(SUMPRODUCT((nCUENTA=1)*(nASIG=B14)*(nAPTO="N"))/D14,"—") -> — | J14: {=IFERROR(_xlfn.MODE.SNGL(_xlfn._xlws.FILTER(nNOTA,(nCUENTA=1)*(nASIG=B14)*(nAPTO="S"))),"—")} -> — | K14: {=IFERROR(_xlfn.MODE.SNGL(_xlfn._xlws.FILTER(nNOTA,(nCUENTA=1)*(nASIG=B14)*(nAPTO="N"))),"—")} -> — | L14: =SUMPRODUCT((nCUENTA=1)*(nASIG=B14)*(nNOTA=1)) -> 0 | M14: =SUMPRODUCT((nCUENTA=1)*(nASIG=B14)*(nNOTA=2)) -> 0 | N14: =SUMPRODUCT((nCUENTA=1)*(nASIG=B14)*(nNOTA=3)) -> 0 | O14: =SUMPRODUCT((nCUENTA=1)*(nASIG=B14)*(nNOTA=4)) -> 0 | P14: =SUMPRODUCT((nCUENTA=1)*(nASIG=B14)*(nNOTA=5)) -> 0 | Q14: =SUMPRODUCT((nCUENTA=1)*(nASIG=B14)*(nNOTA=6)) -> 0 | R14: =SUMPRODUCT((nCUENTA=1)*(nASIG=B14)*(nNOTA=7)) -> 0 | S14: =SUMPRODUCT((nCUENTA=1)*(nASIG=B14)*(nNOTA=8)) -> 0 | T14: =SUMPRODUCT((nCUENTA=1)*(nASIG=B14)*(nNOTA=9)) -> 0 | U14: =SUMPRODUCT((nCUENTA=1)*(nASIG=B14)*(nNOTA=10)) -> 0
A15: GLOBAL | B15: {=IFERROR(INDEX(_xlfn._xlws.FILTER(CONFIG_ASIGNATURAS!$B$2:$B$91,CONFIG_ASIGNATURAS!$G$2:$G$91="Sí"),10),"")} | C15: =IF(B15="","",IFERROR(VLOOKUP(B15,CONFIG_ASIGNATURAS!$B$2:$D$91,3,FALSE()),"Asignatura")) | D15: =SUMPRODUCT((nCUENTA=1)*(nASIG=B15)) -> 0 | E15: =IFERROR(SUMPRODUCT((nCUENTA=1)*(nASIG=B15)*(nNOTA))/D15,"—") -> — | F15: {=IFERROR(_xlfn.STDEV.P(_xlfn._xlws.FILTER(nNOTA,(nCUENTA=1)*(nASIG=B15))),"—")} -> — | G15: {=IFERROR(_xlfn.MODE.SNGL(_xlfn._xlws.FILTER(nNOTA,(nCUENTA=1)*(nASIG=B15))),"—")} -> — | H15: =IFERROR(SUMPRODUCT((nCUENTA=1)*(nASIG=B15)*(nAPTO="S"))/D15,"—") -> — | I15: =IFERROR(SUMPRODUCT((nCUENTA=1)*(nASIG=B15)*(nAPTO="N"))/D15,"—") -> — | J15: {=IFERROR(_xlfn.MODE.SNGL(_xlfn._xlws.FILTER(nNOTA,(nCUENTA=1)*(nASIG=B15)*(nAPTO="S"))),"—")} -> — | K15: {=IFERROR(_xlfn.MODE.SNGL(_xlfn._xlws.FILTER(nNOTA,(nCUENTA=1)*(nASIG=B15)*(nAPTO="N"))),"—")} -> — | L15: =SUMPRODUCT((nCUENTA=1)*(nASIG=B15)*(nNOTA=1)) -> 0 | M15: =SUMPRODUCT((nCUENTA=1)*(nASIG=B15)*(nNOTA=2)) -> 0 | N15: =SUMPRODUCT((nCUENTA=1)*(nASIG=B15)*(nNOTA=3)) -> 0 | O15: =SUMPRODUCT((nCUENTA=1)*(nASIG=B15)*(nNOTA=4)) -> 0 | P15: =SUMPRODUCT((nCUENTA=1)*(nASIG=B15)*(nNOTA=5)) -> 0 | Q15: =SUMPRODUCT((nCUENTA=1)*(nASIG=B15)*(nNOTA=6)) -> 0 | R15: =SUMPRODUCT((nCUENTA=1)*(nASIG=B15)*(nNOTA=7)) -> 0 | S15: =SUMPRODUCT((nCUENTA=1)*(nASIG=B15)*(nNOTA=8)) -> 0 | T15: =SUMPRODUCT((nCUENTA=1)*(nASIG=B15)*(nNOTA=9)) -> 0 | U15: =SUMPRODUCT((nCUENTA=1)*(nASIG=B15)*(nNOTA=10)) -> 0
A16: GLOBAL | B16: {=IFERROR(INDEX(_xlfn._xlws.FILTER(CONFIG_ASIGNATURAS!$B$2:$B$91,CONFIG_ASIGNATURAS!$G$2:$G$91="Sí"),11),"")} | C16: =IF(B16="","",IFERROR(VLOOKUP(B16,CONFIG_ASIGNATURAS!$B$2:$D$91,3,FALSE()),"Asignatura")) | D16: =SUMPRODUCT((nCUENTA=1)*(nASIG=B16)) -> 0 | E16: =IFERROR(SUMPRODUCT((nCUENTA=1)*(nASIG=B16)*(nNOTA))/D16,"—") -> — | F16: {=IFERROR(_xlfn.STDEV.P(_xlfn._xlws.FILTER(nNOTA,(nCUENTA=1)*(nASIG=B16))),"—")} -> — | G16: {=IFERROR(_xlfn.MODE.SNGL(_xlfn._xlws.FILTER(nNOTA,(nCUENTA=1)*(nASIG=B16))),"—")} -> — | H16: =IFERROR(SUMPRODUCT((nCUENTA=1)*(nASIG=B16)*(nAPTO="S"))/D16,"—") -> — | I16: =IFERROR(SUMPRODUCT((nCUENTA=1)*(nASIG=B16)*(nAPTO="N"))/D16,"—") -> — | J16: {=IFERROR(_xlfn.MODE.SNGL(_xlfn._xlws.FILTER(nNOTA,(nCUENTA=1)*(nASIG=B16)*(nAPTO="S"))),"—")} -> — | K16: {=IFERROR(_xlfn.MODE.SNGL(_xlfn._xlws.FILTER(nNOTA,(nCUENTA=1)*(nASIG=B16)*(nAPTO="N"))),"—")} -> — | L16: =SUMPRODUCT((nCUENTA=1)*(nASIG=B16)*(nNOTA=1)) -> 0 | M16: =SUMPRODUCT((nCUENTA=1)*(nASIG=B16)*(nNOTA=2)) -> 0 | N16: =SUMPRODUCT((nCUENTA=1)*(nASIG=B16)*(nNOTA=3)) -> 0 | O16: =SUMPRODUCT((nCUENTA=1)*(nASIG=B16)*(nNOTA=4)) -> 0 | P16: =SUMPRODUCT((nCUENTA=1)*(nASIG=B16)*(nNOTA=5)) -> 0 | Q16: =SUMPRODUCT((nCUENTA=1)*(nASIG=B16)*(nNOTA=6)) -> 0 | R16: =SUMPRODUCT((nCUENTA=1)*(nASIG=B16)*(nNOTA=7)) -> 0 | S16: =SUMPRODUCT((nCUENTA=1)*(nASIG=B16)*(nNOTA=8)) -> 0 | T16: =SUMPRODUCT((nCUENTA=1)*(nASIG=B16)*(nNOTA=9)) -> 0 | U16: =SUMPRODUCT((nCUENTA=1)*(nASIG=B16)*(nNOTA=10)) -> 0
A17: GLOBAL | B17: {=IFERROR(INDEX(_xlfn._xlws.FILTER(CONFIG_ASIGNATURAS!$B$2:$B$91,CONFIG_ASIGNATURAS!$G$2:$G$91="Sí"),12),"")} | C17: =IF(B17="","",IFERROR(VLOOKUP(B17,CONFIG_ASIGNATURAS!$B$2:$D$91,3,FALSE()),"Asignatura")) | D17: =SUMPRODUCT((nCUENTA=1)*(nASIG=B17)) -> 0 | E17: =IFERROR(SUMPRODUCT((nCUENTA=1)*(nASIG=B17)*(nNOTA))/D17,"—") -> — | F17: {=IFERROR(_xlfn.STDEV.P(_xlfn._xlws.FILTER(nNOTA,(nCUENTA=1)*(nASIG=B17))),"—")} -> — | G17: {=IFERROR(_xlfn.MODE.SNGL(_xlfn._xlws.FILTER(nNOTA,(nCUENTA=1)*(nASIG=B17))),"—")} -> — | H17: =IFERROR(SUMPRODUCT((nCUENTA=1)*(nASIG=B17)*(nAPTO="S"))/D17,"—") -> — | I17: =IFERROR(SUMPRODUCT((nCUENTA=1)*(nASIG=B17)*(nAPTO="N"))/D17,"—") -> — | J17: {=IFERROR(_xlfn.MODE.SNGL(_xlfn._xlws.FILTER(nNOTA,(nCUENTA=1)*(nASIG=B17)*(nAPTO="S"))),"—")} -> — | K17: {=IFERROR(_xlfn.MODE.SNGL(_xlfn._xlws.FILTER(nNOTA,(nCUENTA=1)*(nASIG=B17)*(nAPTO="N"))),"—")} -> — | L17: =SUMPRODUCT((nCUENTA=1)*(nASIG=B17)*(nNOTA=1)) -> 0 | M17: =SUMPRODUCT((nCUENTA=1)*(nASIG=B17)*(nNOTA=2)) -> 0 | N17: =SUMPRODUCT((nCUENTA=1)*(nASIG=B17)*(nNOTA=3)) -> 0 | O17: =SUMPRODUCT((nCUENTA=1)*(nASIG=B17)*(nNOTA=4)) -> 0 | P17: =SUMPRODUCT((nCUENTA=1)*(nASIG=B17)*(nNOTA=5)) -> 0 | Q17: =SUMPRODUCT((nCUENTA=1)*(nASIG=B17)*(nNOTA=6)) -> 0 | R17: =SUMPRODUCT((nCUENTA=1)*(nASIG=B17)*(nNOTA=7)) -> 0 | S17: =SUMPRODUCT((nCUENTA=1)*(nASIG=B17)*(nNOTA=8)) -> 0 | T17: =SUMPRODUCT((nCUENTA=1)*(nASIG=B17)*(nNOTA=9)) -> 0 | U17: =SUMPRODUCT((nCUENTA=1)*(nASIG=B17)*(nNOTA=10)) -> 0
A18: GLOBAL | B18: {=IFERROR(INDEX(_xlfn._xlws.FILTER(CONFIG_ASIGNATURAS!$B$2:$B$91,CONFIG_ASIGNATURAS!$G$2:$G$91="Sí"),13),"")} | C18: =IF(B18="","",IFERROR(VLOOKUP(B18,CONFIG_ASIGNATURAS!$B$2:$D$91,3,FALSE()),"Asignatura")) | D18: =SUMPRODUCT((nCUENTA=1)*(nASIG=B18)) -> 0 | E18: =IFERROR(SUMPRODUCT((nCUENTA=1)*(nASIG=B18)*(nNOTA))/D18,"—") -> — | F18: {=IFERROR(_xlfn.STDEV.P(_xlfn._xlws.FILTER(nNOTA,(nCUENTA=1)*(nASIG=B18))),"—")} -> — | G18: {=IFERROR(_xlfn.MODE.SNGL(_xlfn._xlws.FILTER(nNOTA,(nCUENTA=1)*(nASIG=B18))),"—")} -> — | H18: =IFERROR(SUMPRODUCT((nCUENTA=1)*(nASIG=B18)*(nAPTO="S"))/D18,"—") -> — | I18: =IFERROR(SUMPRODUCT((nCUENTA=1)*(nASIG=B18)*(nAPTO="N"))/D18,"—") -> — | J18: {=IFERROR(_xlfn.MODE.SNGL(_xlfn._xlws.FILTER(nNOTA,(nCUENTA=1)*(nASIG=B18)*(nAPTO="S"))),"—")} -> — | K18: {=IFERROR(_xlfn.MODE.SNGL(_xlfn._xlws.FILTER(nNOTA,(nCUENTA=1)*(nASIG=B18)*(nAPTO="N"))),"—")} -> — | L18: =SUMPRODUCT((nCUENTA=1)*(nASIG=B18)*(nNOTA=1)) -> 0 | M18: =SUMPRODUCT((nCUENTA=1)*(nASIG=B18)*(nNOTA=2)) -> 0 | N18: =SUMPRODUCT((nCUENTA=1)*(nASIG=B18)*(nNOTA=3)) -> 0 | O18: =SUMPRODUCT((nCUENTA=1)*(nASIG=B18)*(nNOTA=4)) -> 0 | P18: =SUMPRODUCT((nCUENTA=1)*(nASIG=B18)*(nNOTA=5)) -> 0 | Q18: =SUMPRODUCT((nCUENTA=1)*(nASIG=B18)*(nNOTA=6)) -> 0 | R18: =SUMPRODUCT((nCUENTA=1)*(nASIG=B18)*(nNOTA=7)) -> 0 | S18: =SUMPRODUCT((nCUENTA=1)*(nASIG=B18)*(nNOTA=8)) -> 0 | T18: =SUMPRODUCT((nCUENTA=1)*(nASIG=B18)*(nNOTA=9)) -> 0 | U18: =SUMPRODUCT((nCUENTA=1)*(nASIG=B18)*(nNOTA=10)) -> 0
A19: GLOBAL | B19: {=IFERROR(INDEX(_xlfn._xlws.FILTER(CONFIG_ASIGNATURAS!$B$2:$B$91,CONFIG_ASIGNATURAS!$G$2:$G$91="Sí"),14),"")} | C19: =IF(B19="","",IFERROR(VLOOKUP(B19,CONFIG_ASIGNATURAS!$B$2:$D$91,3,FALSE()),"Asignatura")) | D19: =SUMPRODUCT((nCUENTA=1)*(nASIG=B19)) -> 0 | E19: =IFERROR(SUMPRODUCT((nCUENTA=1)*(nASIG=B19)*(nNOTA))/D19,"—") -> — | F19: {=IFERROR(_xlfn.STDEV.P(_xlfn._xlws.FILTER(nNOTA,(nCUENTA=1)*(nASIG=B19))),"—")} -> — | G19: {=IFERROR(_xlfn.MODE.SNGL(_xlfn._xlws.FILTER(nNOTA,(nCUENTA=1)*(nASIG=B19))),"—")} -> — | H19: =IFERROR(SUMPRODUCT((nCUENTA=1)*(nASIG=B19)*(nAPTO="S"))/D19,"—") -> — | I19: =IFERROR(SUMPRODUCT((nCUENTA=1)*(nASIG=B19)*(nAPTO="N"))/D19,"—") -> — | J19: {=IFERROR(_xlfn.MODE.SNGL(_xlfn._xlws.FILTER(nNOTA,(nCUENTA=1)*(nASIG=B19)*(nAPTO="S"))),"—")} -> — | K19: {=IFERROR(_xlfn.MODE.SNGL(_xlfn._xlws.FILTER(nNOTA,(nCUENTA=1)*(nASIG=B19)*(nAPTO="N"))),"—")} -> — | L19: =SUMPRODUCT((nCUENTA=1)*(nASIG=B19)*(nNOTA=1)) -> 0 | M19: =SUMPRODUCT((nCUENTA=1)*(nASIG=B19)*(nNOTA=2)) -> 0 | N19: =SUMPRODUCT((nCUENTA=1)*(nASIG=B19)*(nNOTA=3)) -> 0 | O19: =SUMPRODUCT((nCUENTA=1)*(nASIG=B19)*(nNOTA=4)) -> 0 | P19: =SUMPRODUCT((nCUENTA=1)*(nASIG=B19)*(nNOTA=5)) -> 0 | Q19: =SUMPRODUCT((nCUENTA=1)*(nASIG=B19)*(nNOTA=6)) -> 0 | R19: =SUMPRODUCT((nCUENTA=1)*(nASIG=B19)*(nNOTA=7)) -> 0 | S19: =SUMPRODUCT((nCUENTA=1)*(nASIG=B19)*(nNOTA=8)) -> 0 | T19: =SUMPRODUCT((nCUENTA=1)*(nASIG=B19)*(nNOTA=9)) -> 0 | U19: =SUMPRODUCT((nCUENTA=1)*(nASIG=B19)*(nNOTA=10)) -> 0
A20: GLOBAL | B20: {=IFERROR(INDEX(_xlfn._xlws.FILTER(CONFIG_ASIGNATURAS!$B$2:$B$91,CONFIG_ASIGNATURAS!$G$2:$G$91="Sí"),15),"")} | C20: =IF(B20="","",IFERROR(VLOOKUP(B20,CONFIG_ASIGNATURAS!$B$2:$D$91,3,FALSE()),"Asignatura")) | D20: =SUMPRODUCT((nCUENTA=1)*(nASIG=B20)) -> 0 | E20: =IFERROR(SUMPRODUCT((nCUENTA=1)*(nASIG=B20)*(nNOTA))/D20,"—") -> — | F20: {=IFERROR(_xlfn.STDEV.P(_xlfn._xlws.FILTER(nNOTA,(nCUENTA=1)*(nASIG=B20))),"—")} -> — | G20: {=IFERROR(_xlfn.MODE.SNGL(_xlfn._xlws.FILTER(nNOTA,(nCUENTA=1)*(nASIG=B20))),"—")} -> — | H20: =IFERROR(SUMPRODUCT((nCUENTA=1)*(nASIG=B20)*(nAPTO="S"))/D20,"—") -> — | I20: =IFERROR(SUMPRODUCT((nCUENTA=1)*(nASIG=B20)*(nAPTO="N"))/D20,"—") -> — | J20: {=IFERROR(_xlfn.MODE.SNGL(_xlfn._xlws.FILTER(nNOTA,(nCUENTA=1)*(nASIG=B20)*(nAPTO="S"))),"—")} -> — | K20: {=IFERROR(_xlfn.MODE.SNGL(_xlfn._xlws.FILTER(nNOTA,(nCUENTA=1)*(nASIG=B20)*(nAPTO="N"))),"—")} -> — | L20: =SUMPRODUCT((nCUENTA=1)*(nASIG=B20)*(nNOTA=1)) -> 0 | M20: =SUMPRODUCT((nCUENTA=1)*(nASIG=B20)*(nNOTA=2)) -> 0 | N20: =SUMPRODUCT((nCUENTA=1)*(nASIG=B20)*(nNOTA=3)) -> 0 | O20: =SUMPRODUCT((nCUENTA=1)*(nASIG=B20)*(nNOTA=4)) -> 0 | P20: =SUMPRODUCT((nCUENTA=1)*(nASIG=B20)*(nNOTA=5)) -> 0 | Q20: =SUMPRODUCT((nCUENTA=1)*(nASIG=B20)*(nNOTA=6)) -> 0 | R20: =SUMPRODUCT((nCUENTA=1)*(nASIG=B20)*(nNOTA=7)) -> 0 | S20: =SUMPRODUCT((nCUENTA=1)*(nASIG=B20)*(nNOTA=8)) -> 0 | T20: =SUMPRODUCT((nCUENTA=1)*(nASIG=B20)*(nNOTA=9)) -> 0 | U20: =SUMPRODUCT((nCUENTA=1)*(nASIG=B20)*(nNOTA=10)) -> 0
A21: GLOBAL | B21: {=IFERROR(INDEX(_xlfn._xlws.FILTER(CONFIG_ASIGNATURAS!$B$2:$B$91,CONFIG_ASIGNATURAS!$G$2:$G$91="Sí"),16),"")} | C21: =IF(B21="","",IFERROR(VLOOKUP(B21,CONFIG_ASIGNATURAS!$B$2:$D$91,3,FALSE()),"Asignatura")) | D21: =SUMPRODUCT((nCUENTA=1)*(nASIG=B21)) -> 0 | E21: =IFERROR(SUMPRODUCT((nCUENTA=1)*(nASIG=B21)*(nNOTA))/D21,"—") -> — | F21: {=IFERROR(_xlfn.STDEV.P(_xlfn._xlws.FILTER(nNOTA,(nCUENTA=1)*(nASIG=B21))),"—")} -> — | G21: {=IFERROR(_xlfn.MODE.SNGL(_xlfn._xlws.FILTER(nNOTA,(nCUENTA=1)*(nASIG=B21))),"—")} -> — | H21: =IFERROR(SUMPRODUCT((nCUENTA=1)*(nASIG=B21)*(nAPTO="S"))/D21,"—") -> — | I21: =IFERROR(SUMPRODUCT((nCUENTA=1)*(nASIG=B21)*(nAPTO="N"))/D21,"—") -> — | J21: {=IFERROR(_xlfn.MODE.SNGL(_xlfn._xlws.FILTER(nNOTA,(nCUENTA=1)*(nASIG=B21)*(nAPTO="S"))),"—")} -> — | K21: {=IFERROR(_xlfn.MODE.SNGL(_xlfn._xlws.FILTER(nNOTA,(nCUENTA=1)*(nASIG=B21)*(nAPTO="N"))),"—")} -> — | L21: =SUMPRODUCT((nCUENTA=1)*(nASIG=B21)*(nNOTA=1)) -> 0 | M21: =SUMPRODUCT((nCUENTA=1)*(nASIG=B21)*(nNOTA=2)) -> 0 | N21: =SUMPRODUCT((nCUENTA=1)*(nASIG=B21)*(nNOTA=3)) -> 0 | O21: =SUMPRODUCT((nCUENTA=1)*(nASIG=B21)*(nNOTA=4)) -> 0 | P21: =SUMPRODUCT((nCUENTA=1)*(nASIG=B21)*(nNOTA=5)) -> 0 | Q21: =SUMPRODUCT((nCUENTA=1)*(nASIG=B21)*(nNOTA=6)) -> 0 | R21: =SUMPRODUCT((nCUENTA=1)*(nASIG=B21)*(nNOTA=7)) -> 0 | S21: =SUMPRODUCT((nCUENTA=1)*(nASIG=B21)*(nNOTA=8)) -> 0 | T21: =SUMPRODUCT((nCUENTA=1)*(nASIG=B21)*(nNOTA=9)) -> 0 | U21: =SUMPRODUCT((nCUENTA=1)*(nASIG=B21)*(nNOTA=10)) -> 0
A22: GLOBAL | B22: {=IFERROR(INDEX(_xlfn._xlws.FILTER(CONFIG_ASIGNATURAS!$B$2:$B$91,CONFIG_ASIGNATURAS!$G$2:$G$91="Sí"),17),"")} | C22: =IF(B22="","",IFERROR(VLOOKUP(B22,CONFIG_ASIGNATURAS!$B$2:$D$91,3,FALSE()),"Asignatura")) | D22: =SUMPRODUCT((nCUENTA=1)*(nASIG=B22)) -> 0 | E22: =IFERROR(SUMPRODUCT((nCUENTA=1)*(nASIG=B22)*(nNOTA))/D22,"—") -> — | F22: {=IFERROR(_xlfn.STDEV.P(_xlfn._xlws.FILTER(nNOTA,(nCUENTA=1)*(nASIG=B22))),"—")} -> — | G22: {=IFERROR(_xlfn.MODE.SNGL(_xlfn._xlws.FILTER(nNOTA,(nCUENTA=1)*(nASIG=B22))),"—")} -> — | H22: =IFERROR(SUMPRODUCT((nCUENTA=1)*(nASIG=B22)*(nAPTO="S"))/D22,"—") -> — | I22: =IFERROR(SUMPRODUCT((nCUENTA=1)*(nASIG=B22)*(nAPTO="N"))/D22,"—") -> — | J22: {=IFERROR(_xlfn.MODE.SNGL(_xlfn._xlws.FILTER(nNOTA,(nCUENTA=1)*(nASIG=B22)*(nAPTO="S"))),"—")} -> — | K22: {=IFERROR(_xlfn.MODE.SNGL(_xlfn._xlws.FILTER(nNOTA,(nCUENTA=1)*(nASIG=B22)*(nAPTO="N"))),"—")} -> — | L22: =SUMPRODUCT((nCUENTA=1)*(nASIG=B22)*(nNOTA=1)) -> 0 | M22: =SUMPRODUCT((nCUENTA=1)*(nASIG=B22)*(nNOTA=2)) -> 0 | N22: =SUMPRODUCT((nCUENTA=1)*(nASIG=B22)*(nNOTA=3)) -> 0 | O22: =SUMPRODUCT((nCUENTA=1)*(nASIG=B22)*(nNOTA=4)) -> 0 | P22: =SUMPRODUCT((nCUENTA=1)*(nASIG=B22)*(nNOTA=5)) -> 0 | Q22: =SUMPRODUCT((nCUENTA=1)*(nASIG=B22)*(nNOTA=6)) -> 0 | R22: =SUMPRODUCT((nCUENTA=1)*(nASIG=B22)*(nNOTA=7)) -> 0 | S22: =SUMPRODUCT((nCUENTA=1)*(nASIG=B22)*(nNOTA=8)) -> 0 | T22: =SUMPRODUCT((nCUENTA=1)*(nASIG=B22)*(nNOTA=9)) -> 0 | U22: =SUMPRODUCT((nCUENTA=1)*(nASIG=B22)*(nNOTA=10)) -> 0
A23: GLOBAL | B23: {=IFERROR(INDEX(_xlfn._xlws.FILTER(CONFIG_ASIGNATURAS!$B$2:$B$91,CONFIG_ASIGNATURAS!$G$2:$G$91="Sí"),18),"")} | C23: =IF(B23="","",IFERROR(VLOOKUP(B23,CONFIG_ASIGNATURAS!$B$2:$D$91,3,FALSE()),"Asignatura")) | D23: =SUMPRODUCT((nCUENTA=1)*(nASIG=B23)) -> 0 | E23: =IFERROR(SUMPRODUCT((nCUENTA=1)*(nASIG=B23)*(nNOTA))/D23,"—") -> — | F23: {=IFERROR(_xlfn.STDEV.P(_xlfn._xlws.FILTER(nNOTA,(nCUENTA=1)*(nASIG=B23))),"—")} -> — | G23: {=IFERROR(_xlfn.MODE.SNGL(_xlfn._xlws.FILTER(nNOTA,(nCUENTA=1)*(nASIG=B23))),"—")} -> — | H23: =IFERROR(SUMPRODUCT((nCUENTA=1)*(nASIG=B23)*(nAPTO="S"))/D23,"—") -> — | I23: =IFERROR(SUMPRODUCT((nCUENTA=1)*(nASIG=B23)*(nAPTO="N"))/D23,"—") -> — | J23: {=IFERROR(_xlfn.MODE.SNGL(_xlfn._xlws.FILTER(nNOTA,(nCUENTA=1)*(nASIG=B23)*(nAPTO="S"))),"—")} -> — | K23: {=IFERROR(_xlfn.MODE.SNGL(_xlfn._xlws.FILTER(nNOTA,(nCUENTA=1)*(nASIG=B23)*(nAPTO="N"))),"—")} -> — | L23: =SUMPRODUCT((nCUENTA=1)*(nASIG=B23)*(nNOTA=1)) -> 0 | M23: =SUMPRODUCT((nCUENTA=1)*(nASIG=B23)*(nNOTA=2)) -> 0 | N23: =SUMPRODUCT((nCUENTA=1)*(nASIG=B23)*(nNOTA=3)) -> 0 | O23: =SUMPRODUCT((nCUENTA=1)*(nASIG=B23)*(nNOTA=4)) -> 0 | P23: =SUMPRODUCT((nCUENTA=1)*(nASIG=B23)*(nNOTA=5)) -> 0 | Q23: =SUMPRODUCT((nCUENTA=1)*(nASIG=B23)*(nNOTA=6)) -> 0 | R23: =SUMPRODUCT((nCUENTA=1)*(nASIG=B23)*(nNOTA=7)) -> 0 | S23: =SUMPRODUCT((nCUENTA=1)*(nASIG=B23)*(nNOTA=8)) -> 0 | T23: =SUMPRODUCT((nCUENTA=1)*(nASIG=B23)*(nNOTA=9)) -> 0 | U23: =SUMPRODUCT((nCUENTA=1)*(nASIG=B23)*(nNOTA=10)) -> 0
