Workbook
Name cASIG: CATALOGO!$A$2:$A$201
Name cESP: CATALOGO!$C$2:$C$201
Name cETAPA: CATALOGO!$B$2:$B$201
Name eANO: INDEX(eBLOQUE,0,_xlfn.XMATCH("anoacademico_id",ENTRADA!$A$1:$AZ$1))
Name eAPRUEBA: INDEX(eBLOQUE,0,_xlfn.XMATCH("aprueba",ENTRADA!$A$1:$AZ$1))
Name eASIG: INDEX(eBLOQUE,0,_xlfn.XMATCH("co_desc",ENTRADA!$A$1:$AZ$1))
Name eBLOQUE: ENTRADA!$A$2:INDEX(ENTRADA!$AZ:$AZ,MAX(2,CONTROL!$B$4))
Name eCENTRO: INDEX(eBLOQUE,0,_xlfn.XMATCH("denominacionespecifica",ENTRADA!$A$1:$AZ$1))
Name eCODIGO: INDEX(eBLOQUE,0,_xlfn.XMATCH("co_codigo",ENTRADA!$A$1:$AZ$1))
Name eCURSO: INDEX(eBLOQUE,0,_xlfn.XMATCH("curso_cont",ENTRADA!$A$1:$AZ$1))
Name eCURSOMAT: INDEX(eBLOQUE,0,_xlfn.XMATCH("curso_mat",ENTRADA!$A$1:$AZ$1))
Name eEVAL: INDEX(eBLOQUE,0,_xlfn.XMATCH("ev_codigo",ENTRADA!$A$1:$AZ$1))
Name eNIA: INDEX(eBLOQUE,0,_xlfn.XMATCH("nia",ENTRADA!$A$1:$AZ$1))
Name eNOTA: INDEX(eBLOQUE,0,_xlfn.XMATCH("nota",ENTRADA!$A$1:$AZ$1))
Name ePROMOCIONA: INDEX(eBLOQUE,0,_xlfn.XMATCH("promociona",ENTRADA!$A$1:$AZ$1))
Name eTIPO: INDEX(eBLOQUE,0,_xlfn.XMATCH("co_tipobasico",ENTRADA!$A$1:$AZ$1))
Name eULTIMA: CONTROL!$B$4

Sheet PORTADA
A1: Conversor Excel a Dashboard
A2: De la exportación de calificaciones de fin de curso a la hoja DATOS de los dos analizadores.
A3: Necesita Excel 365 o Excel 2021 o posterior, igual que los analizadores. En Excel 2019 o anterior las fórmulas salen como #¿NOMBRE?.
A5: 1 · Pega la exportación en ENTRADA
A6: Entera, desde la celda A1, con su fila de cabeceras. Si había algo de otra vez, bórralo antes.
A7: Las columnas se buscan por el nombre de su cabecera: da igual en qué orden vengan.
A9: 2 · Mira CONTROL antes de seguir
A10: Dice cuántas filas pasan a cada etapa, cuántas se descartan y por qué, y qué asignaturas no están en el catálogo. Si «Columnas que faltan» no dice «Ninguna», para aquí.
A12: 3 · Copia DATOS_EEM y DATOS_EPM en sus analizadores
A13: Selecciona la hoja desde A1 hasta la última fila, copia, y en la hoja DATOS del analizador pega SOLO LOS VALORES desde A1.
A14: Elementales: DATOS_EEM, y en CONFIG_METADATA elige la evaluación FI.
A15: Profesionales: DATOS_EPM, y elige OR+EX: la ordinaria con las recuperaciones de la extraordinaria encima. Es la foto definitiva del curso.
... A35: José Luis Miralles Bono · www.jlmirall.es · Desarrollado con Claude (Anthropic)

Sheet ENTRADA
A1: anoacademico_id | B1: codcentro | C1: denominacionespecifica | D1: codensenanza | E1: curso_mat | F1: curso_cont | G1: nombre | H1: apellido1 | I1: apellido2 | J1: nia | K1: sexo | L1: ev_codigo | M1: ev_abrv | N1: ev_desc | O1: ev_orden | P1: ev_obligatoria | Q1: ev_para_fct_proyecto | R1: co_codigo | S1: co_desc | T1: co_estutoria | U1: co_esproyecto | V1: co_caracter | W1: co_tipobasico | X1: co_singularidad | Y1: nota | Z1: aprueba | AA1: promociona

Sheet CATALOGO
A1: Asignatura | B1: Etapa | C1: EsEspecialidad | E1: CÓMO SE USA
A2: Lenguaje Musical | B2: EEM | C2: No | E2: Es el mismo catálogo que CONFIG_ASIGNATURAS de los dos analizadores, con su etapa.
A3: Coro | B3: EEM | C3: No | E3: Sirve para dos cosas: escribir cada asignatura con el nombre del analizador, y saber
A4: Conjunto | B4: EEM | C4: No | E4: qué asignatura es la especialidad de cada alumno.
A5: Acordeón | B5: EEM | C5: Sí | E5: Una asignatura nueva: en la primera fila libre, con el MISMO nombre que en el analizador,
A6: Arpa | B6: EEM | C6: Sí | E6: su etapa (EEM o EPM) y «Sí» si es un instrumento. No hace falta ordenar nada.
A7: Clarinete | B7: EEM | C7: Sí
A8: Clave | B8: EEM | C8: Sí
A9: Contrabajo | B9: EEM | C9: Sí
A10: Dulzaina | B10: EEM | C10: Sí
A11: Fagot | B11: EEM | C11: Sí
A12: Flauta Travesera | B12: EEM | C12: Sí
A13: Flauta de Pico | B13: EEM | C13: Sí
A14: Guitarra | B14: EEM | C14: Sí
A15: Instrumentos de Púa | B15: EEM | C15: Sí
A16: Oboe | B16: EEM | C16: Sí
A17: Percusión | B17: EEM | C17: Sí
A18: Piano | B18: EEM | C18: Sí
... A69: Improvisación y Jazz | B69: EPM | C69: No
A70: ↓ primera fila libre

Sheet DATOS_EEM
A1: NIA | B1: Apellidos | C1: Nombre | D1: Curso | E1: Especialidad | F1: Repite | G1: Evaluación | H1: Código Asig | I1: Contenido | J1: Nota | K1: Nota Numérica | L1: Apto | M1: Profesor | N1: Observ.
A2: {=IF(CONTROL!$B$4<2,"",_xlfn.LET(_xlpm.vEt,RIGHT(eCURSO,3),_xlpm.vAsig,TRIM(eASIG),_xlpm.vCanon,_xlfn.IFNA(_xlfn.XLOOKUP(_xlpm.vAsig&"|"&_xlpm.vEt,cASIG&"|"&cETAPA,cASIG),_xlpm.vAsig),_xlpm.vEsEsp,ISNUMBER(_xlfn.XMATCH(_xlpm.vAsig&"|"&_xlpm.vEt&"|Sí",cASIG&"|"&cETAPA&"|"&cESP)),_xlpm.vClave,eNIA&"|"&_xlpm.vEt,_xlpm.vTexto,TRIM(eNOTA&""),_xlpm.vNum,IF(_xlpm.vTexto="","",IFERROR(IF(ISNUMBER(SEARCH(",",_xlpm.vTexto)),_xlfn.NUMBERVALUE(_xlpm.vTexto,","),_xlfn.NUMBERVALUE(_xlpm.vTexto,".")),"?")),_xlpm.vInstr,IF(_xlpm.vEsEsp,_xlpm.vCanon,_xlfn.XLOOKUP(_xlpm.vClave,_xlfn._xlws.FILTER(_xlpm.vClave,_xlpm.vEsEsp,"~"),_xlfn._xlws.FILTER(_xlpm.vCanon,_xlpm.vEsEsp,""),"")),_xlpm.vId,_xlfn.XMATCH(eNIA&"",_xlfn.UNIQUE(eNIA&"")),_xlpm.vApto,IF(TRIM(eAPRUEBA&"")="",IF(_xlpm.vNum>=5,"S","N"),IF(TRIM(eAPRUEBA&"")="1","S","N")),_xlpm.vTabla,CHOOSE({1,2,3,4,5,6,7,8,9,10,11,12,13,14},_xlpm.vId,"","",eCURSO,_xlpm.vInstr,"",eEVAL,eCODIGO&"",_xlpm.vCanon,_xlpm.vNum,_xlpm.vNum,_xlpm.vApto,"",""),_xlfn._xlws.FILTER(_xlpm.vTabla,(_xlpm.vEt="EEM")*(_xlpm.vTexto<>"")*ISNUMBER(_xlpm.vNum),"")))}

Sheet DATOS_EPM
A1: NIA | B1: Apellidos | C1: Nombre | D1: Curso | E1: Especialidad | F1: Repite | G1: Evaluación | H1: Código Asig | I1: Contenido | J1: Nota | K1: Nota Numérica | L1: Apto | M1: Profesor | N1: Observ.
A2: {=IF(CONTROL!$B$4<2,"",_xlfn.LET(_xlpm.vEt,RIGHT(eCURSO,3),_xlpm.vAsig,TRIM(eASIG),_xlpm.vCanon,_xlfn.IFNA(_xlfn.XLOOKUP(_xlpm.vAsig&"|"&_xlpm.vEt,cASIG&"|"&cETAPA,cASIG),_xlpm.vAsig),_xlpm.vEsEsp,ISNUMBER(_xlfn.XMATCH(_xlpm.vAsig&"|"&_xlpm.vEt&"|Sí",cASIG&"|"&cETAPA&"|"&cESP)),_xlpm.vClave,eNIA&"|"&_xlpm.vEt,_xlpm.vTexto,TRIM(eNOTA&""),_xlpm.vNum,IF(_xlpm.vTexto="","",IFERROR(IF(ISNUMBER(SEARCH(",",_xlpm.vTexto)),_xlfn.NUMBERVALUE(_xlpm.vTexto,","),_xlfn.NUMBERVALUE(_xlpm.vTexto,".")),"?")),_xlpm.vInstr,IF(_xlpm.vEsEsp,_xlpm.vCanon,_xlfn.XLOOKUP(_xlpm.vClave,_xlfn._xlws.FILTER(_xlpm.vClave,_xlpm.vEsEsp,"~"),_xlfn._xlws.FILTER(_xlpm.vCanon,_xlpm.vEsEsp,""),"")),_xlpm.vId,_xlfn.XMATCH(eNIA&"",_xlfn.UNIQUE(eNIA&"")),_xlpm.vApto,IF(TRIM(eAPRUEBA&"")="",IF(_xlpm.vNum>=5,"S","N"),IF(TRIM(eAPRUEBA&"")="1","S","N")),_xlpm.vTabla,CHOOSE({1,2,3,4,5,6,7,8,9,10,11,12,13,14},_xlpm.vId,"","",eCURSO,_xlpm.vInstr,"",eEVAL,eCODIGO&"",_xlpm.vCanon,_xlpm.vNum,_xlpm.vNum,_xlpm.vApto,"",""),_xlfn._xlws.FILTER(_xlpm.vTabla,(_xlpm.vEt="EPM")*(_xlpm.vTexto<>"")*ISNUMBER(_xlpm.vNum),"")))}

Sheet CONTROL
A1: Comprobación | B1: Resultado | C1: Qué significa
A2: Mira esto antes de copiar DATOS_EEM y DATOS_EPM.
A3: Columnas que faltan en ENTRADA | B3: {=_xlfn.LET(_xlpm.vC,{"nia","curso_mat","curso_cont","ev_codigo","co_codigo","co_desc","co_tipobasico","nota","aprueba"},_xlpm.vL,_xlfn.TEXTJOIN(", ",TRUE,IF(ISNA(_xlfn.XMATCH(_xlpm.vC,ENTRADA!$A$1:$AZ$1)),_xlpm.vC,"")),IF(_xlpm.vL="","Ninguna",_xlpm.vL))} | C3: Si falta alguna, el resto de la hoja no vale: la exportación no tiene la forma esperada.
A4: Última fila con datos | B4: {=IFERROR(LOOKUP(2,1/(INDEX(ENTRADA!$A$1:$AZ$30000,0,_xlfn.XMATCH("nia",ENTRADA!$A$1:$AZ$1))<>""),ROW(ENTRADA!$A$1:$A$30000)),1)} | C4: Hasta dónde miran las fórmulas. Se decide por la columna nia.
A5: Filas pegadas | B5: {=MAX(0,CONTROL!$B$4-1)}
A6: Filas de elemental | B6: {=IF(CONTROL!$B$4<2,0,_xlfn.LET(_xlpm.vEt,RIGHT(eCURSO,3),_xlpm.vAsig,TRIM(eASIG),_xlpm.vCanon,_xlfn.IFNA(_xlfn.XLOOKUP(_xlpm.vAsig&"|"&_xlpm.vEt,cASIG&"|"&cETAPA,cASIG),_xlpm.vAsig),_xlpm.vEsEsp,ISNUMBER(_xlfn.XMATCH(_xlpm.vAsig&"|"&_xlpm.vEt&"|Sí",cASIG&"|"&cETAPA&"|"&cESP)),_xlpm.vClave,eNIA&"|"&_xlpm.vEt,_xlpm.vTexto,TRIM(eNOTA&""),_xlpm.vNum,IF(_xlpm.vTexto="","",IFERROR(IF(ISNUMBER(SEARCH(",",_xlpm.vTexto)),_xlfn.NUMBERVALUE(_xlpm.vTexto,","),_xlfn.NUMBERVALUE(_xlpm.vTexto,".")),"?")),SUM(--(_xlpm.vEt="EEM"))))} | C6: Por el curso de la asignatura.
A7: Filas de profesional | B7: {=IF(CONTROL!$B$4<2,0,_xlfn.LET(_xlpm.vEt,RIGHT(eCURSO,3),_xlpm.vAsig,TRIM(eASIG),_xlpm.vCanon,_xlfn.IFNA(_xlfn.XLOOKUP(_xlpm.vAsig&"|"&_xlpm.vEt,cASIG&"|"&cETAPA,cASIG),_xlpm.vAsig),_xlpm.vEsEsp,ISNUMBER(_xlfn.XMATCH(_xlpm.vAsig&"|"&_xlpm.vEt&"|Sí",cASIG&"|"&cETAPA&"|"&cESP)),_xlpm.vClave,eNIA&"|"&_xlpm.vEt,_xlpm.vTexto,TRIM(eNOTA&""),_xlpm.vNum,IF(_xlpm.vTexto="","",IFERROR(IF(ISNUMBER(SEARCH(",",_xlpm.vTexto)),_xlfn.NUMBERVALUE(_xlpm.vTexto,","),_xlfn.NUMBERVALUE(_xlpm.vTexto,".")),"?")),SUM(--(_xlpm.vEt="EPM"))))}
A8: Filas con un curso que no es de ninguna etapa | B8: {=IF(CONTROL!$B$4<2,0,_xlfn.LET(_xlpm.vEt,RIGHT(eCURSO,3),_xlpm.vAsig,TRIM(eASIG),_xlpm.vCanon,_xlfn.IFNA(_xlfn.XLOOKUP(_xlpm.vAsig&"|"&_xlpm.vEt,cASIG&"|"&cETAPA,cASIG),_xlpm.vAsig),_xlpm.vEsEsp,ISNUMBER(_xlfn.XMATCH(_xlpm.vAsig&"|"&_xlpm.vEt&"|Sí",cASIG&"|"&cETAPA&"|"&cESP)),_xlpm.vClave,eNIA&"|"&_xlpm.vEt,_xlpm.vTexto,TRIM(eNOTA&""),_xlpm.vNum,IF(_xlpm.vTexto="","",IFERROR(IF(ISNUMBER(SEARCH(",",_xlpm.vTexto)),_xlfn.NUMBERVALUE(_xlpm.vTexto,","),_xlfn.NUMBERVALUE(_xlpm.vTexto,".")),"?")),SUM((_xlpm.vEt<>"EEM")*(_xlpm.vEt<>"EPM"))))} | C8: No pasan a ninguna hoja. Si no es cero, algún curso viene escrito de otra forma.
A9: Filas sin nota, descartadas | B9: {=IF(CONTROL!$B$4<2,0,_xlfn.LET(_xlpm.vEt,RIGHT(eCURSO,3),_xlpm.vAsig,TRIM(eASIG),_xlpm.vCanon,_xlfn.IFNA(_xlfn.XLOOKUP(_xlpm.vAsig&"|"&_xlpm.vEt,cASIG&"|"&cETAPA,cASIG),_xlpm.vAsig),_xlpm.vEsEsp,ISNUMBER(_xlfn.XMATCH(_xlpm.vAsig&"|"&_xlpm.vEt&"|Sí",cASIG&"|"&cETAPA&"|"&cESP)),_xlpm.vClave,eNIA&"|"&_xlpm.vEt,_xlpm.vTexto,TRIM(eNOTA&""),_xlpm.vNum,IF(_xlpm.vTexto="","",IFERROR(IF(ISNUMBER(SEARCH(",",_xlpm.vTexto)),_xlfn.NUMBERVALUE(_xlpm.vTexto,","),_xlfn.NUMBERVALUE(_xlpm.vTexto,".")),"?")),SUM(--(_xlpm.vTexto=""))))} | C9: Casi todas son la extraordinaria de quien aprobó en la ordinaria: no se examinó.
A10: de ellas, de la extraordinaria | B10: {=IF(CONTROL!$B$4<2,0,_xlfn.LET(_xlpm.vEt,RIGHT(eCURSO,3),_xlpm.vAsig,TRIM(eASIG),_xlpm.vCanon,_xlfn.IFNA(_xlfn.XLOOKUP(_xlpm.vAsig&"|"&_xlpm.vEt,cASIG&"|"&cETAPA,cASIG),_xlpm.vAsig),_xlpm.vEsEsp,ISNUMBER(_xlfn.XMATCH(_xlpm.vAsig&"|"&_xlpm.vEt&"|Sí",cASIG&"|"&cETAPA&"|"&cESP)),_xlpm.vClave,eNIA&"|"&_xlpm.vEt,_xlpm.vTexto,TRIM(eNOTA&""),_xlpm.vNum,IF(_xlpm.vTexto="","",IFERROR(IF(ISNUMBER(SEARCH(",",_xlpm.vTexto)),_xlfn.NUMBERVALUE(_xlpm.vTexto,","),_xlfn.NUMBERVALUE(_xlpm.vTexto,".")),"?")),SUM((_xlpm.vTexto="")*(eEVAL="EX"))))}
A11: Filas con una nota que no es un número | B11: {=IF(CONTROL!$B$4<2,0,_xlfn.LET(_xlpm.vEt,RIGHT(eCURSO,3),_xlpm.vAsig,TRIM(eASIG),_xlpm.vCanon,_xlfn.IFNA(_xlfn.XLOOKUP(_xlpm.vAsig&"|"&_xlpm.vEt,cASIG&"|"&cETAPA,cASIG),_xlpm.vAsig),_xlpm.vEsEsp,ISNUMBER(_xlfn.XMATCH(_xlpm.vAsig&"|"&_xlpm.vEt&"|Sí",cASIG&"|"&cETAPA&"|"&cESP)),_xlpm.vClave,eNIA&"|"&_xlpm.vEt,_xlpm.vTexto,TRIM(eNOTA&""),_xlpm.vNum,IF(_xlpm.vTexto="","",IFERROR(IF(ISNUMBER(SEARCH(",",_xlpm.vTexto)),_xlfn.NUMBERVALUE(_xlpm.vTexto,","),_xlfn.NUMBERVALUE(_xlpm.vTexto,".")),"?")),SUM((_xlpm.vTexto<>"")*(_xlpm.vNum="?"))))} | C11: Tampoco pasan. Si no es cero, hay que ver qué traen.
A12: Filas que pasan a DATOS_EEM | B12: {=IF(CONTROL!$B$4<2,0,_xlfn.LET(_xlpm.vEt,RIGHT(eCURSO,3),_xlpm.vAsig,TRIM(eASIG),_xlpm.vCanon,_xlfn.IFNA(_xlfn.XLOOKUP(_xlpm.vAsig&"|"&_xlpm.vEt,cASIG&"|"&cETAPA,cASIG),_xlpm.vAsig),_xlpm.vEsEsp,ISNUMBER(_xlfn.XMATCH(_xlpm.vAsig&"|"&_xlpm.vEt&"|Sí",cASIG&"|"&cETAPA&"|"&cESP)),_xlpm.vClave,eNIA&"|"&_xlpm.vEt,_xlpm.vTexto,TRIM(eNOTA&""),_xlpm.vNum,IF(_xlpm.vTexto="","",IFERROR(IF(ISNUMBER(SEARCH(",",_xlpm.vTexto)),_xlfn.NUMBERVALUE(_xlpm.vTexto,","),_xlfn.NUMBERVALUE(_xlpm.vTexto,".")),"?")),SUM((_xlpm.vEt="EEM")*(_xlpm.vTexto<>"")*(_xlpm.vNum<>"?"))))} | C12: Se pegan en DATOS del analizador de Elementales. Evaluación: FI.
A13: Filas que pasan a DATOS_EPM | B13: {=IF(CONTROL!$B$4<2,0,_xlfn.LET(_xlpm.vEt,RIGHT(eCURSO,3),_xlpm.vAsig,TRIM(eASIG),_xlpm.vCanon,_xlfn.IFNA(_xlfn.XLOOKUP(_xlpm.vAsig&"|"&_xlpm.vEt,cASIG&"|"&cETAPA,cASIG),_xlpm.vAsig),_xlpm.vEsEsp,ISNUMBER(_xlfn.XMATCH(_xlpm.vAsig&"|"&_xlpm.vEt&"|Sí",cASIG&"|"&cETAPA&"|"&cESP)),_xlpm.vClave,eNIA&"|"&_xlpm.vEt,_xlpm.vTexto,TRIM(eNOTA&""),_xlpm.vNum,IF(_xlpm.vTexto="","",IFERROR(IF(ISNUMBER(SEARCH(",",_xlpm.vTexto)),_xlfn.NUMBERVALUE(_xlpm.vTexto,","),_xlfn.NUMBERVALUE(_xlpm.vTexto,".")),"?")),SUM((_xlpm.vEt="EPM")*(_xlpm.vTexto<>"")*(_xlpm.vNum<>"?"))))} | C13: Se pegan en DATOS del analizador de Profesionales. Evaluación: OR+EX.
A14: Evaluaciones en elemental | B14: {=IF(CONTROL!$B$4<2,"—",_xlfn.LET(_xlpm.vEt,RIGHT(eCURSO,3),_xlpm.vAsig,TRIM(eASIG),_xlpm.vCanon,_xlfn.IFNA(_xlfn.XLOOKUP(_xlpm.vAsig&"|"&_xlpm.vEt,cASIG&"|"&cETAPA,cASIG),_xlpm.vAsig),_xlpm.vEsEsp,ISNUMBER(_xlfn.XMATCH(_xlpm.vAsig&"|"&_xlpm.vEt&"|Sí",cASIG&"|"&cETAPA&"|"&cESP)),_xlpm.vClave,eNIA&"|"&_xlpm.vEt,_xlpm.vTexto,TRIM(eNOTA&""),_xlpm.vNum,IF(_xlpm.vTexto="","",IFERROR(IF(ISNUMBER(SEARCH(",",_xlpm.vTexto)),_xlfn.NUMBERVALUE(_xlpm.vTexto,","),_xlfn.NUMBERVALUE(_xlpm.vTexto,".")),"?")),_xlpm.vL,_xlfn.TEXTJOIN(" · ",TRUE,_xlfn.UNIQUE(_xlfn._xlws.FILTER(eEVAL&"",_xlpm.vEt="EEM",""))),IF(_xlpm.vL="","—",_xlpm.vL)))} | C14: Lo esperado es FI.
A15: Evaluaciones en profesional | B15: {=IF(CONTROL!$B$4<2,"—",_xlfn.LET(_xlpm.vEt,RIGHT(eCURSO,3),_xlpm.vAsig,TRIM(eASIG),_xlpm.vCanon,_xlfn.IFNA(_xlfn.XLOOKUP(_xlpm.vAsig&"|"&_xlpm.vEt,cASIG&"|"&cETAPA,cASIG),_xlpm.vAsig),_xlpm.vEsEsp,ISNUMBER(_xlfn.XMATCH(_xlpm.vAsig&"|"&_xlpm.vEt&"|Sí",cASIG&"|"&cETAPA&"|"&cESP)),_xlpm.vClave,eNIA&"|"&_xlpm.vEt,_xlpm.vTexto,TRIM(eNOTA&""),_xlpm.vNum,IF(_xlpm.vTexto="","",IFERROR(IF(ISNUMBER(SEARCH(",",_xlpm.vTexto)),_xlfn.NUMBERVALUE(_xlpm.vTexto,","),_xlfn.NUMBERVALUE(_xlpm.vTexto,".")),"?")),_xlpm.vL,_xlfn.TEXTJOIN(" · ",TRUE,_xlfn.UNIQUE(_xlfn._xlws.FILTER(eEVAL&"",_xlpm.vEt="EPM",""))),IF(_xlpm.vL="","—",_xlpm.vL)))} | C15: Lo esperado es OR y EX.
A16: Pendientes | B16: {=IF(CONTROL!$B$4<2,0,_xlfn.LET(_xlpm.vEt,RIGHT(eCURSO,3),_xlpm.vAsig,TRIM(eASIG),_xlpm.vCanon,_xlfn.IFNA(_xlfn.XLOOKUP(_xlpm.vAsig&"|"&_xlpm.vEt,cASIG&"|"&cETAPA,cASIG),_xlpm.vAsig),_xlpm.vEsEsp,ISNUMBER(_xlfn.XMATCH(_xlpm.vAsig&"|"&_xlpm.vEt&"|Sí",cASIG&"|"&cETAPA&"|"&cESP)),_xlpm.vClave,eNIA&"|"&_xlpm.vEt,_xlpm.vTexto,TRIM(eNOTA&""),_xlpm.vNum,IF(_xlpm.vTexto="","",IFERROR(IF(ISNUMBER(SEARCH(",",_xlpm.vTexto)),_xlfn.NUMBERVALUE(_xlpm.vTexto,","),_xlfn.NUMBERVALUE(_xlpm.vTexto,".")),"?")),SUM(--(TRIM(eTIPO&"")="Pendiente"))))} | C16: Cuentan en el curso de la asignatura, no en el de matrícula.
A17: Filas cuyo curso de matrícula es de otra etapa | B17: {=IF(CONTROL!$B$4<2,0,_xlfn.LET(_xlpm.vEt,RIGHT(eCURSO,3),_xlpm.vAsig,TRIM(eASIG),_xlpm.vCanon,_xlfn.IFNA(_xlfn.XLOOKUP(_xlpm.vAsig&"|"&_xlpm.vEt,cASIG&"|"&cETAPA,cASIG),_xlpm.vAsig),_xlpm.vEsEsp,ISNUMBER(_xlfn.XMATCH(_xlpm.vAsig&"|"&_xlpm.vEt&"|Sí",cASIG&"|"&cETAPA&"|"&cESP)),_xlpm.vClave,eNIA&"|"&_xlpm.vEt,_xlpm.vTexto,TRIM(eNOTA&""),_xlpm.vNum,IF(_xlpm.vTexto="","",IFERROR(IF(ISNUMBER(SEARCH(",",_xlpm.vTexto)),_xlfn.NUMBERVALUE(_xlpm.vTexto,","),_xlfn.NUMBERVALUE(_xlpm.vTexto,".")),"?")),SUM(--(RIGHT(eCURSOMAT,3)<>_xlpm.vEt))))} | C17: Cuentan en la etapa de la asignatura.
A18: Alumnado distinto | B18: {=IF(CONTROL!$B$4<2,0,_xlfn.LET(_xlpm.vEt,RIGHT(eCURSO,3),_xlpm.vAsig,TRIM(eASIG),_xlpm.vCanon,_xlfn.IFNA(_xlfn.XLOOKUP(_xlpm.vAsig&"|"&_xlpm.vEt,cASIG&"|"&cETAPA,cASIG),_xlpm.vAsig),_xlpm.vEsEsp,ISNUMBER(_xlfn.XMATCH(_xlpm.vAsig&"|"&_xlpm.vEt&"|Sí",cASIG&"|"&cETAPA&"|"&cESP)),_xlpm.vClave,eNIA&"|"&_xlpm.vEt,_xlpm.vTexto,TRIM(eNOTA&""),_xlpm.vNum,IF(_xlpm.vTexto="","",IFERROR(IF(ISNUMBER(SEARCH(",",_xlpm.vTexto)),_xlfn.NUMBERVALUE(_xlpm.vTexto,","),_xlfn.NUMBERVALUE(_xlpm.vTexto,".")),"?")),IFERROR(ROWS(_xlfn.UNIQUE(_xlfn._xlws.FILTER(eNIA&"",eNIA&""<>""))),0)))} | C18: En DATOS lleva un número correlativo en lugar del NIA.
A19: Alumnado con dos especialidades | B19: {=IF(CONTROL!$B$4<2,0,_xlfn.LET(_xlpm.vEt,RIGHT(eCURSO,3),_xlpm.vAsig,TRIM(eASIG),_xlpm.vCanon,_xlfn.IFNA(_xlfn.XLOOKUP(_xlpm.vAsig&"|"&_xlpm.vEt,cASIG&"|"&cETAPA,cASIG),_xlpm.vAsig),_xlpm.vEsEsp,ISNUMBER(_xlfn.XMATCH(_xlpm.vAsig&"|"&_xlpm.vEt&"|Sí",cASIG&"|"&cETAPA&"|"&cESP)),_xlpm.vClave,eNIA&"|"&_xlpm.vEt,_xlpm.vTexto,TRIM(eNOTA&""),_xlpm.vNum,IF(_xlpm.vTexto="","",IFERROR(IF(ISNUMBER(SEARCH(",",_xlpm.vTexto)),_xlfn.NUMBERVALUE(_xlpm.vTexto,","),_xlfn.NUMBERVALUE(_xlpm.vTexto,".")),"?")),IFERROR(ROWS(_xlfn.UNIQUE(_xlfn._xlws.FILTER(_xlpm.vClave&"|"&_xlpm.vCanon,_xlpm.vEsEsp))),0)-IFERROR(ROWS(_xlfn.UNIQUE(_xlfn._xlws.FILTER(_xlpm.vClave,_xlpm.vEsEsp))),0)))} | C19: Sus asignaturas comunes aparecen dos veces: lo cuenta el aviso DobleEspecialidad del analizador.
A20: Alumnado de profesional sin especialidad reconocida | B20: {=IF(CONTROL!$B$4<2,0,_xlfn.LET(_xlpm.vEt,RIGHT(eCURSO,3),_xlpm.vAsig,TRIM(eASIG),_xlpm.vCanon,_xlfn.IFNA(_xlfn.XLOOKUP(_xlpm.vAsig&"|"&_xlpm.vEt,cASIG&"|"&cETAPA,cASIG),_xlpm.vAsig),_xlpm.vEsEsp,ISNUMBER(_xlfn.XMATCH(_xlpm.vAsig&"|"&_xlpm.vEt&"|Sí",cASIG&"|"&cETAPA&"|"&cESP)),_xlpm.vClave,eNIA&"|"&_xlpm.vEt,_xlpm.vTexto,TRIM(eNOTA&""),_xlpm.vNum,IF(_xlpm.vTexto="","",IFERROR(IF(ISNUMBER(SEARCH(",",_xlpm.vTexto)),_xlfn.NUMBERVALUE(_xlpm.vTexto,","),_xlfn.NUMBERVALUE(_xlpm.vTexto,".")),"?")),IFERROR(ROWS(_xlfn.UNIQUE(_xlfn._xlws.FILTER(_xlpm.vClave,_xlpm.vEt="EPM"))),0)-IFERROR(ROWS(_xlfn.UNIQUE(_xlfn._xlws.FILTER(_xlpm.vClave,_xlpm.vEsEsp*(_xlpm.vEt="EPM")))),0)))} | C20: Su columna Especialidad sale vacía. Si no es cero, falta su instrumento en CATALOGO.
A21: Asignaturas que no están en el catálogo de su etapa | B21: {=IF(CONTROL!$B$4<2,0,_xlfn.LET(_xlpm.vEt,RIGHT(eCURSO,3),_xlpm.vAsig,TRIM(eASIG),_xlpm.vCanon,_xlfn.IFNA(_xlfn.XLOOKUP(_xlpm.vAsig&"|"&_xlpm.vEt,cASIG&"|"&cETAPA,cASIG),_xlpm.vAsig),_xlpm.vEsEsp,ISNUMBER(_xlfn.XMATCH(_xlpm.vAsig&"|"&_xlpm.vEt&"|Sí",cASIG&"|"&cETAPA&"|"&cESP)),_xlpm.vClave,eNIA&"|"&_xlpm.vEt,_xlpm.vTexto,TRIM(eNOTA&""),_xlpm.vNum,IF(_xlpm.vTexto="","",IFERROR(IF(ISNUMBER(SEARCH(",",_xlpm.vTexto)),_xlfn.NUMBERVALUE(_xlpm.vTexto,","),_xlfn.NUMBERVALUE(_xlpm.vTexto,".")),"?")),IFERROR(ROWS(_xlfn.UNIQUE(_xlfn._xlws.FILTER(_xlpm.vAsig&"|"&_xlpm.vEt,(_xlpm.vAsig<>"")*((_xlpm.vEt="EEM")+(_xlpm.vEt="EPM"))*ISNA(_xlfn.XMATCH(_xlpm.vAsig&"|"&_xlpm.vEt,cASIG&"|"&cETAPA))))),0)))} | C21: Pasan con el nombre que traen, y el analizador las cuenta en «FueraDeLasCifras». La lista está en INCIDENCIAS.
A22: Columnas opcionales que faltan | B22: {=_xlfn.LET(_xlpm.vC,{"promociona","anoacademico_id","denominacionespecifica"},_xlpm.vL,_xlfn.TEXTJOIN(", ",TRUE,IF(ISNA(_xlfn.XMATCH(_xlpm.vC,ENTRADA!$A$1:$AZ$1)),_xlpm.vC,"")),IF(_xlpm.vL="","Ninguna",_xlpm.vL))} | C22: Sin «promociona», PROMOCION no puede dar decisiones de promoción; el resto de sus recuentos, sí.

Sheet INCIDENCIAS
A1: Lo que no se procesa bien
A2: Esta hoja NO contiene datos personales: agrupa por el valor que da problemas y cuenta filas. Si hay algo distinto de «Ninguna», envíala a quien mantiene el conversor (joseluismirallesbono@gmail.com) para que se pueda incorporar.
A3: Alumnado de profesional sin especialidad reconocida: | D3: {=IF(CONTROL!$B$4<2,0,_xlfn.LET(_xlpm.vEt,RIGHT(eCURSO,3),_xlpm.vAsig,TRIM(eASIG),_xlpm.vCanon,_xlfn.IFNA(_xlfn.XLOOKUP(_xlpm.vAsig&"|"&_xlpm.vEt,cASIG&"|"&cETAPA,cASIG),_xlpm.vAsig),_xlpm.vEsEsp,ISNUMBER(_xlfn.XMATCH(_xlpm.vAsig&"|"&_xlpm.vEt&"|Sí",cASIG&"|"&cETAPA&"|"&cESP)),_xlpm.vClave,eNIA&"|"&_xlpm.vEt,_xlpm.vTexto,TRIM(eNOTA&""),_xlpm.vNum,IF(_xlpm.vTexto="","",IFERROR(IF(ISNUMBER(SEARCH(",",_xlpm.vTexto)),_xlfn.NUMBERVALUE(_xlpm.vTexto,","),_xlfn.NUMBERVALUE(_xlpm.vTexto,".")),"?")),IFERROR(ROWS(_xlfn.UNIQUE(_xlfn._xlws.FILTER(_xlpm.vClave,_xlpm.vEt="EPM"))),0)-IFERROR(ROWS(_xlfn.UNIQUE(_xlfn._xlws.FILTER(_xlpm.vClave,_xlpm.vEsEsp*(_xlpm.vEt="EPM")))),0)))}
A4: Asignaturas que no están en el catálogo | E4: Cursos que no son de ninguna etapa | H4: Notas que no son un número | K4: Evaluaciones que no son las de fin de curso
A5: Pasan con el nombre que traen y el analizador no las enseña: las cuenta en «FueraDeLasCifras». Si una es una especialidad, además su alumnado se queda sin especialidad. | E5: No pasan a ninguna hoja. El curso tiene que acabar en EEM o EPM (1EEM, 3EPM…). | H5: No pasan. El analizador solo entiende notas numéricas. | K5: Pasan, pero el analizador solo las cuenta si se elige esa evaluación. Lo esperado es FI en elemental, y OR y EX en profesional.
A6: Asignatura, tal como viene | B6: Etapa | C6: Filas | E6: Curso, tal como viene | F6: Filas | H6: Nota, tal como viene | I6: Filas | K6: Evaluación | L6: Etapa | M6: Filas
A7: {=IF(CONTROL!$B$4<2,"Sin datos",IFERROR(_xlfn.LET(_xlpm.vEt,RIGHT(eCURSO,3),_xlpm.vAsig,TRIM(eASIG),_xlpm.vCanon,_xlfn.IFNA(_xlfn.XLOOKUP(_xlpm.vAsig&"|"&_xlpm.vEt,cASIG&"|"&cETAPA,cASIG),_xlpm.vAsig),_xlpm.vEsEsp,ISNUMBER(_xlfn.XMATCH(_xlpm.vAsig&"|"&_xlpm.vEt&"|Sí",cASIG&"|"&cETAPA&"|"&cESP)),_xlpm.vClave,eNIA&"|"&_xlpm.vEt,_xlpm.vTexto,TRIM(eNOTA&""),_xlpm.vNum,IF(_xlpm.vTexto="","",IFERROR(IF(ISNUMBER(SEARCH(",",_xlpm.vTexto)),_xlfn.NUMBERVALUE(_xlpm.vTexto,","),_xlfn.NUMBERVALUE(_xlpm.vTexto,".")),"?")),_xlpm.vCond,(_xlpm.vAsig<>"")*((_xlpm.vEt="EEM")+(_xlpm.vEt="EPM"))*ISNA(_xlfn.XMATCH(_xlpm.vAsig&"|"&_xlpm.vEt,cASIG&"|"&cETAPA)),_xlpm.vK,_xlfn._xlws.FILTER(_xlpm.vAsig&"|"&_xlpm.vEt,_xlpm.vCond),_xlpm.vU,_xlfn.UNIQUE(_xlfn._xlws.FILTER(CHOOSE({1,2},_xlpm.vAsig,_xlpm.vEt),_xlpm.vCond)),_xlpm.vN,MMULT(--((INDEX(_xlpm.vU,0,1)&"|"&INDEX(_xlpm.vU,0,2))=TRANSPOSE(_xlpm.vK)),_xlfn.SEQUENCE(ROWS(_xlpm.vK),1,1,0)),_xlfn._xlws.SORT(CHOOSE({1,2,3},INDEX(_xlpm.vU,0,1),INDEX(_xlpm.vU,0,2),_xlpm.vN),3,-1)),"Ninguna"))} | E7: {=IF(CONTROL!$B$4<2,"Sin datos",IFERROR(_xlfn.LET(_xlpm.vEt,RIGHT(eCURSO,3),_xlpm.vAsig,TRIM(eASIG),_xlpm.vCanon,_xlfn.IFNA(_xlfn.XLOOKUP(_xlpm.vAsig&"|"&_xlpm.vEt,cASIG&"|"&cETAPA,cASIG),_xlpm.vAsig),_xlpm.vEsEsp,ISNUMBER(_xlfn.XMATCH(_xlpm.vAsig&"|"&_xlpm.vEt&"|Sí",cASIG&"|"&cETAPA&"|"&cESP)),_xlpm.vClave,eNIA&"|"&_xlpm.vEt,_xlpm.vTexto,TRIM(eNOTA&""),_xlpm.vNum,IF(_xlpm.vTexto="","",IFERROR(IF(ISNUMBER(SEARCH(",",_xlpm.vTexto)),_xlfn.NUMBERVALUE(_xlpm.vTexto,","),_xlfn.NUMBERVALUE(_xlpm.vTexto,".")),"?")),_xlpm.vCond,(_xlpm.vEt<>"EEM")*(_xlpm.vEt<>"EPM"),_xlpm.vK,_xlfn._xlws.FILTER(eCURSO&"",_xlpm.vCond),_xlpm.vU,_xlfn.UNIQUE(_xlfn._xlws.FILTER(CHOOSE({1},eCURSO&""),_xlpm.vCond)),_xlpm.vN,MMULT(--((INDEX(_xlpm.vU,0,1))=TRANSPOSE(_xlpm.vK)),_xlfn.SEQUENCE(ROWS(_xlpm.vK),1,1,0)),_xlfn._xlws.SORT(CHOOSE({1,2},INDEX(_xlpm.vU,0,1),_xlpm.vN),2,-1)),"Ninguna"))} | H7: {=IF(CONTROL!$B$4<2,"Sin datos",IFERROR(_xlfn.LET(_xlpm.vEt,RIGHT(eCURSO,3),_xlpm.vAsig,TRIM(eASIG),_xlpm.vCanon,_xlfn.IFNA(_xlfn.XLOOKUP(_xlpm.vAsig&"|"&_xlpm.vEt,cASIG&"|"&cETAPA,cASIG),_xlpm.vAsig),_xlpm.vEsEsp,ISNUMBER(_xlfn.XMATCH(_xlpm.vAsig&"|"&_xlpm.vEt&"|Sí",cASIG&"|"&cETAPA&"|"&cESP)),_xlpm.vClave,eNIA&"|"&_xlpm.vEt,_xlpm.vTexto,TRIM(eNOTA&""),_xlpm.vNum,IF(_xlpm.vTexto="","",IFERROR(IF(ISNUMBER(SEARCH(",",_xlpm.vTexto)),_xlfn.NUMBERVALUE(_xlpm.vTexto,","),_xlfn.NUMBERVALUE(_xlpm.vTexto,".")),"?")),_xlpm.vCond,(_xlpm.vTexto<>"")*(_xlpm.vNum="?"),_xlpm.vK,_xlfn._xlws.FILTER(_xlpm.vTexto,_xlpm.vCond),_xlpm.vU,_xlfn.UNIQUE(_xlfn._xlws.FILTER(CHOOSE({1},_xlpm.vTexto),_xlpm.vCond)),_xlpm.vN,MMULT(--((INDEX(_xlpm.vU,0,1))=TRANSPOSE(_xlpm.vK)),_xlfn.SEQUENCE(ROWS(_xlpm.vK),1,1,0)),_xlfn._xlws.SORT(CHOOSE({1,2},INDEX(_xlpm.vU,0,1),_xlpm.vN),2,-1)),"Ninguna"))} | K7: {=IF(CONTROL!$B$4<2,"Sin datos",IFERROR(_xlfn.LET(_xlpm.vEt,RIGHT(eCURSO,3),_xlpm.vAsig,TRIM(eASIG),_xlpm.vCanon,_xlfn.IFNA(_xlfn.XLOOKUP(_xlpm.vAsig&"|"&_xlpm.vEt,cASIG&"|"&cETAPA,cASIG),_xlpm.vAsig),_xlpm.vEsEsp,ISNUMBER(_xlfn.XMATCH(_xlpm.vAsig&"|"&_xlpm.vEt&"|Sí",cASIG&"|"&cETAPA&"|"&cESP)),_xlpm.vClave,eNIA&"|"&_xlpm.vEt,_xlpm.vTexto,TRIM(eNOTA&""),_xlpm.vNum,IF(_xlpm.vTexto="","",IFERROR(IF(ISNUMBER(SEARCH(",",_xlpm.vTexto)),_xlfn.NUMBERVALUE(_xlpm.vTexto,","),_xlfn.NUMBERVALUE(_xlpm.vTexto,".")),"?")),_xlpm.vCond,((_xlpm.vEt="EEM")*(eEVAL&""<>"FI")+(_xlpm.vEt="EPM")*(eEVAL&""<>"OR")*(eEVAL&""<>"EX"))>0,_xlpm.vK,_xlfn._xlws.FILTER(eEVAL&""&"|"&_xlpm.vEt,_xlpm.vCond),_xlpm.vU,_xlfn.UNIQUE(_xlfn._xlws.FILTER(CHOOSE({1,2},eEVAL&"",_xlpm.vEt),_xlpm.vCond)),_xlpm.vN,MMULT(--((INDEX(_xlpm.vU,0,1)&"|"&INDEX(_xlpm.vU,0,2))=TRANSPOSE(_xlpm.vK)),_xlfn.SEQUENCE(ROWS(_xlpm.vK),1,1,0)),_xlfn._xlws.SORT(CHOOSE({1,2,3},INDEX(_xlpm.vU,0,1),INDEX(_xlpm.vU,0,2),_xlpm.vN),3,-1)),"Ninguna"))}

Sheet PROMOCION
A1: Promoción, titulación y resultados del alumnado
A2: {=IF(CONTROL!$B$4<2,"Pega la exportación en ENTRADA",IFERROR("Año académico "&INDEX(eANO,1),"")&IFERROR(" · "&INDEX(eCENTRO,1),""))}
A3: Solo recuentos: ningún NIA, ningún nombre. Un curso que no aparece en la exportación sale como «—», no como 0.
A5: 1. Promoción por curso
A6: Un alumno, una vez, en su curso de matrícula. Manda la decisión de la evaluación más tardía que la trae: la extraordinaria antes que la ordinaria. «Con evaluación»: al menos una nota o una decisión.
A7: Curso | B7: Matriculados | C7: Con evaluación | D7: Promocionan | E7: No promocionan | F7: Sin decisión | G7: Sin evaluación | H7: % promociona sobre evaluados | I7: % promociona sobre matriculados
A8: 1EEM | B8: {=IF(CONTROL!$B$4<2,"—",IFERROR(_xlfn.LET(_xlpm.vC,(INDEX(_xlfn.ANCHORARRAY(ALUMNADO!$A$2),0,2)="1EEM"),_xlpm.vN,SUM(--(_xlpm.vC)),IF(_xlpm.vN=0,"—",_xlpm.vN)),"—"))} | C8: {=IF(CONTROL!$B$4<2,"—",IFERROR(_xlfn.LET(_xlpm.vC,(INDEX(_xlfn.ANCHORARRAY(ALUMNADO!$A$2),0,2)="1EEM"),_xlpm.vN,SUM(--(_xlpm.vC)),IF(_xlpm.vN=0,"—",SUM(_xlpm.vC*(INDEX(_xlfn.ANCHORARRAY(ALUMNADO!$A$2),0,8)="Con evaluación")))),"—"))} | D8: {=IF(CONTROL!$B$4<2,"—",IFERROR(_xlfn.LET(_xlpm.vC,(INDEX(_xlfn.ANCHORARRAY(ALUMNADO!$A$2),0,2)="1EEM"),_xlpm.vN,SUM(--(_xlpm.vC)),IF(_xlpm.vN=0,"—",IF(SUM(_xlpm.vC*(INDEX(_xlfn.ANCHORARRAY(ALUMNADO!$A$2),0,6)<>""))=0,"—",SUM(_xlpm.vC*(INDEX(_xlfn.ANCHORARRAY(ALUMNADO!$A$2),0,7)="Promociona"))))),"—"))} | E8: {=IF(CONTROL!$B$4<2,"—",IFERROR(_xlfn.LET(_xlpm.vC,(INDEX(_xlfn.ANCHORARRAY(ALUMNADO!$A$2),0,2)="1EEM"),_xlpm.vN,SUM(--(_xlpm.vC)),IF(_xlpm.vN=0,"—",IF(SUM(_xlpm.vC*(INDEX(_xlfn.ANCHORARRAY(ALUMNADO!$A$2),0,6)<>""))=0,"—",SUM(_xlpm.vC*(INDEX(_xlfn.ANCHORARRAY(ALUMNADO!$A$2),0,7)="No promociona"))))),"—"))} | F8: {=IF(CONTROL!$B$4<2,"—",IFERROR(_xlfn.LET(_xlpm.vC,(INDEX(_xlfn.ANCHORARRAY(ALUMNADO!$A$2),0,2)="1EEM"),_xlpm.vN,SUM(--(_xlpm.vC)),IF(_xlpm.vN=0,"—",SUM(_xlpm.vC*(INDEX(_xlfn.ANCHORARRAY(ALUMNADO!$A$2),0,8)="Con evaluación")*(INDEX(_xlfn.ANCHORARRAY(ALUMNADO!$A$2),0,7)="Sin decisión")))),"—"))} | G8: {=IF(CONTROL!$B$4<2,"—",IFERROR(_xlfn.LET(_xlpm.vC,(INDEX(_xlfn.ANCHORARRAY(ALUMNADO!$A$2),0,2)="1EEM"),_xlpm.vN,SUM(--(_xlpm.vC)),IF(_xlpm.vN=0,"—",SUM(_xlpm.vC*(INDEX(_xlfn.ANCHORARRAY(ALUMNADO!$A$2),0,8)="Sin evaluación")))),"—"))} | H8: {=IF(CONTROL!$B$4<2,"—",IFERROR(_xlfn.LET(_xlpm.vC,(INDEX(_xlfn.ANCHORARRAY(ALUMNADO!$A$2),0,2)="1EEM"),_xlpm.vN,SUM(--(_xlpm.vC)),IF(_xlpm.vN=0,"—",IF(SUM(_xlpm.vC*(INDEX(_xlfn.ANCHORARRAY(ALUMNADO!$A$2),0,6)<>""))=0,"—",IFERROR(SUM(_xlpm.vC*(INDEX(_xlfn.ANCHORARRAY(ALUMNADO!$A$2),0,7)="Promociona"))/SUM(_xlpm.vC*(INDEX(_xlfn.ANCHORARRAY(ALUMNADO!$A$2),0,8)="Con evaluación")),"—")))),"—"))} | I8: {=IF(CONTROL!$B$4<2,"—",IFERROR(_xlfn.LET(_xlpm.vC,(INDEX(_xlfn.ANCHORARRAY(ALUMNADO!$A$2),0,2)="1EEM"),_xlpm.vN,SUM(--(_xlpm.vC)),IF(_xlpm.vN=0,"—",IF(SUM(_xlpm.vC*(INDEX(_xlfn.ANCHORARRAY(ALUMNADO!$A$2),0,6)<>""))=0,"—",SUM(_xlpm.vC*(INDEX(_xlfn.ANCHORARRAY(ALUMNADO!$A$2),0,7)="Promociona"))/_xlpm.vN))),"—"))}
A9: 2EEM | B9: {=IF(CONTROL!$B$4<2,"—",IFERROR(_xlfn.LET(_xlpm.vC,(INDEX(_xlfn.ANCHORARRAY(ALUMNADO!$A$2),0,2)="2EEM"),_xlpm.vN,SUM(--(_xlpm.vC)),IF(_xlpm.vN=0,"—",_xlpm.vN)),"—"))} | C9: {=IF(CONTROL!$B$4<2,"—",IFERROR(_xlfn.LET(_xlpm.vC,(INDEX(_xlfn.ANCHORARRAY(ALUMNADO!$A$2),0,2)="2EEM"),_xlpm.vN,SUM(--(_xlpm.vC)),IF(_xlpm.vN=0,"—",SUM(_xlpm.vC*(INDEX(_xlfn.ANCHORARRAY(ALUMNADO!$A$2),0,8)="Con evaluación")))),"—"))} | D9: {=IF(CONTROL!$B$4<2,"—",IFERROR(_xlfn.LET(_xlpm.vC,(INDEX(_xlfn.ANCHORARRAY(ALUMNADO!$A$2),0,2)="2EEM"),_xlpm.vN,SUM(--(_xlpm.vC)),IF(_xlpm.vN=0,"—",IF(SUM(_xlpm.vC*(INDEX(_xlfn.ANCHORARRAY(ALUMNADO!$A$2),0,6)<>""))=0,"—",SUM(_xlpm.vC*(INDEX(_xlfn.ANCHORARRAY(ALUMNADO!$A$2),0,7)="Promociona"))))),"—"))} | E9: {=IF(CONTROL!$B$4<2,"—",IFERROR(_xlfn.LET(_xlpm.vC,(INDEX(_xlfn.ANCHORARRAY(ALUMNADO!$A$2),0,2)="2EEM"),_xlpm.vN,SUM(--(_xlpm.vC)),IF(_xlpm.vN=0,"—",IF(SUM(_xlpm.vC*(INDEX(_xlfn.ANCHORARRAY(ALUMNADO!$A$2),0,6)<>""))=0,"—",SUM(_xlpm.vC*(INDEX(_xlfn.ANCHORARRAY(ALUMNADO!$A$2),0,7)="No promociona"))))),"—"))} | F9: {=IF(CONTROL!$B$4<2,"—",IFERROR(_xlfn.LET(_xlpm.vC,(INDEX(_xlfn.ANCHORARRAY(ALUMNADO!$A$2),0,2)="2EEM"),_xlpm.vN,SUM(--(_xlpm.vC)),IF(_xlpm.vN=0,"—",SUM(_xlpm.vC*(INDEX(_xlfn.ANCHORARRAY(ALUMNADO!$A$2),0,8)="Con evaluación")*(INDEX(_xlfn.ANCHORARRAY(ALUMNADO!$A$2),0,7)="Sin decisión")))),"—"))} | G9: {=IF(CONTROL!$B$4<2,"—",IFERROR(_xlfn.LET(_xlpm.vC,(INDEX(_xlfn.ANCHORARRAY(ALUMNADO!$A$2),0,2)="2EEM"),_xlpm.vN,SUM(--(_xlpm.vC)),IF(_xlpm.vN=0,"—",SUM(_xlpm.vC*(INDEX(_xlfn.ANCHORARRAY(ALUMNADO!$A$2),0,8)="Sin evaluación")))),"—"))} | H9: {=IF(CONTROL!$B$4<2,"—",IFERROR(_xlfn.LET(_xlpm.vC,(INDEX(_xlfn.ANCHORARRAY(ALUMNADO!$A$2),0,2)="2EEM"),_xlpm.vN,SUM(--(_xlpm.vC)),IF(_xlpm.vN=0,"—",IF(SUM(_xlpm.vC*(INDEX(_xlfn.ANCHORARRAY(ALUMNADO!$A$2),0,6)<>""))=0,"—",IFERROR(SUM(_xlpm.vC*(INDEX(_xlfn.ANCHORARRAY(ALUMNADO!$A$2),0,7)="Promociona"))/SUM(_xlpm.vC*(INDEX(_xlfn.ANCHORARRAY(ALUMNADO!$A$2),0,8)="Con evaluación")),"—")))),"—"))} | I9: {=IF(CONTROL!$B$4<2,"—",IFERROR(_xlfn.LET(_xlpm.vC,(INDEX(_xlfn.ANCHORARRAY(ALUMNADO!$A$2),0,2)="2EEM"),_xlpm.vN,SUM(--(_xlpm.vC)),IF(_xlpm.vN=0,"—",IF(SUM(_xlpm.vC*(INDEX(_xlfn.ANCHORARRAY(ALUMNADO!$A$2),0,6)<>""))=0,"—",SUM(_xlpm.vC*(INDEX(_xlfn.ANCHORARRAY(ALUMNADO!$A$2),0,7)="Promociona"))/_xlpm.vN))),"—"))}
A10: 3EEM | B10: {=IF(CONTROL!$B$4<2,"—",IFERROR(_xlfn.LET(_xlpm.vC,(INDEX(_xlfn.ANCHORARRAY(ALUMNADO!$A$2),0,2)="3EEM"),_xlpm.vN,SUM(--(_xlpm.vC)),IF(_xlpm.vN=0,"—",_xlpm.vN)),"—"))} | C10: {=IF(CONTROL!$B$4<2,"—",IFERROR(_xlfn.LET(_xlpm.vC,(INDEX(_xlfn.ANCHORARRAY(ALUMNADO!$A$2),0,2)="3EEM"),_xlpm.vN,SUM(--(_xlpm.vC)),IF(_xlpm.vN=0,"—",SUM(_xlpm.vC*(INDEX(_xlfn.ANCHORARRAY(ALUMNADO!$A$2),0,8)="Con evaluación")))),"—"))} | D10: {=IF(CONTROL!$B$4<2,"—",IFERROR(_xlfn.LET(_xlpm.vC,(INDEX(_xlfn.ANCHORARRAY(ALUMNADO!$A$2),0,2)="3EEM"),_xlpm.vN,SUM(--(_xlpm.vC)),IF(_xlpm.vN=0,"—",IF(SUM(_xlpm.vC*(INDEX(_xlfn.ANCHORARRAY(ALUMNADO!$A$2),0,6)<>""))=0,"—",SUM(_xlpm.vC*(INDEX(_xlfn.ANCHORARRAY(ALUMNADO!$A$2),0,7)="Promociona"))))),"—"))} | E10: {=IF(CONTROL!$B$4<2,"—",IFERROR(_xlfn.LET(_xlpm.vC,(INDEX(_xlfn.ANCHORARRAY(ALUMNADO!$A$2),0,2)="3EEM"),_xlpm.vN,SUM(--(_xlpm.vC)),IF(_xlpm.vN=0,"—",IF(SUM(_xlpm.vC*(INDEX(_xlfn.ANCHORARRAY(ALUMNADO!$A$2),0,6)<>""))=0,"—",SUM(_xlpm.vC*(INDEX(_xlfn.ANCHORARRAY(ALUMNADO!$A$2),0,7)="No promociona"))))),"—"))} | F10: {=IF(CONTROL!$B$4<2,"—",IFERROR(_xlfn.LET(_xlpm.vC,(INDEX(_xlfn.ANCHORARRAY(ALUMNADO!$A$2),0,2)="3EEM"),_xlpm.vN,SUM(--(_xlpm.vC)),IF(_xlpm.vN=0,"—",SUM(_xlpm.vC*(INDEX(_xlfn.ANCHORARRAY(ALUMNADO!$A$2),0,8)="Con evaluación")*(INDEX(_xlfn.ANCHORARRAY(ALUMNADO!$A$2),0,7)="Sin decisión")))),"—"))} | G10: {=IF(CONTROL!$B$4<2,"—",IFERROR(_xlfn.LET(_xlpm.vC,(INDEX(_xlfn.ANCHORARRAY(ALUMNADO!$A$2),0,2)="3EEM"),_xlpm.vN,SUM(--(_xlpm.vC)),IF(_xlpm.vN=0,"—",SUM(_xlpm.vC*(INDEX(_xlfn.ANCHORARRAY(ALUMNADO!$A$2),0,8)="Sin evaluación")))),"—"))} | H10: {=IF(CONTROL!$B$4<2,"—",IFERROR(_xlfn.LET(_xlpm.vC,(INDEX(_xlfn.ANCHORARRAY(ALUMNADO!$A$2),0,2)="3EEM"),_xlpm.vN,SUM(--(_xlpm.vC)),IF(_xlpm.vN=0,"—",IF(SUM(_xlpm.vC*(INDEX(_xlfn.ANCHORARRAY(ALUMNADO!$A$2),0,6)<>""))=0,"—",IFERROR(SUM(_xlpm.vC*(INDEX(_xlfn.ANCHORARRAY(ALUMNADO!$A$2),0,7)="Promociona"))/SUM(_xlpm.vC*(INDEX(_xlfn.ANCHORARRAY(ALUMNADO!$A$2),0,8)="Con evaluación")),"—")))),"—"))} | I10: {=IF(CONTROL!$B$4<2,"—",IFERROR(_xlfn.LET(_xlpm.vC,(INDEX(_xlfn.ANCHORARRAY(ALUMNADO!$A$2),0,2)="3EEM"),_xlpm.vN,SUM(--(_xlpm.vC)),IF(_xlpm.vN=0,"—",IF(SUM(_xlpm.vC*(INDEX(_xlfn.ANCHORARRAY(ALUMNADO!$A$2),0,6)<>""))=0,"—",SUM(_xlpm.vC*(INDEX(_xlfn.ANCHORARRAY(ALUMNADO!$A$2),0,7)="Promociona"))/_xlpm.vN))),"—"))}
A11: 4EEM | B11: {=IF(CONTROL!$B$4<2,"—",IFERROR(_xlfn.LET(_xlpm.vC,(INDEX(_xlfn.ANCHORARRAY(ALUMNADO!$A$2),0,2)="4EEM"),_xlpm.vN,SUM(--(_xlpm.vC)),IF(_xlpm.vN=0,"—",_xlpm.vN)),"—"))} | C11: {=IF(CONTROL!$B$4<2,"—",IFERROR(_xlfn.LET(_xlpm.vC,(INDEX(_xlfn.ANCHORARRAY(ALUMNADO!$A$2),0,2)="4EEM"),_xlpm.vN,SUM(--(_xlpm.vC)),IF(_xlpm.vN=0,"—",SUM(_xlpm.vC*(INDEX(_xlfn.ANCHORARRAY(ALUMNADO!$A$2),0,8)="Con evaluación")))),"—"))} | D11: {=IF(CONTROL!$B$4<2,"—",IFERROR(_xlfn.LET(_xlpm.vC,(INDEX(_xlfn.ANCHORARRAY(ALUMNADO!$A$2),0,2)="4EEM"),_xlpm.vN,SUM(--(_xlpm.vC)),IF(_xlpm.vN=0,"—",IF(SUM(_xlpm.vC*(INDEX(_xlfn.ANCHORARRAY(ALUMNADO!$A$2),0,6)<>""))=0,"—",SUM(_xlpm.vC*(INDEX(_xlfn.ANCHORARRAY(ALUMNADO!$A$2),0,7)="Promociona"))))),"—"))} | E11: {=IF(CONTROL!$B$4<2,"—",IFERROR(_xlfn.LET(_xlpm.vC,(INDEX(_xlfn.ANCHORARRAY(ALUMNADO!$A$2),0,2)="4EEM"),_xlpm.vN,SUM(--(_xlpm.vC)),IF(_xlpm.vN=0,"—",IF(SUM(_xlpm.vC*(INDEX(_xlfn.ANCHORARRAY(ALUMNADO!$A$2),0,6)<>""))=0,"—",SUM(_xlpm.vC*(INDEX(_xlfn.ANCHORARRAY(ALUMNADO!$A$2),0,7)="No promociona"))))),"—"))} | F11: {=IF(CONTROL!$B$4<2,"—",IFERROR(_xlfn.LET(_xlpm.vC,(INDEX(_xlfn.ANCHORARRAY(ALUMNADO!$A$2),0,2)="4EEM"),_xlpm.vN,SUM(--(_xlpm.vC)),IF(_xlpm.vN=0,"—",SUM(_xlpm.vC*(INDEX(_xlfn.ANCHORARRAY(ALUMNADO!$A$2),0,8)="Con evaluación")*(INDEX(_xlfn.ANCHORARRAY(ALUMNADO!$A$2),0,7)="Sin decisión")))),"—"))} | G11: {=IF(CONTROL!$B$4<2,"—",IFERROR(_xlfn.LET(_xlpm.vC,(INDEX(_xlfn.ANCHORARRAY(ALUMNADO!$A$2),0,2)="4EEM"),_xlpm.vN,SUM(--(_xlpm.vC)),IF(_xlpm.vN=0,"—",SUM(_xlpm.vC*(INDEX(_xlfn.ANCHORARRAY(ALUMNADO!$A$2),0,8)="Sin evaluación")))),"—"))} | H11: {=IF(CONTROL!$B$4<2,"—",IFERROR(_xlfn.LET(_xlpm.vC,(INDEX(_xlfn.ANCHORARRAY(ALUMNADO!$A$2),0,2)="4EEM"),_xlpm.vN,SUM(--(_xlpm.vC)),IF(_xlpm.vN=0,"—",IF(SUM(_xlpm.vC*(INDEX(_xlfn.ANCHORARRAY(ALUMNADO!$A$2),0,6)<>""))=0,"—",IFERROR(SUM(_xlpm.vC*(INDEX(_xlfn.ANCHORARRAY(ALUMNADO!$A$2),0,7)="Promociona"))/SUM(_xlpm.vC*(INDEX(_xlfn.ANCHORARRAY(ALUMNADO!$A$2),0,8)="Con evaluación")),"—")))),"—"))} | I11: {=IF(CONTROL!$B$4<2,"—",IFERROR(_xlfn.LET(_xlpm.vC,(INDEX(_xlfn.ANCHORARRAY(ALUMNADO!$A$2),0,2)="4EEM"),_xlpm.vN,SUM(--(_xlpm.vC)),IF(_xlpm.vN=0,"—",IF(SUM(_xlpm.vC*(INDEX(_xlfn.ANCHORARRAY(ALUMNADO!$A$2),0,6)<>""))=0,"—",SUM(_xlpm.vC*(INDEX(_xlfn.ANCHORARRAY(ALUMNADO!$A$2),0,7)="Promociona"))/_xlpm.vN))),"—"))}
A12: Total EEM | B12: {=IF(CONTROL!$B$4<2,"—",IFERROR(_xlfn.LET(_xlpm.vC,(INDEX(_xlfn.ANCHORARRAY(ALUMNADO!$A$2),0,3)="EEM"),_xlpm.vN,SUM(--(_xlpm.vC)),IF(_xlpm.vN=0,"—",_xlpm.vN)),"—"))} | C12: {=IF(CONTROL!$B$4<2,"—",IFERROR(_xlfn.LET(_xlpm.vC,(INDEX(_xlfn.ANCHORARRAY(ALUMNADO!$A$2),0,3)="EEM"),_xlpm.vN,SUM(--(_xlpm.vC)),IF(_xlpm.vN=0,"—",SUM(_xlpm.vC*(INDEX(_xlfn.ANCHORARRAY(ALUMNADO!$A$2),0,8)="Con evaluación")))),"—"))} | D12: {=IF(CONTROL!$B$4<2,"—",IFERROR(_xlfn.LET(_xlpm.vC,(INDEX(_xlfn.ANCHORARRAY(ALUMNADO!$A$2),0,3)="EEM"),_xlpm.vN,SUM(--(_xlpm.vC)),IF(_xlpm.vN=0,"—",IF(SUM(_xlpm.vC*(INDEX(_xlfn.ANCHORARRAY(ALUMNADO!$A$2),0,6)<>""))=0,"—",SUM(_xlpm.vC*(INDEX(_xlfn.ANCHORARRAY(ALUMNADO!$A$2),0,7)="Promociona"))))),"—"))} | E12: {=IF(CONTROL!$B$4<2,"—",IFERROR(_xlfn.LET(_xlpm.vC,(INDEX(_xlfn.ANCHORARRAY(ALUMNADO!$A$2),0,3)="EEM"),_xlpm.vN,SUM(--(_xlpm.vC)),IF(_xlpm.vN=0,"—",IF(SUM(_xlpm.vC*(INDEX(_xlfn.ANCHORARRAY(ALUMNADO!$A$2),0,6)<>""))=0,"—",SUM(_xlpm.vC*(INDEX(_xlfn.ANCHORARRAY(ALUMNADO!$A$2),0,7)="No promociona"))))),"—"))} | F12: {=IF(CONTROL!$B$4<2,"—",IFERROR(_xlfn.LET(_xlpm.vC,(INDEX(_xlfn.ANCHORARRAY(ALUMNADO!$A$2),0,3)="EEM"),_xlpm.vN,SUM(--(_xlpm.vC)),IF(_xlpm.vN=0,"—",SUM(_xlpm.vC*(INDEX(_xlfn.ANCHORARRAY(ALUMNADO!$A$2),0,8)="Con evaluación")*(INDEX(_xlfn.ANCHORARRAY(ALUMNADO!$A$2),0,7)="Sin decisión")))),"—"))} | G12: {=IF(CONTROL!$B$4<2,"—",IFERROR(_xlfn.LET(_xlpm.vC,(INDEX(_xlfn.ANCHORARRAY(ALUMNADO!$A$2),0,3)="EEM"),_xlpm.vN,SUM(--(_xlpm.vC)),IF(_xlpm.vN=0,"—",SUM(_xlpm.vC*(INDEX(_xlfn.ANCHORARRAY(ALUMNADO!$A$2),0,8)="Sin evaluación")))),"—"))} | H12: {=IF(CONTROL!$B$4<2,"—",IFERROR(_xlfn.LET(_xlpm.vC,(INDEX(_xlfn.ANCHORARRAY(ALUMNADO!$A$2),0,3)="EEM"),_xlpm.vN,SUM(--(_xlpm.vC)),IF(_xlpm.vN=0,"—",IF(SUM(_xlpm.vC*(INDEX(_xlfn.ANCHORARRAY(ALUMNADO!$A$2),0,6)<>""))=0,"—",IFERROR(SUM(_xlpm.vC*(INDEX(_xlfn.ANCHORARRAY(ALUMNADO!$A$2),0,7)="Promociona"))/SUM(_xlpm.vC*(INDEX(_xlfn.ANCHORARRAY(ALUMNADO!$A$2),0,8)="Con evaluación")),"—")))),"—"))} | I12: {=IF(CONTROL!$B$4<2,"—",IFERROR(_xlfn.LET(_xlpm.vC,(INDEX(_xlfn.ANCHORARRAY(ALUMNADO!$A$2),0,3)="EEM"),_xlpm.vN,SUM(--(_xlpm.vC)),IF(_xlpm.vN=0,"—",IF(SUM(_xlpm.vC*(INDEX(_xlfn.ANCHORARRAY(ALUMNADO!$A$2),0,6)<>""))=0,"—",SUM(_xlpm.vC*(INDEX(_xlfn.ANCHORARRAY(ALUMNADO!$A$2),0,7)="Promociona"))/_xlpm.vN))),"—"))}
A13: 1EPM | B13: {=IF(CONTROL!$B$4<2,"—",IFERROR(_xlfn.LET(_xlpm.vC,(INDEX(_xlfn.ANCHORARRAY(ALUMNADO!$A$2),0,2)="1EPM"),_xlpm.vN,SUM(--(_xlpm.vC)),IF(_xlpm.vN=0,"—",_xlpm.vN)),"—"))} | C13: {=IF(CONTROL!$B$4<2,"—",IFERROR(_xlfn.LET(_xlpm.vC,(INDEX(_xlfn.ANCHORARRAY(ALUMNADO!$A$2),0,2)="1EPM"),_xlpm.vN,SUM(--(_xlpm.vC)),IF(_xlpm.vN=0,"—",SUM(_xlpm.vC*(INDEX(_xlfn.ANCHORARRAY(ALUMNADO!$A$2),0,8)="Con evaluación")))),"—"))} | D13: {=IF(CONTROL!$B$4<2,"—",IFERROR(_xlfn.LET(_xlpm.vC,(INDEX(_xlfn.ANCHORARRAY(ALUMNADO!$A$2),0,2)="1EPM"),_xlpm.vN,SUM(--(_xlpm.vC)),IF(_xlpm.vN=0,"—",IF(SUM(_xlpm.vC*(INDEX(_xlfn.ANCHORARRAY(ALUMNADO!$A$2),0,6)<>""))=0,"—",SUM(_xlpm.vC*(INDEX(_xlfn.ANCHORARRAY(ALUMNADO!$A$2),0,7)="Promociona"))))),"—"))} | E13: {=IF(CONTROL!$B$4<2,"—",IFERROR(_xlfn.LET(_xlpm.vC,(INDEX(_xlfn.ANCHORARRAY(ALUMNADO!$A$2),0,2)="1EPM"),_xlpm.vN,SUM(--(_xlpm.vC)),IF(_xlpm.vN=0,"—",IF(SUM(_xlpm.vC*(INDEX(_xlfn.ANCHORARRAY(ALUMNADO!$A$2),0,6)<>""))=0,"—",SUM(_xlpm.vC*(INDEX(_xlfn.ANCHORARRAY(ALUMNADO!$A$2),0,7)="No promociona"))))),"—"))} | F13: {=IF(CONTROL!$B$4<2,"—",IFERROR(_xlfn.LET(_xlpm.vC,(INDEX(_xlfn.ANCHORARRAY(ALUMNADO!$A$2),0,2)="1EPM"),_xlpm.vN,SUM(--(_xlpm.vC)),IF(_xlpm.vN=0,"—",SUM(_xlpm.vC*(INDEX(_xlfn.ANCHORARRAY(ALUMNADO!$A$2),0,8)="Con evaluación")*(INDEX(_xlfn.ANCHORARRAY(ALUMNADO!$A$2),0,7)="Sin decisión")))),"—"))} | G13: {=IF(CONTROL!$B$4<2,"—",IFERROR(_xlfn.LET(_xlpm.vC,(INDEX(_xlfn.ANCHORARRAY(ALUMNADO!$A$2),0,2)="1EPM"),_xlpm.vN,SUM(--(_xlpm.vC)),IF(_xlpm.vN=0,"—",SUM(_xlpm.vC*(INDEX(_xlfn.ANCHORARRAY(ALUMNADO!$A$2),0,8)="Sin evaluación")))),"—"))} | H13: {=IF(CONTROL!$B$4<2,"—",IFERROR(_xlfn.LET(_xlpm.vC,(INDEX(_xlfn.ANCHORARRAY(ALUMNADO!$A$2),0,2)="1EPM"),_xlpm.vN,SUM(--(_xlpm.vC)),IF(_xlpm.vN=0,"—",IF(SUM(_xlpm.vC*(INDEX(_xlfn.ANCHORARRAY(ALUMNADO!$A$2),0,6)<>""))=0,"—",IFERROR(SUM(_xlpm.vC*(INDEX(_xlfn.ANCHORARRAY(ALUMNADO!$A$2),0,7)="Promociona"))/SUM(_xlpm.vC*(INDEX(_xlfn.ANCHORARRAY(ALUMNADO!$A$2),0,8)="Con evaluación")),"—")))),"—"))} | I13: {=IF(CONTROL!$B$4<2,"—",IFERROR(_xlfn.LET(_xlpm.vC,(INDEX(_xlfn.ANCHORARRAY(ALUMNADO!$A$2),0,2)="1EPM"),_xlpm.vN,SUM(--(_xlpm.vC)),IF(_xlpm.vN=0,"—",IF(SUM(_xlpm.vC*(INDEX(_xlfn.ANCHORARRAY(ALUMNADO!$A$2),0,6)<>""))=0,"—",SUM(_xlpm.vC*(INDEX(_xlfn.ANCHORARRAY(ALUMNADO!$A$2),0,7)="Promociona"))/_xlpm.vN))),"—"))}
A14: 2EPM | B14: {=IF(CONTROL!$B$4<2,"—",IFERROR(_xlfn.LET(_xlpm.vC,(INDEX(_xlfn.ANCHORARRAY(ALUMNADO!$A$2),0,2)="2EPM"),_xlpm.vN,SUM(--(_xlpm.vC)),IF(_xlpm.vN=0,"—",_xlpm.vN)),"—"))} | C14: {=IF(CONTROL!$B$4<2,"—",IFERROR(_xlfn.LET(_xlpm.vC,(INDEX(_xlfn.ANCHORARRAY(ALUMNADO!$A$2),0,2)="2EPM"),_xlpm.vN,SUM(--(_xlpm.vC)),IF(_xlpm.vN=0,"—",SUM(_xlpm.vC*(INDEX(_xlfn.ANCHORARRAY(ALUMNADO!$A$2),0,8)="Con evaluación")))),"—"))} | D14: {=IF(CONTROL!$B$4<2,"—",IFERROR(_xlfn.LET(_xlpm.vC,(INDEX(_xlfn.ANCHORARRAY(ALUMNADO!$A$2),0,2)="2EPM"),_xlpm.vN,SUM(--(_xlpm.vC)),IF(_xlpm.vN=0,"—",IF(SUM(_xlpm.vC*(INDEX(_xlfn.ANCHORARRAY(ALUMNADO!$A$2),0,6)<>""))=0,"—",SUM(_xlpm.vC*(INDEX(_xlfn.ANCHORARRAY(ALUMNADO!$A$2),0,7)="Promociona"))))),"—"))} | E14: {=IF(CONTROL!$B$4<2,"—",IFERROR(_xlfn.LET(_xlpm.vC,(INDEX(_xlfn.ANCHORARRAY(ALUMNADO!$A$2),0,2)="2EPM"),_xlpm.vN,SUM(--(_xlpm.vC)),IF(_xlpm.vN=0,"—",IF(SUM(_xlpm.vC*(INDEX(_xlfn.ANCHORARRAY(ALUMNADO!$A$2),0,6)<>""))=0,"—",SUM(_xlpm.vC*(INDEX(_xlfn.ANCHORARRAY(ALUMNADO!$A$2),0,7)="No promociona"))))),"—"))} | F14: {=IF(CONTROL!$B$4<2,"—",IFERROR(_xlfn.LET(_xlpm.vC,(INDEX(_xlfn.ANCHORARRAY(ALUMNADO!$A$2),0,2)="2EPM"),_xlpm.vN,SUM(--(_xlpm.vC)),IF(_xlpm.vN=0,"—",SUM(_xlpm.vC*(INDEX(_xlfn.ANCHORARRAY(ALUMNADO!$A$2),0,8)="Con evaluación")*(INDEX(_xlfn.ANCHORARRAY(ALUMNADO!$A$2),0,7)="Sin decisión")))),"—"))} | G14: {=IF(CONTROL!$B$4<2,"—",IFERROR(_xlfn.LET(_xlpm.vC,(INDEX(_xlfn.ANCHORARRAY(ALUMNADO!$A$2),0,2)="2EPM"),_xlpm.vN,SUM(--(_xlpm.vC)),IF(_xlpm.vN=0,"—",SUM(_xlpm.vC*(INDEX(_xlfn.ANCHORARRAY(ALUMNADO!$A$2),0,8)="Sin evaluación")))),"—"))} | H14: {=IF(CONTROL!$B$4<2,"—",IFERROR(_xlfn.LET(_xlpm.vC,(INDEX(_xlfn.ANCHORARRAY(ALUMNADO!$A$2),0,2)="2EPM"),_xlpm.vN,SUM(--(_xlpm.vC)),IF(_xlpm.vN=0,"—",IF(SUM(_xlpm.vC*(INDEX(_xlfn.ANCHORARRAY(ALUMNADO!$A$2),0,6)<>""))=0,"—",IFERROR(SUM(_xlpm.vC*(INDEX(_xlfn.ANCHORARRAY(ALUMNADO!$A$2),0,7)="Promociona"))/SUM(_xlpm.vC*(INDEX(_xlfn.ANCHORARRAY(ALUMNADO!$A$2),0,8)="Con evaluación")),"—")))),"—"))} | I14: {=IF(CONTROL!$B$4<2,"—",IFERROR(_xlfn.LET(_xlpm.vC,(INDEX(_xlfn.ANCHORARRAY(ALUMNADO!$A$2),0,2)="2EPM"),_xlpm.vN,SUM(--(_xlpm.vC)),IF(_xlpm.vN=0,"—",IF(SUM(_xlpm.vC*(INDEX(_xlfn.ANCHORARRAY(ALUMNADO!$A$2),0,6)<>""))=0,"—",SUM(_xlpm.vC*(INDEX(_xlfn.ANCHORARRAY(ALUMNADO!$A$2),0,7)="Promociona"))/_xlpm.vN))),"—"))}
A15: 3EPM | B15: {=IF(CONTROL!$B$4<2,"—",IFERROR(_xlfn.LET(_xlpm.vC,(INDEX(_xlfn.ANCHORARRAY(ALUMNADO!$A$2),0,2)="3EPM"),_xlpm.vN,SUM(--(_xlpm.vC)),IF(_xlpm.vN=0,"—",_xlpm.vN)),"—"))} | C15: {=IF(CONTROL!$B$4<2,"—",IFERROR(_xlfn.LET(_xlpm.vC,(INDEX(_xlfn.ANCHORARRAY(ALUMNADO!$A$2),0,2)="3EPM"),_xlpm.vN,SUM(--(_xlpm.vC)),IF(_xlpm.vN=0,"—",SUM(_xlpm.vC*(INDEX(_xlfn.ANCHORARRAY(ALUMNADO!$A$2),0,8)="Con evaluación")))),"—"))} | D15: {=IF(CONTROL!$B$4<2,"—",IFERROR(_xlfn.LET(_xlpm.vC,(INDEX(_xlfn.ANCHORARRAY(ALUMNADO!$A$2),0,2)="3EPM"),_xlpm.vN,SUM(--(_xlpm.vC)),IF(_xlpm.vN=0,"—",IF(SUM(_xlpm.vC*(INDEX(_xlfn.ANCHORARRAY(ALUMNADO!$A$2),0,6)<>""))=0,"—",SUM(_xlpm.vC*(INDEX(_xlfn.ANCHORARRAY(ALUMNADO!$A$2),0,7)="Promociona"))))),"—"))} | E15: {=IF(CONTROL!$B$4<2,"—",IFERROR(_xlfn.LET(_xlpm.vC,(INDEX(_xlfn.ANCHORARRAY(ALUMNADO!$A$2),0,2)="3EPM"),_xlpm.vN,SUM(--(_xlpm.vC)),IF(_xlpm.vN=0,"—",IF(SUM(_xlpm.vC*(INDEX(_xlfn.ANCHORARRAY(ALUMNADO!$A$2),0,6)<>""))=0,"—",SUM(_xlpm.vC*(INDEX(_xlfn.ANCHORARRAY(ALUMNADO!$A$2),0,7)="No promociona"))))),"—"))} | F15: {=IF(CONTROL!$B$4<2,"—",IFERROR(_xlfn.LET(_xlpm.vC,(INDEX(_xlfn.ANCHORARRAY(ALUMNADO!$A$2),0,2)="3EPM"),_xlpm.vN,SUM(--(_xlpm.vC)),IF(_xlpm.vN=0,"—",SUM(_xlpm.vC*(INDEX(_xlfn.ANCHORARRAY(ALUMNADO!$A$2),0,8)="Con evaluación")*(INDEX(_xlfn.ANCHORARRAY(ALUMNADO!$A$2),0,7)="Sin decisión")))),"—"))} | G15: {=IF(CONTROL!$B$4<2,"—",IFERROR(_xlfn.LET(_xlpm.vC,(INDEX(_xlfn.ANCHORARRAY(ALUMNADO!$A$2),0,2)="3EPM"),_xlpm.vN,SUM(--(_xlpm.vC)),IF(_xlpm.vN=0,"—",SUM(_xlpm.vC*(INDEX(_xlfn.ANCHORARRAY(ALUMNADO!$A$2),0,8)="Sin evaluación")))),"—"))} | H15: {=IF(CONTROL!$B$4<2,"—",IFERROR(_xlfn.LET(_xlpm.vC,(INDEX(_xlfn.ANCHORARRAY(ALUMNADO!$A$2),0,2)="3EPM"),_xlpm.vN,SUM(--(_xlpm.vC)),IF(_xlpm.vN=0,"—",IF(SUM(_xlpm.vC*(INDEX(_xlfn.ANCHORARRAY(ALUMNADO!$A$2),0,6)<>""))=0,"—",IFERROR(SUM(_xlpm.vC*(INDEX(_xlfn.ANCHORARRAY(ALUMNADO!$A$2),0,7)="Promociona"))/SUM(_xlpm.vC*(INDEX(_xlfn.ANCHORARRAY(ALUMNADO!$A$2),0,8)="Con evaluación")),"—")))),"—"))} | I15: {=IF(CONTROL!$B$4<2,"—",IFERROR(_xlfn.LET(_xlpm.vC,(INDEX(_xlfn.ANCHORARRAY(ALUMNADO!$A$2),0,2)="3EPM"),_xlpm.vN,SUM(--(_xlpm.vC)),IF(_xlpm.vN=0,"—",IF(SUM(_xlpm.vC*(INDEX(_xlfn.ANCHORARRAY(ALUMNADO!$A$2),0,6)<>""))=0,"—",SUM(_xlpm.vC*(INDEX(_xlfn.ANCHORARRAY(ALUMNADO!$A$2),0,7)="Promociona"))/_xlpm.vN))),"—"))}
A16: 4EPM | B16: {=IF(CONTROL!$B$4<2,"—",IFERROR(_xlfn.LET(_xlpm.vC,(INDEX(_xlfn.ANCHORARRAY(ALUMNADO!$A$2),0,2)="4EPM"),_xlpm.vN,SUM(--(_xlpm.vC)),IF(_xlpm.vN=0,"—",_xlpm.vN)),"—"))} | C16: {=IF(CONTROL!$B$4<2,"—",IFERROR(_xlfn.LET(_xlpm.vC,(INDEX(_xlfn.ANCHORARRAY(ALUMNADO!$A$2),0,2)="4EPM"),_xlpm.vN,SUM(--(_xlpm.vC)),IF(_xlpm.vN=0,"—",SUM(_xlpm.vC*(INDEX(_xlfn.ANCHORARRAY(ALUMNADO!$A$2),0,8)="Con evaluación")))),"—"))} | D16: {=IF(CONTROL!$B$4<2,"—",IFERROR(_xlfn.LET(_xlpm.vC,(INDEX(_xlfn.ANCHORARRAY(ALUMNADO!$A$2),0,2)="4EPM"),_xlpm.vN,SUM(--(_xlpm.vC)),IF(_xlpm.vN=0,"—",IF(SUM(_xlpm.vC*(INDEX(_xlfn.ANCHORARRAY(ALUMNADO!$A$2),0,6)<>""))=0,"—",SUM(_xlpm.vC*(INDEX(_xlfn.ANCHORARRAY(ALUMNADO!$A$2),0,7)="Promociona"))))),"—"))} | E16: {=IF(CONTROL!$B$4<2,"—",IFERROR(_xlfn.LET(_xlpm.vC,(INDEX(_xlfn.ANCHORARRAY(ALUMNADO!$A$2),0,2)="4EPM"),_xlpm.vN,SUM(--(_xlpm.vC)),IF(_xlpm.vN=0,"—",IF(SUM(_xlpm.vC*(INDEX(_xlfn.ANCHORARRAY(ALUMNADO!$A$2),0,6)<>""))=0,"—",SUM(_xlpm.vC*(INDEX(_xlfn.ANCHORARRAY(ALUMNADO!$A$2),0,7)="No promociona"))))),"—"))} | F16: {=IF(CONTROL!$B$4<2,"—",IFERROR(_xlfn.LET(_xlpm.vC,(INDEX(_xlfn.ANCHORARRAY(ALUMNADO!$A$2),0,2)="4EPM"),_xlpm.vN,SUM(--(_xlpm.vC)),IF(_xlpm.vN=0,"—",SUM(_xlpm.vC*(INDEX(_xlfn.ANCHORARRAY(ALUMNADO!$A$2),0,8)="Con evaluación")*(INDEX(_xlfn.ANCHORARRAY(ALUMNADO!$A$2),0,7)="Sin decisión")))),"—"))} | G16: {=IF(CONTROL!$B$4<2,"—",IFERROR(_xlfn.LET(_xlpm.vC,(INDEX(_xlfn.ANCHORARRAY(ALUMNADO!$A$2),0,2)="4EPM"),_xlpm.vN,SUM(--(_xlpm.vC)),IF(_xlpm.vN=0,"—",SUM(_xlpm.vC*(INDEX(_xlfn.ANCHORARRAY(ALUMNADO!$A$2),0,8)="Sin evaluación")))),"—"))} | H16: {=IF(CONTROL!$B$4<2,"—",IFERROR(_xlfn.LET(_xlpm.vC,(INDEX(_xlfn.ANCHORARRAY(ALUMNADO!$A$2),0,2)="4EPM"),_xlpm.vN,SUM(--(_xlpm.vC)),IF(_xlpm.vN=0,"—",IF(SUM(_xlpm.vC*(INDEX(_xlfn.ANCHORARRAY(ALUMNADO!$A$2),0,6)<>""))=0,"—",IFERROR(SUM(_xlpm.vC*(INDEX(_xlfn.ANCHORARRAY(ALUMNADO!$A$2),0,7)="Promociona"))/SUM(_xlpm.vC*(INDEX(_xlfn.ANCHORARRAY(ALUMNADO!$A$2),0,8)="Con evaluación")),"—")))),"—"))} | I16: {=IF(CONTROL!$B$4<2,"—",IFERROR(_xlfn.LET(_xlpm.vC,(INDEX(_xlfn.ANCHORARRAY(ALUMNADO!$A$2),0,2)="4EPM"),_xlpm.vN,SUM(--(_xlpm.vC)),IF(_xlpm.vN=0,"—",IF(SUM(_xlpm.vC*(INDEX(_xlfn.ANCHORARRAY(ALUMNADO!$A$2),0,6)<>""))=0,"—",SUM(_xlpm.vC*(INDEX(_xlfn.ANCHORARRAY(ALUMNADO!$A$2),0,7)="Promociona"))/_xlpm.vN))),"—"))}
A17: 5EPM | B17: {=IF(CONTROL!$B$4<2,"—",IFERROR(_xlfn.LET(_xlpm.vC,(INDEX(_xlfn.ANCHORARRAY(ALUMNADO!$A$2),0,2)="5EPM"),_xlpm.vN,SUM(--(_xlpm.vC)),IF(_xlpm.vN=0,"—",_xlpm.vN)),"—"))} | C17: {=IF(CONTROL!$B$4<2,"—",IFERROR(_xlfn.LET(_xlpm.vC,(INDEX(_xlfn.ANCHORARRAY(ALUMNADO!$A$2),0,2)="5EPM"),_xlpm.vN,SUM(--(_xlpm.vC)),IF(_xlpm.vN=0,"—",SUM(_xlpm.vC*(INDEX(_xlfn.ANCHORARRAY(ALUMNADO!$A$2),0,8)="Con evaluación")))),"—"))} | D17: {=IF(CONTROL!$B$4<2,"—",IFERROR(_xlfn.LET(_xlpm.vC,(INDEX(_xlfn.ANCHORARRAY(ALUMNADO!$A$2),0,2)="5EPM"),_xlpm.vN,SUM(--(_xlpm.vC)),IF(_xlpm.vN=0,"—",IF(SUM(_xlpm.vC*(INDEX(_xlfn.ANCHORARRAY(ALUMNADO!$A$2),0,6)<>""))=0,"—",SUM(_xlpm.vC*(INDEX(_xlfn.ANCHORARRAY(ALUMNADO!$A$2),0,7)="Promociona"))))),"—"))} | E17: {=IF(CONTROL!$B$4<2,"—",IFERROR(_xlfn.LET(_xlpm.vC,(INDEX(_xlfn.ANCHORARRAY(ALUMNADO!$A$2),0,2)="5EPM"),_xlpm.vN,SUM(--(_xlpm.vC)),IF(_xlpm.vN=0,"—",IF(SUM(_xlpm.vC*(INDEX(_xlfn.ANCHORARRAY(ALUMNADO!$A$2),0,6)<>""))=0,"—",SUM(_xlpm.vC*(INDEX(_xlfn.ANCHORARRAY(ALUMNADO!$A$2),0,7)="No promociona"))))),"—"))} | F17: {=IF(CONTROL!$B$4<2,"—",IFERROR(_xlfn.LET(_xlpm.vC,(INDEX(_xlfn.ANCHORARRAY(ALUMNADO!$A$2),0,2)="5EPM"),_xlpm.vN,SUM(--(_xlpm.vC)),IF(_xlpm.vN=0,"—",SUM(_xlpm.vC*(INDEX(_xlfn.ANCHORARRAY(ALUMNADO!$A$2),0,8)="Con evaluación")*(INDEX(_xlfn.ANCHORARRAY(ALUMNADO!$A$2),0,7)="Sin decisión")))),"—"))} | G17: {=IF(CONTROL!$B$4<2,"—",IFERROR(_xlfn.LET(_xlpm.vC,(INDEX(_xlfn.ANCHORARRAY(ALUMNADO!$A$2),0,2)="5EPM"),_xlpm.vN,SUM(--(_xlpm.vC)),IF(_xlpm.vN=0,"—",SUM(_xlpm.vC*(INDEX(_xlfn.ANCHORARRAY(ALUMNADO!$A$2),0,8)="Sin evaluación")))),"—"))} | H17: {=IF(CONTROL!$B$4<2,"—",IFERROR(_xlfn.LET(_xlpm.vC,(INDEX(_xlfn.ANCHORARRAY(ALUMNADO!$A$2),0,2)="5EPM"),_xlpm.vN,SUM(--(_xlpm.vC)),IF(_xlpm.vN=0,"—",IF(SUM(_xlpm.vC*(INDEX(_xlfn.ANCHORARRAY(ALUMNADO!$A$2),0,6)<>""))=0,"—",IFERROR(SUM(_xlpm.vC*(INDEX(_xlfn.ANCHORARRAY(ALUMNADO!$A$2),0,7)="Promociona"))/SUM(_xlpm.vC*(INDEX(_xlfn.ANCHORARRAY(ALUMNADO!$A$2),0,8)="Con evaluación")),"—")))),"—"))} | I17: {=IF(CONTROL!$B$4<2,"—",IFERROR(_xlfn.LET(_xlpm.vC,(INDEX(_xlfn.ANCHORARRAY(ALUMNADO!$A$2),0,2)="5EPM"),_xlpm.vN,SUM(--(_xlpm.vC)),IF(_xlpm.vN=0,"—",IF(SUM(_xlpm.vC*(INDEX(_xlfn.ANCHORARRAY(ALUMNADO!$A$2),0,6)<>""))=0,"—",SUM(_xlpm.vC*(INDEX(_xlfn.ANCHORARRAY(ALUMNADO!$A$2),0,7)="Promociona"))/_xlpm.vN))),"—"))}
A18: 6EPM | B18: {=IF(CONTROL!$B$4<2,"—",IFERROR(_xlfn.LET(_xlpm.vC,(INDEX(_xlfn.ANCHORARRAY(ALUMNADO!$A$2),0,2)="6EPM"),_xlpm.vN,SUM(--(_xlpm.vC)),IF(_xlpm.vN=0,"—",_xlpm.vN)),"—"))} | C18: {=IF(CONTROL!$B$4<2,"—",IFERROR(_xlfn.LET(_xlpm.vC,(INDEX(_xlfn.ANCHORARRAY(ALUMNADO!$A$2),0,2)="6EPM"),_xlpm.vN,SUM(--(_xlpm.vC)),IF(_xlpm.vN=0,"—",SUM(_xlpm.vC*(INDEX(_xlfn.ANCHORARRAY(ALUMNADO!$A$2),0,8)="Con evaluación")))),"—"))} | D18: {=IF(CONTROL!$B$4<2,"—",IFERROR(_xlfn.LET(_xlpm.vC,(INDEX(_xlfn.ANCHORARRAY(ALUMNADO!$A$2),0,2)="6EPM"),_xlpm.vN,SUM(--(_xlpm.vC)),IF(_xlpm.vN=0,"—",IF(SUM(_xlpm.vC*(INDEX(_xlfn.ANCHORARRAY(ALUMNADO!$A$2),0,6)<>""))=0,"—",SUM(_xlpm.vC*(INDEX(_xlfn.ANCHORARRAY(ALUMNADO!$A$2),0,7)="Promociona"))))),"—"))} | E18: {=IF(CONTROL!$B$4<2,"—",IFERROR(_xlfn.LET(_xlpm.vC,(INDEX(_xlfn.ANCHORARRAY(ALUMNADO!$A$2),0,2)="6EPM"),_xlpm.vN,SUM(--(_xlpm.vC)),IF(_xlpm.vN=0,"—",IF(SUM(_xlpm.vC*(INDEX(_xlfn.ANCHORARRAY(ALUMNADO!$A$2),0,6)<>""))=0,"—",SUM(_xlpm.vC*(INDEX(_xlfn.ANCHORARRAY(ALUMNADO!$A$2),0,7)="No promociona"))))),"—"))} | F18: {=IF(CONTROL!$B$4<2,"—",IFERROR(_xlfn.LET(_xlpm.vC,(INDEX(_xlfn.ANCHORARRAY(ALUMNADO!$A$2),0,2)="6EPM"),_xlpm.vN,SUM(--(_xlpm.vC)),IF(_xlpm.vN=0,"—",SUM(_xlpm.vC*(INDEX(_xlfn.ANCHORARRAY(ALUMNADO!$A$2),0,8)="Con evaluación")*(INDEX(_xlfn.ANCHORARRAY(ALUMNADO!$A$2),0,7)="Sin decisión")))),"—"))} | G18: {=IF(CONTROL!$B$4<2,"—",IFERROR(_xlfn.LET(_xlpm.vC,(INDEX(_xlfn.ANCHORARRAY(ALUMNADO!$A$2),0,2)="6EPM"),_xlpm.vN,SUM(--(_xlpm.vC)),IF(_xlpm.vN=0,"—",SUM(_xlpm.vC*(INDEX(_xlfn.ANCHORARRAY(ALUMNADO!$A$2),0,8)="Sin evaluación")))),"—"))} | H18: {=IF(CONTROL!$B$4<2,"—",IFERROR(_xlfn.LET(_xlpm.vC,(INDEX(_xlfn.ANCHORARRAY(ALUMNADO!$A$2),0,2)="6EPM"),_xlpm.vN,SUM(--(_xlpm.vC)),IF(_xlpm.vN=0,"—",IF(SUM(_xlpm.vC*(INDEX(_xlfn.ANCHORARRAY(ALUMNADO!$A$2),0,6)<>""))=0,"—",IFERROR(SUM(_xlpm.vC*(INDEX(_xlfn.ANCHORARRAY(ALUMNADO!$A$2),0,7)="Promociona"))/SUM(_xlpm.vC*(INDEX(_xlfn.ANCHORARRAY(ALUMNADO!$A$2),0,8)="Con evaluación")),"—")))),"—"))} | I18: {=IF(CONTROL!$B$4<2,"—",IFERROR(_xlfn.LET(_xlpm.vC,(INDEX(_xlfn.ANCHORARRAY(ALUMNADO!$A$2),0,2)="6EPM"),_xlpm.vN,SUM(--(_xlpm.vC)),IF(_xlpm.vN=0,"—",IF(SUM(_xlpm.vC*(INDEX(_xlfn.ANCHORARRAY(ALUMNADO!$A$2),0,6)<>""))=0,"—",SUM(_xlpm.vC*(INDEX(_xlfn.ANCHORARRAY(ALUMNADO!$A$2),0,7)="Promociona"))/_xlpm.vN))),"—"))}
A19: Total EPM | B19: {=IF(CONTROL!$B$4<2,"—",IFERROR(_xlfn.LET(_xlpm.vC,(INDEX(_xlfn.ANCHORARRAY(ALUMNADO!$A$2),0,3)="EPM"),_xlpm.vN,SUM(--(_xlpm.vC)),IF(_xlpm.vN=0,"—",_xlpm.vN)),"—"))} | C19: {=IF(CONTROL!$B$4<2,"—",IFERROR(_xlfn.LET(_xlpm.vC,(INDEX(_xlfn.ANCHORARRAY(ALUMNADO!$A$2),0,3)="EPM"),_xlpm.vN,SUM(--(_xlpm.vC)),IF(_xlpm.vN=0,"—",SUM(_xlpm.vC*(INDEX(_xlfn.ANCHORARRAY(ALUMNADO!$A$2),0,8)="Con evaluación")))),"—"))} | D19: {=IF(CONTROL!$B$4<2,"—",IFERROR(_xlfn.LET(_xlpm.vC,(INDEX(_xlfn.ANCHORARRAY(ALUMNADO!$A$2),0,3)="EPM"),_xlpm.vN,SUM(--(_xlpm.vC)),IF(_xlpm.vN=0,"—",IF(SUM(_xlpm.vC*(INDEX(_xlfn.ANCHORARRAY(ALUMNADO!$A$2),0,6)<>""))=0,"—",SUM(_xlpm.vC*(INDEX(_xlfn.ANCHORARRAY(ALUMNADO!$A$2),0,7)="Promociona"))))),"—"))} | E19: {=IF(CONTROL!$B$4<2,"—",IFERROR(_xlfn.LET(_xlpm.vC,(INDEX(_xlfn.ANCHORARRAY(ALUMNADO!$A$2),0,3)="EPM"),_xlpm.vN,SUM(--(_xlpm.vC)),IF(_xlpm.vN=0,"—",IF(SUM(_xlpm.vC*(INDEX(_xlfn.ANCHORARRAY(ALUMNADO!$A$2),0,6)<>""))=0,"—",SUM(_xlpm.vC*(INDEX(_xlfn.ANCHORARRAY(ALUMNADO!$A$2),0,7)="No promociona"))))),"—"))} | F19: {=IF(CONTROL!$B$4<2,"—",IFERROR(_xlfn.LET(_xlpm.vC,(INDEX(_xlfn.ANCHORARRAY(ALUMNADO!$A$2),0,3)="EPM"),_xlpm.vN,SUM(--(_xlpm.vC)),IF(_xlpm.vN=0,"—",SUM(_xlpm.vC*(INDEX(_xlfn.ANCHORARRAY(ALUMNADO!$A$2),0,8)="Con evaluación")*(INDEX(_xlfn.ANCHORARRAY(ALUMNADO!$A$2),0,7)="Sin decisión")))),"—"))} | G19: {=IF(CONTROL!$B$4<2,"—",IFERROR(_xlfn.LET(_xlpm.vC,(INDEX(_xlfn.ANCHORARRAY(ALUMNADO!$A$2),0,3)="EPM"),_xlpm.vN,SUM(--(_xlpm.vC)),IF(_xlpm.vN=0,"—",SUM(_xlpm.vC*(INDEX(_xlfn.ANCHORARRAY(ALUMNADO!$A$2),0,8)="Sin evaluación")))),"—"))} | H19: {=IF(CONTROL!$B$4<2,"—",IFERROR(_xlfn.LET(_xlpm.vC,(INDEX(_xlfn.ANCHORARRAY(ALUMNADO!$A$2),0,3)="EPM"),_xlpm.vN,SUM(--(_xlpm.vC)),IF(_xlpm.vN=0,"—",IF(SUM(_xlpm.vC*(INDEX(_xlfn.ANCHORARRAY(ALUMNADO!$A$2),0,6)<>""))=0,"—",IFERROR(SUM(_xlpm.vC*(INDEX(_xlfn.ANCHORARRAY(ALUMNADO!$A$2),0,7)="Promociona"))/SUM(_xlpm.vC*(INDEX(_xlfn.ANCHORARRAY(ALUMNADO!$A$2),0,8)="Con evaluación")),"—")))),"—"))} | I19: {=IF(CONTROL!$B$4<2,"—",IFERROR(_xlfn.LET(_xlpm.vC,(INDEX(_xlfn.ANCHORARRAY(ALUMNADO!$A$2),0,3)="EPM"),_xlpm.vN,SUM(--(_xlpm.vC)),IF(_xlpm.vN=0,"—",IF(SUM(_xlpm.vC*(INDEX(_xlfn.ANCHORARRAY(ALUMNADO!$A$2),0,6)<>""))=0,"—",SUM(_xlpm.vC*(INDEX(_xlfn.ANCHORARRAY(ALUMNADO!$A$2),0,7)="Promociona"))/_xlpm.vN))),"—"))}
A20: Total | B20: {=IF(CONTROL!$B$4<2,"—",IFERROR(_xlfn.LET(_xlpm.vC,((INDEX(_xlfn.ANCHORARRAY(ALUMNADO!$A$2),0,3)="EEM")+(INDEX(_xlfn.ANCHORARRAY(ALUMNADO!$A$2),0,3)="EPM")),_xlpm.vN,SUM(--(_xlpm.vC)),IF(_xlpm.vN=0,"—",_xlpm.vN)),"—"))} | C20: {=IF(CONTROL!$B$4<2,"—",IFERROR(_xlfn.LET(_xlpm.vC,((INDEX(_xlfn.ANCHORARRAY(ALUMNADO!$A$2),0,3)="EEM")+(INDEX(_xlfn.ANCHORARRAY(ALUMNADO!$A$2),0,3)="EPM")),_xlpm.vN,SUM(--(_xlpm.vC)),IF(_xlpm.vN=0,"—",SUM(_xlpm.vC*(INDEX(_xlfn.ANCHORARRAY(ALUMNADO!$A$2),0,8)="Con evaluación")))),"—"))} | D20: {=IF(CONTROL!$B$4<2,"—",IFERROR(_xlfn.LET(_xlpm.vC,((INDEX(_xlfn.ANCHORARRAY(ALUMNADO!$A$2),0,3)="EEM")+(INDEX(_xlfn.ANCHORARRAY(ALUMNADO!$A$2),0,3)="EPM")),_xlpm.vN,SUM(--(_xlpm.vC)),IF(_xlpm.vN=0,"—",IF(SUM(_xlpm.vC*(INDEX(_xlfn.ANCHORARRAY(ALUMNADO!$A$2),0,6)<>""))=0,"—",SUM(_xlpm.vC*(INDEX(_xlfn.ANCHORARRAY(ALUMNADO!$A$2),0,7)="Promociona"))))),"—"))} | E20: {=IF(CONTROL!$B$4<2,"—",IFERROR(_xlfn.LET(_xlpm.vC,((INDEX(_xlfn.ANCHORARRAY(ALUMNADO!$A$2),0,3)="EEM")+(INDEX(_xlfn.ANCHORARRAY(ALUMNADO!$A$2),0,3)="EPM")),_xlpm.vN,SUM(--(_xlpm.vC)),IF(_xlpm.vN=0,"—",IF(SUM(_xlpm.vC*(INDEX(_xlfn.ANCHORARRAY(ALUMNADO!$A$2),0,6)<>""))=0,"—",SUM(_xlpm.vC*(INDEX(_xlfn.ANCHORARRAY(ALUMNADO!$A$2),0,7)="No promociona"))))),"—"))} | F20: {=IF(CONTROL!$B$4<2,"—",IFERROR(_xlfn.LET(_xlpm.vC,((INDEX(_xlfn.ANCHORARRAY(ALUMNADO!$A$2),0,3)="EEM")+(INDEX(_xlfn.ANCHORARRAY(ALUMNADO!$A$2),0,3)="EPM")),_xlpm.vN,SUM(--(_xlpm.vC)),IF(_xlpm.vN=0,"—",SUM(_xlpm.vC*(INDEX(_xlfn.ANCHORARRAY(ALUMNADO!$A$2),0,8)="Con evaluación")*(INDEX(_xlfn.ANCHORARRAY(ALUMNADO!$A$2),0,7)="Sin decisión")))),"—"))} | G20: {=IF(CONTROL!$B$4<2,"—",IFERROR(_xlfn.LET(_xlpm.vC,((INDEX(_xlfn.ANCHORARRAY(ALUMNADO!$A$2),0,3)="EEM")+(INDEX(_xlfn.ANCHORARRAY(ALUMNADO!$A$2),0,3)="EPM")),_xlpm.vN,SUM(--(_xlpm.vC)),IF(_xlpm.vN=0,"—",SUM(_xlpm.vC*(INDEX(_xlfn.ANCHORARRAY(ALUMNADO!$A$2),0,8)="Sin evaluación")))),"—"))} | H20: {=IF(CONTROL!$B$4<2,"—",IFERROR(_xlfn.LET(_xlpm.vC,((INDEX(_xlfn.ANCHORARRAY(ALUMNADO!$A$2),0,3)="EEM")+(INDEX(_xlfn.ANCHORARRAY(ALUMNADO!$A$2),0,3)="EPM")),_xlpm.vN,SUM(--(_xlpm.vC)),IF(_xlpm.vN=0,"—",IF(SUM(_xlpm.vC*(INDEX(_xlfn.ANCHORARRAY(ALUMNADO!$A$2),0,6)<>""))=0,"—",IFERROR(SUM(_xlpm.vC*(INDEX(_xlfn.ANCHORARRAY(ALUMNADO!$A$2),0,7)="Promociona"))/SUM(_xlpm.vC*(INDEX(_xlfn.ANCHORARRAY(ALUMNADO!$A$2),0,8)="Con evaluación")),"—")))),"—"))} | I20: {=IF(CONTROL!$B$4<2,"—",IFERROR(_xlfn.LET(_xlpm.vC,((INDEX(_xlfn.ANCHORARRAY(ALUMNADO!$A$2),0,3)="EEM")+(INDEX(_xlfn.ANCHORARRAY(ALUMNADO!$A$2),0,3)="EPM")),_xlpm.vN,SUM(--(_xlpm.vC)),IF(_xlpm.vN=0,"—",IF(SUM(_xlpm.vC*(INDEX(_xlfn.ANCHORARRAY(ALUMNADO!$A$2),0,6)<>""))=0,"—",SUM(_xlpm.vC*(INDEX(_xlfn.ANCHORARRAY(ALUMNADO!$A$2),0,7)="Promociona"))/_xlpm.vN))),"—"))}
A22: 2. Finalizan elementales y titulan en profesionales
A23: Finalizar es promocionar en 4EEM y titular, en 6EPM, según la columna promociona. Al lado, quién termina sin ninguna suspensa: si la exportación no rellena la decisión, es la otra lectura.
A24: Curso | B24: Matriculados | C24: Con evaluación | D24: Finalizan o titulan, según la exportación | E24: Terminan sin ninguna suspensa | F24: % sobre evaluados
A25: 4EEM | B25: {=IF(CONTROL!$B$4<2,"—",IFERROR(_xlfn.LET(_xlpm.vC,(INDEX(_xlfn.ANCHORARRAY(ALUMNADO!$A$2),0,2)="4EEM"),_xlpm.vN,SUM(--(_xlpm.vC)),IF(_xlpm.vN=0,"—",_xlpm.vN)),"—"))} | C25: {=IF(CONTROL!$B$4<2,"—",IFERROR(_xlfn.LET(_xlpm.vC,(INDEX(_xlfn.ANCHORARRAY(ALUMNADO!$A$2),0,2)="4EEM"),_xlpm.vN,SUM(--(_xlpm.vC)),IF(_xlpm.vN=0,"—",SUM(_xlpm.vC*(INDEX(_xlfn.ANCHORARRAY(ALUMNADO!$A$2),0,8)="Con evaluación")))),"—"))} | D25: {=IF(CONTROL!$B$4<2,"—",IFERROR(_xlfn.LET(_xlpm.vC,(INDEX(_xlfn.ANCHORARRAY(ALUMNADO!$A$2),0,2)="4EEM"),_xlpm.vN,SUM(--(_xlpm.vC)),IF(_xlpm.vN=0,"—",IF(SUM(_xlpm.vC*(INDEX(_xlfn.ANCHORARRAY(ALUMNADO!$A$2),0,6)<>""))=0,"—",SUM(_xlpm.vC*(INDEX(_xlfn.ANCHORARRAY(ALUMNADO!$A$2),0,7)="Promociona"))))),"—"))} | E25: {=IF(CONTROL!$B$4<2,"—",IFERROR(_xlfn.LET(_xlpm.vC,(INDEX(_xlfn.ANCHORARRAY(ALUMNADO!$A$2),0,2)="4EEM"),_xlpm.vN,SUM(--(_xlpm.vC)),IF(_xlpm.vN=0,"—",SUM(_xlpm.vC*(INDEX(_xlfn.ANCHORARRAY(ALUMNADO!$A$2),0,8)="Con evaluación")*(INDEX(_xlfn.ANCHORARRAY(ALUMNADO!$A$2),0,4)>0)*(INDEX(_xlfn.ANCHORARRAY(ALUMNADO!$A$2),0,5)=0)))),"—"))} | F25: {=IF(CONTROL!$B$4<2,"—",IFERROR(_xlfn.LET(_xlpm.vC,(INDEX(_xlfn.ANCHORARRAY(ALUMNADO!$A$2),0,2)="4EEM"),_xlpm.vN,SUM(--(_xlpm.vC)),IF(_xlpm.vN=0,"—",IF(SUM(_xlpm.vC*(INDEX(_xlfn.ANCHORARRAY(ALUMNADO!$A$2),0,6)<>""))=0,"—",IFERROR(SUM(_xlpm.vC*(INDEX(_xlfn.ANCHORARRAY(ALUMNADO!$A$2),0,7)="Promociona"))/SUM(_xlpm.vC*(INDEX(_xlfn.ANCHORARRAY(ALUMNADO!$A$2),0,8)="Con evaluación")),"—")))),"—"))}
A26: 6EPM | B26: {=IF(CONTROL!$B$4<2,"—",IFERROR(_xlfn.LET(_xlpm.vC,(INDEX(_xlfn.ANCHORARRAY(ALUMNADO!$A$2),0,2)="6EPM"),_xlpm.vN,SUM(--(_xlpm.vC)),IF(_xlpm.vN=0,"—",_xlpm.vN)),"—"))} | C26: {=IF(CONTROL!$B$4<2,"—",IFERROR(_xlfn.LET(_xlpm.vC,(INDEX(_xlfn.ANCHORARRAY(ALUMNADO!$A$2),0,2)="6EPM"),_xlpm.vN,SUM(--(_xlpm.vC)),IF(_xlpm.vN=0,"—",SUM(_xlpm.vC*(INDEX(_xlfn.ANCHORARRAY(ALUMNADO!$A$2),0,8)="Con evaluación")))),"—"))} | D26: {=IF(CONTROL!$B$4<2,"—",IFERROR(_xlfn.LET(_xlpm.vC,(INDEX(_xlfn.ANCHORARRAY(ALUMNADO!$A$2),0,2)="6EPM"),_xlpm.vN,SUM(--(_xlpm.vC)),IF(_xlpm.vN=0,"—",IF(SUM(_xlpm.vC*(INDEX(_xlfn.ANCHORARRAY(ALUMNADO!$A$2),0,6)<>""))=0,"—",SUM(_xlpm.vC*(INDEX(_xlfn.ANCHORARRAY(ALUMNADO!$A$2),0,7)="Promociona"))))),"—"))} | E26: {=IF(CONTROL!$B$4<2,"—",IFERROR(_xlfn.LET(_xlpm.vC,(INDEX(_xlfn.ANCHORARRAY(ALUMNADO!$A$2),0,2)="6EPM"),_xlpm.vN,SUM(--(_xlpm.vC)),IF(_xlpm.vN=0,"—",SUM(_xlpm.vC*(INDEX(_xlfn.ANCHORARRAY(ALUMNADO!$A$2),0,8)="Con evaluación")*(INDEX(_xlfn.ANCHORARRAY(ALUMNADO!$A$2),0,4)>0)*(INDEX(_xlfn.ANCHORARRAY(ALUMNADO!$A$2),0,5)=0)))),"—"))} | F26: {=IF(CONTROL!$B$4<2,"—",IFERROR(_xlfn.LET(_xlpm.vC,(INDEX(_xlfn.ANCHORARRAY(ALUMNADO!$A$2),0,2)="6EPM"),_xlpm.vN,SUM(--(_xlpm.vC)),IF(_xlpm.vN=0,"—",IF(SUM(_xlpm.vC*(INDEX(_xlfn.ANCHORARRAY(ALUMNADO!$A$2),0,6)<>""))=0,"—",IFERROR(SUM(_xlpm.vC*(INDEX(_xlfn.ANCHORARRAY(ALUMNADO!$A$2),0,7)="Promociona"))/SUM(_xlpm.vC*(INDEX(_xlfn.ANCHORARRAY(ALUMNADO!$A$2),0,8)="Con evaluación")),"—")))),"—"))}
A28: 3. Alumnado por número de asignaturas suspensas
A29: Con la nota final de cada asignatura: la de la extraordinaria si la hay. Es un recuento: no aplica ninguna norma de promoción.
A30: Curso | B30: Con notas | C30: Ninguna | D30: Una | E30: Dos | F30: Tres o más
